Workbook

Sheet 目录
A1: 华东区-同行价格 目录表
A2: 服务 | B2: 渠道名称 | C2: 价格表链接 | D2: 派送参考时效
A3: 海卡价格快捷查询 | B3: 海卡价格快捷查询 | C3: 点击进入 | D3: -
A4: 联邦超大件海派 | B4: 联邦超大件海派 | C4: 点击进入 | D4: 14、18天 赔付时效承诺
A5: 自提-自打单-仓储 | B5: 自提-自打单-仓储 | C5: 点击进入 | D5: CLX MAX EXX OA普船 美中美东普船全渠道自提/仓储服务
A6: 海派汇总表 海派汇总表—DY | B6: 海派 美森极速达 13天赔付 （CLX） | C6: 点击进入 | D6: 13天 赔付时效承诺
B7: 海派 美森极速达 14天赔付 （CLX） | D7: 14天 赔付时效承诺
B8: 海派 美森加班限时达 18天赔付 （MAX） | D8: 18天 赔付时效承诺
B9: 海派 美森加班船 （MAX） | D9: 开船后16天-18天提取
B10: 海派 普船经济线 | D10: 开船后25-30天左右提取
B11: 海派 OA普船定提统配 | D11: 开船后22-25天左右提取
B12: 海派 OA稳速达统配 25天赔付 （OA统配） | D12: 25天 赔付时效承诺
B13: 海派 稳速达统配 22天赔付 （OA/合德/以星 统配） | D13: 22天 赔付时效承诺
B14: 海派 合德快提 18天赔付 | D14: 18天 赔付时效承诺
B15: 海派 EXX限时达 18天赔付 | D15: 18天 赔付时效承诺
B16: 海派 合德/以星统配 20天赔付 | D16: 20天 赔付时效承诺
B17: 海派 休斯顿OA快普 | D17: 开船后35-40天内提取
B18: 海派 芝加哥OA快普 | D18: 开船后35-40天内提取
B19: 海派 美东OA快普 | D19: 开船后35-40天内提取
A20: 海卡汇总表 | B20: 海卡/美森极速达（CLX）【带赔付】 | C20: 点击进入 | D20: 卡派19天起赔
B21: 海卡/美森极速达（CLX） | D21: 14-18天签收提供POD
B22: 海卡/美森加班船（MAX ）【带赔付】 | D22: 卡派20天起赔
B23: 海卡/美森加班船（MAX ） | D23: 16-19天签收提供POD
B24: 海卡/EXX限时达【带赔付】 | D24: 卡派21天起赔
B25: 海卡/合德限时达【带赔付】 | D25: 卡派25天起赔
B26: 海卡/OA稳速达【带赔付】 | D26: 卡派28天起赔
B27: 海卡/OA普船定提统配 | D27: 20-25天提供POD
B28: 海卡/普船经济线 | D28: 25-30天提供POD
A29: 普船海卡整柜直送 | B29: 普船海卡整柜直送 | C29: 点击进入 | D29: 西雅图、洛杉矶直送，开船后20-35天提供POD
A30: 美中专线（休斯顿、芝加哥） | B30: 美中专线（休斯顿、芝加哥） | C30: 点击进入 | D30: 35-40天时效
A31: 萨凡纳海卡专线 | B31: 萨凡纳海卡专线 | C31: 点击进入 | D31: 35-45天时效
A32: 美东纽约海卡专线 | B32: 美东纽约海卡专线 | C32: 点击进入 | D32: 35-40天时效；含纽约海铁赔付渠道
A33: 全美私人卡派 | B33: 全美私人卡派 | C33: 点击进入 | D33: 渠道丰富，对应渠道可以做到秒报价： CLX MAX EXX 以星 洛杉矶普船 奥克兰/纽约/休斯顿/芝加哥普船
A34: 美国转加拿大海派 | B34: 美国转加拿大海派 | C34: 点击进入 | D34: 赔付时效为：18天、20天、25天不等
A35: 奥克兰卡派专线 | B35: 奥克兰普船海卡/散货特价 | C35: 点击进入 | D35: 开船后25-35天提供POD
A36: 西雅图卡派专线 | B36: 西雅图海卡/散货特价 | C36: 点击进入 | D36: 开船后25-35天提供POD
A37: UPS海运小包特价 | B37: UPS海运小包特价 | C37: 点击进入 | D37: 16、18天 赔付时效承诺
A38: 美西海外仓收费标准 | B38: 美西海外仓收费标准 | C38: 点击进入 | D38: /
A39: 奥克兰、芝加哥、休斯顿、纽约海外仓收费标准 | B39: 奥克兰、芝加哥、休斯顿、纽约海外仓收费标准 | C39: 点击进入 | D39: /
A40: 各分公司联系电话；仓库收货联系人，写我司业务员，方便我司识别是哪个业务员的货
...

Sheet 注意事项及赔偿标准
A1: 海派海卡类：美国海运注意事项、收费标准及赔偿标准
A2: 货物包装要求： 1、亚马逊仓外箱要贴两张入仓条码。 2、海派：单件最低计费重12KG，重量不超过22Kg；海卡：单件重量不超过30Kg。 3、外箱规则，坚固，防止货物损坏，否则我司不承担亚马逊仓库拒收所造成的货物丢失。 4、货物外箱上贴上made in china的字样（内部货物产品也需贴有MADE IN CHINA标签。如因包装及标签问题导致亚马逊仓库拒收或清关出现问题，所有责任及费用由发货人承担。) 5、发货前请贴好货物的SKU条码以及FBA箱子标签并用透明胶纸封好，如因标签条码问题无法递送产生的相关费用则由发件人承担。
A3: ★★★ 一、注意事项 ★★★
A4: 1、只收普货。带电产品只接内置纽扣电池类。眼镜类需要FDA跟落球证书才能出。材质是原木或带有原木的货物要求熏蒸商检，商检费：RMB 300/票。需要商检的货物：木家私，木制工艺品，木架，竹制品，藤制品，草制品，植物制品等（仅供参考），客户可自行安排熏蒸和商检。 1）不接产品：玩具产品、仿牌、液体、粉末、美国对华反倾销产品等敏感货物。 2）不接食品类、医疗类产品类、婴儿用品类、童装、童鞋、汽车灯、化妆品类（含纹身美妆产品）、电子烟及烟草相关产品、动物皮毛制品类、激光产品类、成人用品类、管制刀具和警棍、电棒类、植物种子类、强磁类（磁铁、冰箱贴等）、灭蚊、捕鼠、杀虫类产品、杂志书籍出版，如发现冲货或者带电不备注行为没收货物并罚款RMB1000-RMB50000元：不接收木箱；木架；及托盘货物。 3）毛绒玩具 需要CPC认证+申报费：收300元一票。
A5: 2、以上价格为本区域仓库交货价。货物体积重计算方式为长x宽x高(CM)/6000。单票一件的品名超过2个不接，多件的，品名超过5个，按照30元/个收取。
A6: 3、海关要求如实申报，否则造成延误和丢失以及扣关我司一概不负责。
A7: 4、因服务商原因产生海外退件，退件运费及相关退件费用将无条件由发件人支付。
A8: 5、重量尺寸限制明细如下,超重费注：22kg<单箱产品<30kg，收150元/箱；30kg<单箱产品<35kg，收300元/箱；且单件货物不能低于12KG，不足12KG按12KG计算(包装限制：只接受纸箱包装货物)。非规则箱规，收异形费150/件。不收凹凸严重不整齐的异形箱规尺寸！！
A9: 1）0<单件重量<22KG 2）0CM<最长单边长度<120CM 超出+120一件 3）0CM<第二边<75CM 超出+120一件 4）260CM<周长（长+2宽+2高）<320CM 超出+150一件 5）320CM<周长（长+2宽+2高）<410CM 超出+1500一件 6）超410不收
A10: 6、不收地址： 阿拉斯加，夏威夷，波多黎各，关岛，及各岛屿。
A11: 7、以上货物服务仅限于美国48洲，邮箱BOX，军方地址不收(阿拉斯加，夏威夷，波多黎各,关岛，及各岛屿美国直接不收，可中转这几个城市,请咨询)偏远费单询。如果地址错误产生联邦IP/UPS更改地址和扣件费用的，所产生的具体费用需要单独咨询我司客服。海关要求如实申报，否则造成延误和丢失以及扣关我司一概不负责。
A12: 8、有关品牌侵权产品问题： 如美国海关认定货物涉及品牌侵权或蓝牙、HDMI、FCC、UL、FDA、DOT等认证问题，客户需按要求提供相关认证和品牌授权书等文件，如因无法提供或者提供的文件得不到美国海关及相关部门的认可而导致扣货或者退运，所有责任和费用由该发货人承担。
... A28: 以上条款最终解释权归义乌飞迹国际公司所有！

Sheet 海卡价格快捷查询
A1: FBA仓库代码 （请在右侧【C1】输入大小写均可） | C1: ont8 | D1: =UPPER(C1) -> ONT8 | E1: 温馨提示： 关于冷门仓卡派超大件尺寸附加费，比重优惠，带赔付的时效赔付等其他问题，详情请参考的具体价格表！！！
A2: 派送类型 | B2: 渠道 | C2: 价格 | D2: 参考时效
A3: 美西卡派 （热门仓12kg+起收，冷门仓100kg+起收） | B3: 海卡/美森极速达（CLX） 【带赔付】 | C3: {=IFERROR(INDEX(美西海卡汇总表!D4:D345,MATCH(D1,美西海卡汇总表!A4:A345,0)),"-")} -> 8.3 | D3: {=IFERROR(INDEX(美西海卡汇总表!E4:E345,MATCH(D1,美西海卡汇总表!A4:A345,0)),"-")} -> 19天赔付
B4: 海卡/美森极速达（CLX） | C4: {=IFERROR(INDEX(美西海卡汇总表!F4:F345,MATCH(D1,美西海卡汇总表!A4:A345,0)),"-")} -> 8 | D4: {=IFERROR(INDEX(美西海卡汇总表!G4:G345,MATCH(D1,美西海卡汇总表!A4:A345,0)),"-")} -> 15-22天
B5: 海卡/美森加班船（MAX） 【带赔付】 | C5: {=IFERROR(INDEX(美西海卡汇总表!H4:H345,MATCH(D1,美西海卡汇总表!A4:A345,0)),"-")} -> 7.3 | D5: {=IFERROR(INDEX(美西海卡汇总表!I4:I345,MATCH(D1,美西海卡汇总表!A4:A345,0)),"-")} -> 20天赔付
B6: 海卡/美森加班船（MAX） | C6: {=IFERROR(INDEX(美西海卡汇总表!J4:J345,MATCH(D1,美西海卡汇总表!A4:A345,0)),"-")} -> 7 | D6: {=IFERROR(INDEX(美西海卡汇总表!K4:K345,MATCH(D1,美西海卡汇总表!A4:A345,0)),"-")} -> 17-23天
B7: 海卡/EXX限时达【带赔付】 | C7: {=IFERROR(INDEX(美西海卡汇总表!L4:L345,MATCH(D1,美西海卡汇总表!A4:A345,0)),"-")} -> 5.3 | D7: {=IFERROR(INDEX(美西海卡汇总表!M4:M345,MATCH(D1,美西海卡汇总表!A4:A345,0)),"-")} -> 21天赔付
B8: 海卡/华东合德限时达【带赔付】 （最晚周二进仓） | C8: {=IFERROR(INDEX(美西海卡汇总表!N4:N345,MATCH(D1,美西海卡汇总表!A4:A345,0)),"-")} -> 4.7 | D8: {=IFERROR(INDEX(美西海卡汇总表!O4:O345,MATCH(D1,美西海卡汇总表!A4:A345,0)),"-")} -> 25天赔付
B9: 海卡/OA稳速达【带赔付】 （最晚周一进仓） | C9: {=IFERROR(INDEX(美西海卡汇总表!P4:P345,MATCH(D1,美西海卡汇总表!A4:A345,0)),"-")} -> 4.4 | D9: {=IFERROR(INDEX(美西海卡汇总表!Q4:Q345,MATCH(D1,美西海卡汇总表!A4:A345,0)),"-")} -> 28天赔付
B10: 海卡/OA普船定提统配 | C10: {=IFERROR(INDEX(美西海卡汇总表!R4:R345,MATCH(D1,美西海卡汇总表!A4:A345,0)),"-")} -> 4.3 | D10: {=IFERROR(INDEX(美西海卡汇总表!S4:S345,MATCH(D1,美西海卡汇总表!A4:A345,0)),"-")} -> 20-25天
B11: 海卡/普船经济线 （周六开船，25天航程） | C11: {=IFERROR(INDEX(美西海卡汇总表!T4:T345,MATCH(D1,美西海卡汇总表!A4:A345,0)),"-")} -> 4.2 | D11: {=IFERROR(INDEX(美西海卡汇总表!U4:U345,MATCH(D1,美西海卡汇总表!A4:A345,0)),"-")} -> 25-30天
A12: 普船海卡整柜直送 （12kg+起收） | B12: 西雅图普船海卡/整柜直送 | C12: =IFERROR(INDEX(普船海卡整柜直送!#REF!,MATCH(D1,普船海卡整柜直送!#REF!,0)),"-") -> - | D12: =IFERROR(INDEX(普船海卡整柜直送!#REF!,MATCH(D1,普船海卡整柜直送!#REF!,0)),"-") -> -
B13: 美西普船海卡/整柜直送 | C13: {=IFERROR(INDEX(普船海卡整柜直送!D4:D22,MATCH(D1,普船海卡整柜直送!A4:A22,0)),"-")} -> 4.1 | D13: {=IFERROR(INDEX(普船海卡整柜直送!F4:F22,MATCH(D1,普船海卡整柜直送!A4:A22,0)),"-")} -> 25-32天
B14: 奥克兰普船海卡/整柜直送 | C14: {=IFERROR(INDEX(普船海卡整柜直送!D26:D31,MATCH(D1,普船海卡整柜直送!A26:A31,0)),"-")} -> - | D14: {=IFERROR(INDEX(普船海卡整柜直送!F26:F31,MATCH(D1,普船海卡整柜直送!A26:A31,0)),"-")} -> -
B15: 美西普船海卡/整柜直送 普船经济线 | C15: {=IFERROR(INDEX(普船海卡整柜直送!D35:D53,MATCH(D1,普船海卡整柜直送!A35:A53,0)),"-")} -> 4 | D15: {=IFERROR(INDEX(普船海卡整柜直送!F35:F53,MATCH(D1,普船海卡整柜直送!A35:A53,0)),"-")} -> 30-35天
A16: 美中专线 （休斯顿、芝加哥） 12kg+起收 | B16: 芝加哥 普船海卡/美中专线 | C16: {=IFERROR(INDEX('美中专线（休斯顿、芝加哥）'!C4:C35,MATCH(D1,'美中专线（休斯顿、芝加哥）'!A4:A35,0)),"-")} -> - | D16: {=IFERROR(INDEX('美中专线（休斯顿、芝加哥）'!D4:D35,MATCH(D1,'美中专线（休斯顿、芝加哥）'!A4:A35,0)),"-")} -> -
B17: 休斯顿 普船海卡/美中专线 | C17: {=IFERROR(INDEX('美中专线（休斯顿、芝加哥）'!C43:C59,MATCH(D1,'美中专线（休斯顿、芝加哥）'!A43:A59,0)),"-")} -> - | D17: {=IFERROR(INDEX('美中专线（休斯顿、芝加哥）'!D43:D59,MATCH(D1,'美中专线（休斯顿、芝加哥）'!A43:A59,0)),"-")} -> -
A18: 萨凡纳海卡专线 （12KG+起收） | B18: 海卡/萨凡纳直航普船 | C18: {=IFERROR(INDEX(萨凡纳海卡专线!C3:C42,MATCH(D1,萨凡纳海卡专线!A3:A42,0)),"-")} -> - | D18: {=IFERROR(INDEX(萨凡纳海卡专线!D3:D42,MATCH(D1,萨凡纳海卡专线!A3:A42,0)),"-")} -> -
A19: 美东纽约海卡专线 | B19: 海卡/纽约直航普船-包税 （1方起收） | C19: {=IFERROR(INDEX(美东纽约海卡专线!C5:C87,MATCH(D1,美东纽约海卡专线!A5:A87,0)),"-")} -> - | D19: {=IFERROR(INDEX(美东纽约海卡专线!E5:E87,MATCH(D1,美东纽约海卡专线!A5:A87,0)),"-")} -> -
B20: 海卡/纽约直航普船 （12kg+起收） | C20: {=IFERROR(INDEX(美东纽约海卡专线!D5:D87,MATCH(D1,美东纽约海卡专线!A5:A87,0)),"-")} -> - | D20: {=IFERROR(INDEX(美东纽约海卡专线!E5:E87,MATCH(D1,美东纽约海卡专线!A5:A87,0)),"-")} -> -
A21: 奥克兰卡派专线 （12kg+起收） | B21: 奥克兰普船海卡/散货特价 | C21: {=IFERROR(INDEX(奥克兰卡派专线!C4:C19,MATCH(D1,奥克兰卡派专线!A4:A19,0)),"-")} -> - | D21: {=IFERROR(INDEX(奥克兰卡派专线!E4:E19,MATCH(D1,奥克兰卡派专线!A4:A19,0)),"-")} -> -
A22: 西雅图卡派专线 （12kg+起收） | B22: 西雅图海卡/散货特价 | C22: {=IFERROR(INDEX(西雅图卡派专线!C4:C9,MATCH(D1,西雅图卡派专线!A4:A9,0)),"-")} -> - | D22: {=IFERROR(INDEX(西雅图卡派专线!E4:E9,MATCH(D1,西雅图卡派专线!A4:A9,0)),"-")} -> -

Sheet 联邦超大件海派
A1: 华东区-同行价格表
A2: 联邦超大件海派 美森正班极速达 14天赔付 （CLX）
A3: 邮编/计费重 | B3: 22-68KG | C3: 普通超大尺寸：备注 （可一票多件） | D3: 40-68KG | E3: 超级大尺寸：备注 （可一票多件） | F3: 下单渠道：联邦超大件海派 美森正班极速达 14天赔付 （CLX）
A4: 邮编90-92 | B4: 22.5 | C4: 尺寸数据不能偏离以下要求： 1、 22KG ≤ 单件计费重 < 68KG 2、 240＞最大边≥125CM 第二边≥80CM 3、 270CM≤长+2*（宽+高）＜320CM | D4: 23.5 | E4: 尺寸数据不能偏离以下要求： 1、 40KG ≤ 单件计费重 < 68KG 2、 270CM>最大边≥245CM 3、 330CM≤长+2*（宽+高）＜400CM 数据超出以上任一条件，需要2500美金/件的附加费 注：单件计费重不低于40kg，不足40kg按40kg计费。 | F4: 开船后第二天开始算第14天提取 第15天开始赔偿1元/kg*天 最高赔付2元每公斤 （如遇海关查验，赔偿1元每公斤） （如遇节假日、码头停摆、港口罢工等非人为因素，不参与赔付）
A5: 邮编 8 9 （除90-92范围） | B5: 23.5 | C5: 尺寸数据不能偏离以下要求： 1、 22KG ≤ 单件计费重 < 65KG 2、 240＞最大边≥125CM 第二边≥80CM 3、 270CM≤长+2*（宽+高）＜320CM | D5: 24.5 | E5: 尺寸数据不能偏离以下要求： 1、 40KG ≤ 单件计费重 < 65KG 2、 270CM>最大边≥245CM 3、 330CM≤长+2*（宽+高）＜400CM 数据超出以上任一条件，需要2500美金/件的附加费 | F5: 开船后第二天开始算第14天提取 第15天开始赔偿1元/kg*天 最高赔付2元每公斤 （如遇海关查验，赔偿1元每公斤） （如遇节假日、码头停摆、港口罢工等非人为因素，不参与赔付）
A6: 邮编5 6 7 | B6: 24.5 | D6: 25.5
A7: 邮编 0 1 2 3 4 | B7: 24.5 | D7: 25.5
A8: 重货比优惠：整票实重大于30公斤以上，1:250 减0.5元 / 1:300 减1元 / 1:400以上 减2元；整票实重/整票方数=货重比
A10: 联邦超大件海派 美森加班限时达 18天赔付 （MAX）
A11: 邮编/计费重 | B11: 22-68KG | C11: 普通超大尺寸：备注 （可一票多件） | D11: 40-68KG | E11: 超级大尺寸：备注 （可一票多件） | F11: 下单渠道：联邦超大件海派 美森加班限时达 18天赔付 （MAX）
A12: 邮编90-92 | B12: 21.5 | C12: 尺寸数据不能偏离以下要求： 1、 22KG ≤ 单件计费重 < 68KG 2、 240＞最大边≥125CM 第二边≥80CM 3、 270CM≤长+2*（宽+高）＜320CM | D12: 22.5 | E12: 尺寸数据不能偏离以下要求： 1、 40KG ≤ 单件计费重 < 68KG 2、 270CM>最大边≥245CM 3、 330CM≤长+2*（宽+高）＜400CM 数据超出以上任一条件，需要2500美金/件的附加费 注：单件计费重不低于40kg，不足40kg按40kg计费。 | F12: 开船后第二天开始算18天提取 第19天开始赔偿1元/kg*天 最高赔付2元每公斤 （如遇海关查验，赔偿1元每公斤） （如遇节假日、码头停摆、港口罢工等非人为因素，不参与赔付）
A13: 邮编 8 9 （除90-92范围） | B13: 22.5 | C13: 尺寸数据不能偏离以下要求： 1、 22KG ≤ 单件计费重 < 65KG 2、 240＞最大边≥125CM 第二边≥80CM 3、 270CM≤长+2*（宽+高）＜320CM | D13: 23.5 | E13: 尺寸数据不能偏离以下要求： 1、 40KG ≤ 单件计费重 < 65KG 2、 270CM>最大边≥245CM 3、 330CM≤长+2*（宽+高）＜400CM 数据超出以上任一条件，需要2500美金/件的附加费
A14: 邮编5 6 7 | B14: 23.5 | D14: 24.5
A15: 邮编 0 1 2 3 4 | B15: 23.5 | D15: 24.5
A16: 重货比优惠：整票实重大于30公斤以上，1:250 减0.5元 / 1:300 减1元 / 1:400以上 减2元；整票实重/整票方数=货重比
A18: 联邦超大件海派 EXX限时达 18天赔付
A19: 邮编/计费重 | B19: 22-68KG | C19: 普通超大尺寸：备注 （可一票多件） | D19: 40-68KG | E19: 超级大尺寸：备注 （可一票多件） | F19: 下单渠道：联邦超大件海派 EXX限时达 18天赔付
A20: 邮编90-92 | B20: 19.5 | C20: 尺寸数据不能偏离以下要求： 1、 22KG ≤ 单件计费重 < 68KG 2、 240＞最大边≥125CM 第二边≥80CM 3、 270CM≤长+2*（宽+高）＜320CM | D20: 20.5 | E20: 尺寸数据不能偏离以下要求： 1、 40KG ≤ 单件计费重 < 68KG 2、 270CM>最大边≥245CM 3、 330CM≤长+2*（宽+高）＜400CM 数据超出以上任一条件，需要2500美金/件的附加费 注：单件计费重不低于40kg，不足40kg按40kg计费。 | F20: 开船后第二天开始算18天提取 第19天开始赔偿1元/kg*天 最高赔付2元每公斤 （如遇海关查验，赔偿1元每公斤） （如遇节假日、码头停摆、港口罢工等非人为因素，不参与赔付）
A21: 邮编 8 9 （除90-92范围） | B21: 20.5 | C21: 尺寸数据不能偏离以下要求： 1、 22KG ≤ 单件计费重 < 65KG 2、 240＞最大边≥125CM 第二边≥80CM 3、 270CM≤长+2*（宽+高）＜320CM | D21: 21.5 | E21: 尺寸数据不能偏离以下要求： 1、 40KG ≤ 单件计费重 < 65KG 2、 270CM>最大边≥245CM 3、 330CM≤长+2*（宽+高）＜400CM 数据超出以上任一条件，需要2500美金/件的附加费
A22: 邮编5 6 7 | B22: 21.5 | D22: 22.5
A23: 邮编 0 1 2 3 4 | B23: 21.5 | D23: 22.5
A24: 重货比优惠：整票实重大于30公斤以上，1:250 减0.5元 / 1:300 减1元 / 1:400以上 减2元；整票实重/整票方数=货重比
A26: 联邦超大件海派 合德限时达（带车架） 18天赔付
A27: 邮编/计费重 | B27: 22-68KG | C27: 普通超大尺寸：备注 （可一票多件） | D27: 40-68KG | E27: 超级大尺寸：备注 （可一票多件） | F27: 下单渠道：联邦超大件海派 合德限时达（带车架） 18天赔付
A28: 邮编90-92 | B28: 19.3 | C28: 尺寸数据不能偏离以下要求： 1、 22KG ≤ 单件计费重 < 68KG 2、 240＞最大边≥125CM 第二边≥80CM 3、 270CM≤长+2*（宽+高）＜320CM | D28: 20.3 | E28: 尺寸数据不能偏离以下要求： 1、 40KG ≤ 单件计费重 < 68KG 2、 270CM>最大边≥245CM 3、 330CM≤长+2*（宽+高）＜400CM 数据超出以上任一条件，需要2500美金/件的附加费 注：单件计费重不低于40kg，不足40kg按40kg计费。 | F28: 开船后第二天开始算18天提取 第19天开始赔偿1元/kg*天 最高赔付2元每公斤 （如遇海关查验，赔偿1元每公斤） （如遇节假日、码头停摆、港口罢工等非人为因素，不参与赔付）
A29: 邮编 8 9 （除90-92范围） | B29: 20.3 | C29: 尺寸数据不能偏离以下要求： 1、 22KG ≤ 单件计费重 < 65KG 2、 240＞最大边≥125CM 第二边≥80CM 3、 270CM≤长+2*（宽+高）＜320CM | D29: 21.3 | E29: 尺寸数据不能偏离以下要求： 1、 40KG ≤ 单件计费重 < 65KG 2、 270CM>最大边≥245CM 3、 330CM≤长+2*（宽+高）＜400CM 数据超出以上任一条件，需要2500美金/件的附加费
A30: 邮编5 6 7 | B30: 21.3 | D30: 22.3
A31: 邮编 0 1 2 3 4 | B31: 21.3 | D31: 22.3
A32: 重货比优惠：整票实重大于30公斤以上，1:250 减0.5元 / 1:300 减1元 / 1:400以上 减2元；整票实重/整票方数=货重比
A34: 联邦超大件海派 普船
A35: 邮编/计费重 | B35: 22-68KG | C35: 普通超大尺寸：备注 （可一票多件） | D35: 40-68KG | E35: 超级大尺寸：备注 （可一票多件） | F35: 下单渠道：联邦超大件海派 普船
A36: 邮编90-92 | B36: 18.3 | C36: 尺寸数据不能偏离以下要求： 1、 22KG ≤ 单件计费重 < 68KG 2、 240＞最大边≥125CM 第二边≥80CM 3、 270CM≤长+2*（宽+高）＜320CM | D36: 19.3 | E36: 尺寸数据不能偏离以下要求： 1、 40KG ≤ 单件计费重 < 68KG 2、 270CM>最大边≥245CM 3、 330CM≤长+2*（宽+高）＜400CM 数据超出以上任一条件，需要2500美金/件的附加费 注：单件计费重不低于40kg，不足40kg按40kg计费。
A37: 邮编 8 9 （除90-92范围） | B37: 19.3 | C37: 尺寸数据不能偏离以下要求： 1、 22KG ≤ 单件计费重 < 65KG 2、 240＞最大边≥125CM 第二边≥80CM 3、 270CM≤长+2*（宽+高）＜320CM | D37: 20.3 | E37: 尺寸数据不能偏离以下要求： 1、 40KG ≤ 单件计费重 < 65KG 2、 270CM>最大边≥245CM 3、 330CM≤长+2*（宽+高）＜400CM 数据超出以上任一条件，需要2500美金/件的附加费
A38: 邮编5 6 7 | B38: 20.3 | D38: 21.3
A39: 邮编 0 1 2 3 4 | B39: 20.3 | D39: 21.3
A40: 重货比优惠：整票实重大于30公斤以上，1:250 减0.5元 / 1:300 减1元 / 1:400以上 减2元；整票实重/整票方数=货重比
A42: 联邦超大件海派 普船经济线
A43: 邮编/计费重 | B43: 22-68KG | C43: 普通超大尺寸：备注 （可一票多件） | D43: 40-68KG | E43: 超级大尺寸：备注 （可一票多件） | F43: 下单渠道：联邦超大件海派 普船经济线
A44: 邮编90-92 | B44: 18 | C44: 尺寸数据不能偏离以下要求： 1、 22KG ≤ 单件计费重 < 68KG 2、 240＞最大边≥125CM 第二边≥80CM 3、 270CM≤长+2*（宽+高）＜320CM | D44: 19 | E44: 尺寸数据不能偏离以下要求： 1、 40KG ≤ 单件计费重 < 68KG 2、 270CM>最大边≥245CM 3、 330CM≤长+2*（宽+高）＜400CM 数据超出以上任一条件，需要2500美金/件的附加费 注：单件计费重不低于40kg，不足40kg按40kg计费。
A45: 邮编 8 9 （除90-92范围） | B45: 19 | C45: 尺寸数据不能偏离以下要求： 1、 22KG ≤ 单件计费重 < 65KG 2、 240＞最大边≥125CM 第二边≥80CM 3、 270CM≤长+2*（宽+高）＜320CM | D45: 20 | E45: 尺寸数据不能偏离以下要求： 1、 40KG ≤ 单件计费重 < 65KG 2、 270CM>最大边≥245CM 3、 330CM≤长+2*（宽+高）＜400CM 数据超出以上任一条件，需要2500美金/件的附加费
...

Sheet 自提-自打单-仓储
A1: 华东区-同行价格表
A2: 美国海外仓 自提 价格表
A3: 海外仓/邮编 | B3: 自提/仓储 | C3: 12KG-99KG | D3: 100KG+ | E3: 参考时效 | F3: 备注
A4: 洛杉矶海外仓 92337 | B4: 自提 美森正班船（CLX） | C4: 9.8 | D4: 8.8 | E4: 13-15天 | F4: 1、自提服务，无时效赔付 若需要做时效赔付，另行单询 | G4: 下单渠道：自提 美森正班船（CLX）
B5: 自提 美森加班船（MAX） | C5: 8.5 | D5: 7.5 | E5: 14-16天 | G5: 下单渠道：自提 美森加班船（MAX）
B6: 自提 EXX | C6: 7 | D6: 6 | E6: 15-18天 | G6: 下单渠道：自提 EXX
B7: 自提 华东合德/以星统配 （最晚周一进仓） | C7: 6.2 | D7: 5.2 | E7: 15-18天 | G7: 下单渠道：自提 华东合德/以星统配（最晚周一进仓）
B8: 自提 OA普船-LA | C8: 5.5 | D8: 4.5 | E8: 18-25天 | G8: 下单渠道：自提 OA普船-LA
B9: 自提 普船经济线-LA | C9: 5.4 | D9: 4.4 | E9: 25-30天 | G9: 下单渠道：自提 普船经济线-LA
A10: 奥克兰海外仓 94545 | B10: 自提 OA普船-OAK | C10: 5.7 | D10: 4.7 | E10: 18-25天 | G10: 下单渠道：自提 OA普船-OAK
A11: 芝加哥海外仓 60106 | B11: 自提 芝加哥普船 | C11: 7.1 | D11: 6.1 | E11: 30-40天 | G11: 下单渠道：自提 芝加哥普船
A12: 休斯顿海外仓 77091 | B12: 自提 休斯顿普船 | C12: 6.4 | D12: 5.4 | E12: 30-40天 | G12: 下单渠道：自提 休斯顿普船
A13: 萨凡纳海外仓 31407 | B13: 自提 萨凡纳普船 | C13: 6.4 | D13: 5.4 | E13: 35-45天 | G13: 下单渠道：自提 萨凡纳普船
A14: 纽约海外仓 08817 | B14: 自提 纽约普船 | C14: 6.2 | D14: 5.2 | E14: 35-45天 | G14: 下单渠道：自提 纽约普船
A15: 货重比：整票实重大于100公斤以上，享受重货比优惠：整票实重/整票方数=货重比 1:190 减0.2元 / 1:200 减0.3元 / 1:220 减0.5元 / 1:250 减0.8元 / 1:300 减1.2元 / 1:350 减1.5元 / 1:400 减1.8元 / 1:450 减2元 / 1:500 减2.2元 / 1:550 减2.5元 / ；超550以上单询；
A16: 超高加费：超过2.3米高度货物，需要加收200美金操作困难费。（原因1：影响国内装柜，顶柜货物无法装满浪费空间 原因2：海外仓卸货费时费力！） 超长附加费：超过3米长度的货物，加收200美金操作困难费。
A18: 美国海外仓 自打单 价格表
A19: 海外仓/邮编 | B19: 自提/仓储 | C19: 12KG-99KG | D19: 100KG+ | E19: 参考时效 | F19: 备注
A20: 洛杉矶海外仓 92337 | B20: 自打单 美森正班船（CLX） | C20: 9.8 | D20: 8.8 | E20: 13-15天 | F20: 1、自打单服务，无时效赔付 若需要做时效赔付，另行单询 2、请务必告知业务员，是联邦还是UPS自打单，以免我司港后无法分辨，导致海外仓分拣错误 | G20: 下单渠道：自打单 美森正班船（CLX）
B21: 自打单 美森加班船（MAX） | C21: 8.5 | D21: 7.5 | E21: 14-16天 | G21: 下单渠道：自打单 美森加班船（MAX）
B22: 自打单 EXX | C22: 7 | D22: 6 | E22: 15-18天 | G22: 下单渠道：自打单 EXX
B23: 自打单 华东合德/以星统配 （最晚周一进仓） | C23: 6.2 | D23: 5.2 | E23: 15-18天 | G23: 下单渠道：自打单 华东合德/以星统配（最晚周一进仓）
B24: 自打单 OA普船-LA | C24: 5.5 | D24: 4.5 | E24: 18-25天 | G24: 下单渠道：自打单 OA普船-LA
B25: 自打单 普船经济线-LA | C25: 5.4 | D25: 4.4 | E25: 25-30天 | G25: 下单渠道：自打单 普船经济线-LA
A26: 奥克兰海外仓 94545 | B26: 自打单 OA普船-OAK | C26: 5.7 | D26: 4.7 | E26: 18-25天 | G26: 下单渠道：自打单 OA普船-OAK
A27: 芝加哥海外仓 60106 | B27: 自打单 芝加哥普船 | C27: 7.1 | D27: 6.1 | E27: 30-40天 | G27: 下单渠道：自打单 芝加哥普船
A28: 休斯顿海外仓 77091 | B28: 自打单 休斯顿普船 | C28: 6.4 | D28: 5.4 | E28: 30-40天 | G28: 下单渠道：自打单 休斯顿普船
A29: 萨凡纳海外仓 31407 | B29: 自打单 萨凡纳普船 | C29: 6.4 | D29: 5.4 | E29: 35-45天 | G29: 下单渠道：自打单 萨凡纳普船
A30: 纽约海外仓 08817 | B30: 自打单 纽约普船 | C30: 6.2 | D30: 5.2 | E30: 35-45天 | G30: 下单渠道：自打单 纽约普船
A31: 货重比：整票实重大于100公斤以上，享受重货比优惠：整票实重/整票方数=货重比 1:190 减0.2元 / 1:200 减0.3元 / 1:220 减0.5元 / 1:250 减0.8元 / 1:300 减1.2元 / 1:350 减1.5元 / 1:400 减1.8元 / 1:450 减2元 / 1:500 减2.2元 / 1:550 减2.5元 / ；超550以上单询；
A33: 美国海外仓 仓储 价格表
A34: 海外仓/邮编 | B34: 自提/仓储 | C34: 12KG-99KG | D34: 100KG+ | E34: 参考时效 | F34: 备注
A35: 洛杉矶海外仓 92337 | B35: 仓储 美森正班船（CLX） | C35: 9.8 | D35: 8.8 | E35: 13-15天 | F35: 1、仓储服务，无时效赔付 若需要做时效赔付，另行单询 2、仓储服务，进入到美国海外仓以后，将按照客户的需求进行仓储、贴换标、派送等服务。具体费用详见海外仓价格表！！ | G35: 下单渠道：仓储 美森正班船（CLX）
B36: 仓储 美森加班船（MAX） | C36: 8.5 | D36: 7.5 | E36: 14-16天 | G36: 下单渠道：仓储 美森加班船（MAX）
B37: 仓储 EXX | C37: 7 | D37: 6 | E37: 15-18天 | G37: 下单渠道：仓储 EXX
B38: 仓储 华东合德/以星统配 （最晚周一进仓） | C38: 6.2 | D38: 5.2 | E38: 15-18天 | G38: 下单渠道：仓储 华东合德/以星统配（最晚周一进仓）
B39: 仓储 OA普船-LA | C39: 5.5 | D39: 4.5 | E39: 18-25天 | G39: 下单渠道：仓储 OA普船-LA
B40: 仓储 普船经济线-LA | C40: 5.4 | D40: 4.4 | E40: 25-30天 | G40: 下单渠道：仓储 普船经济线-LA
A41: 奥克兰海外仓 94545 | B41: 仓储 OA普船-OAK | C41: 5.7 | D41: 4.7 | E41: 18-25天 | G41: 下单渠道：仓储 OA普船-OAK
A42: 芝加哥海外仓 60106 | B42: 仓储 芝加哥普船 | C42: 7.1 | D42: 6.1 | E42: 30-40天 | G42: 下单渠道：仓储 芝加哥普船
...

Sheet 海派汇总表—DY
A1: 华东区-同行价格表 【此渠道为FBA唛头与UPS/FEDEX子单号一 一对应贴单渠道，需要额外收3元/箱操作费！！！即表价相同，额外收费！】
B2: 海派 美森极速达 14天赔付 （CLX） | E2: 海派 美森加班限时达 16天赔付 （MAX） | H2: 海派 美森加班船 （MAX） | K2: 如需要走13天的CLX时效赔付，按照海派极速达表价+0.5； 下单渠道：海派 美森极速达 13天赔付 （CLX）—DY 第14天开始赔偿1元/kg*天 最高赔付2元每公斤
A3: 国家/重量 | B3: 12KG-49KG | C3: 50KG-99KG | D3: 100KG+ | E3: 12KG-49KG | F3: 50KG-99KG | G3: 100KG+ | H3: 12KG-49KG | I3: 50KG-99KG | J3: 100KG+
A4: 美西(USW) 邮编8.9 | B4: 14.8 | C4: 12.8 | D4: 11.8 | E4: 13.8 | F4: 11.8 | G4: 10.8 | H4: 13.4 | I4: 11.4 | J4: 10.4
A5: 美中(USM) 邮编4.5.6.7 | B5: 16.3 | C5: 14.3 | D5: 13.3 | E5: 15.3 | F5: 13.3 | G5: 12.3 | H5: 14.9 | I5: 12.9 | J5: 11.9
A6: 美东(USE) 邮编0.1.2.3 | B6: 17.3 | C6: 15.3 | D6: 14.3 | E6: 16.3 | F6: 14.3 | G6: 13.3 | H6: 15.9 | I6: 13.9 | J6: 12.9
A7: 下单渠道 | B7: 下单渠道：海派 美森极速达 14天赔付 （CLX）—DY | E7: 下单渠道：海派 美森加班限时达 16天赔付 （MAX）—DY | H7: 下单渠道：海派 美森加班船—DY | K7: 如需要走12天的CLX时效赔付，按照海派极速达表价+1.5； 下单渠道：海派 美森极速达 12天赔付 （CLX）—DY 第13天开始赔偿1元/kg*天 最高赔付2元每公斤
A8: 承诺时效 | B8: 开船后第二天开始算第14天提取 第15天开始赔偿1元/kg*天 最高赔付2元每公斤 （如遇海关查验，赔偿1元每公斤） （如遇节假日、码头停摆、港口罢工、晚到港等非人为因素，不参与赔付） | E8: 开船后第二天开始算16天提取 第17天开始赔偿1元/kg*天 最高赔付2元每公斤 （如遇海关查验，赔偿1元每公斤） 如遇节假日、码头停摆、港口罢工、晚到港等非人为因素，不参与赔付） | H8: 开船后16天-20天提取
B11: 海派 普船经济线 （周六开船，25天航程，开船后30天内提取） | E11: 海派 OA普船定提统配 | H11: 海派 OA稳速达统配 25天赔付 （OA 统配） | K11: 海派 稳速达统配 22天赔付 （OA/合德/以星 统配）
A12: 国家/重量 | B12: 12KG-49KG | C12: 50KG-99KG | D12: 100KG+ | E12: 12KG-49KG | F12: 50KG-99KG | G12: 100KG+ | H12: 12KG-49KG | I12: 50KG-99KG | J12: 100KG+ | K12: 12KG-49KG | L12: 50KG-99KG | M12: 100KG+
A13: 美西(USW) 邮编8.9 | B13: 10.7 | C13: 8.7 | D13: 7.7 | E13: 10.8 | F13: 8.8 | G13: 7.8 | H13: 10.9 | I13: 8.9 | J13: 7.9 | K13: 11.2 | L13: 9.2 | M13: 8.2
A14: 美中(USM) 邮编4.5.6.7 | B14: 12.2 | C14: 10.2 | D14: 9.2 | E14: 12.3 | F14: 10.3 | G14: 9.3 | H14: 12.4 | I14: 10.4 | J14: 9.4 | K14: 12.7 | L14: 10.7 | M14: 9.7
A15: 美东(USE) 邮编0.1.2.3 | B15: 13.2 | C15: 11.2 | D15: 10.2 | E15: 13.3 | F15: 11.3 | G15: 10.3 | H15: 13.4 | I15: 11.4 | J15: 10.4 | K15: 13.7 | L15: 11.7 | M15: 10.7
A16: 下单渠道 | B16: 下单渠道：海派 普船经济线—DY | E16: 下单渠道：海派 OA普船定提统配—DY | H16: 下单渠道：海派 稳速达统配 25天赔付—DY | K16: 下单渠道：海派 稳速达统配 22天赔付—DY
A17: 承诺时效 | B17: 开船后25-30天左右提取 【宁波万海、SLS 、TSL、CMA、CUL为主】 不走杨明、马士基、现代、地中海等慢船 | E17: 开船后22-25天左右提取 【周三OA 、保舱CMA、周四SML、周日EX1、周日以星 、合德为主】 不走杨明、马士基、中联、现代、地中海等慢船 | H17: 开船后第二天开始算25天提取 第26天开始赔偿0.5元/kg*天 最高赔付1元每公斤 （如遇海关查验，赔偿0.5元每公斤） 如遇节假日、码头停摆、港口罢工、晚到港等非人为因素，不参与赔付） | K17: 开船后第二天开始算22天提取 第23天开始赔偿0.5元/kg*天 最高赔付1元每公斤 （如遇海关查验，赔偿0.5元每公斤） 如遇节假日、码头停摆、港口罢工、晚到港等非人为因素，不参与赔付）
B20: 海派 EXX限时达 18天赔付 | E20: 海派 华东合德/以星快提统配 18天赔付 华东开 二截四开 最晚周二进仓 | H20: 海派 合德/以星统配 20天赔付
A21: 国家/重量 | B21: 12KG-49KG | C21: 50KG-99KG | D21: 100KG+ | E21: 12KG-49KG | F21: 50KG-99KG | G21: 100KG+ | H21: 12KG-49KG | I21: 50KG-99KG | J21: 100KG+
A22: 美西(USW) 邮编8.9 | B22: 12 | C22: 10 | D22: 9 | E22: 11.7 | F22: 9.7 | G22: 8.7 | H22: 11.5 | I22: 9.5 | J22: 8.5
A23: 美中(USM) 邮编4.5.6.7 | B23: 13.5 | C23: 11.5 | D23: 10.5 | E23: 13.2 | F23: 11.2 | G23: 10.2 | H23: 13 | I23: 11 | J23: 10
A24: 美东(USE) 邮编0.1.2.3 | B24: 14.5 | C24: 12.5 | D24: 11.5 | E24: 14.2 | F24: 12.2 | G24: 11.2 | H24: 14 | I24: 12 | J24: 11
A25: 下单渠道 | B25: 下单渠道：海派 EXX限时达 18天赔付—DY | E25: 下单渠道：海派 华东合德/以星快提统配 18天赔付—DY | H25: 下单渠道：海派 合德/以星统配 20天赔付—DY
A26: 承诺时效 | B26: 开船后第二天开始算18天提取 第19天开始赔偿1元/kg*天 最高赔付2元每公斤 （如遇海关查验，赔偿1元每公斤） 如遇节假日、码头停摆、港口罢工、晚到港等非人为因素，不参与赔付） | E26: 开船后第二天开始算18天提取 第19天开始赔偿0.5元/kg*天 最高赔付1元每公斤 （如遇海关查验，赔偿0.5元每公斤） 如遇节假日、码头停摆、港口罢工、晚到港等非人为因素，不参与赔付 | H26: 开船后第二天开始算20天提取 第21天开始赔偿0.5元/kg*天 最高赔付1元每公斤 （如遇海关查验，赔偿0.5元每公斤） 如遇节假日、码头停摆、港口罢工、晚到港等非人为因素，不参与赔付）
B29: 海派 休斯顿OA快普 （开船后35-40天内提取） | E29: 海派 芝加哥OA快普 （开船后35-40天内提取） | H29: 海派 美东OA快普 （开船后35-40天内提取）
A30: 国家/重量 | B30: 12KG-49KG | C30: 50KG-99KG | D30: 100KG+ | E30: 12KG-49KG | F30: 50KG-99KG | G30: 100KG+ | H30: 12KG-49KG | I30: 50KG-99KG | J30: 100KG+
A31: 邮编7 | B31: 11.9 | C31: 9.9 | D31: 8.9 | E31: / | F31: / | G31: / | H31: / | I31: / | J31: /
A32: 邮编4.5.6 | B32: / | C32: / | D32: / | E32: 12.2 | F32: 10.2 | G32: 9.2 | H32: / | I32: / | J32: /
A33: 邮编0.1.2.3 | B33: / | C33: / | D33: / | E33: / | F33: / | G33: / | H33: 11.9 | I33: 9.9 | J33: 8.9
A34: 下单渠道 | B34: 下单渠道：海派 休斯顿OA快普—DY | E34: 下单渠道：海派 芝加哥OA快普—DY | H34: 下单渠道：海派 美东OA快普—DY
A35: 承诺时效 | B35: 开船后30-40天左右提取 以OA船直航为主 | E35: 开船后25-35天左右提取 以EXX-芝加哥、OA船为主 | H35: 开船后35-45天左右提取 以OA船直航为主
A36: 货重比：整票实重大于100公斤以上，享受重货比优惠：整票实重/整票方数=货重比 美森/EXX货重比优惠：1:190 减0.2元 / 1:200 减0.3元 / 1:220 减0.5元 / 1:250 减0.8元 / 1:300 减1.2元 / 1:350 减1.5元 / 1:400 减1.8元 / 1:450 减2元 / 1:500 减2.2元 / 1:550 减2.5元 / ；超550以上单询； 合德/以星/普船： 1:220 减0.2元 / 1:250 减0.5元 / 1:300 减0.8元 / 1:400 减1.5元 / 1:500 减1.8元 ；超550以上单询；
A37: 单件最低计费12KG，单件不超22公斤； 非FBA地址（私人地址）：+1元/KG； 免商业地址附加费 后程UPS/联邦双渠道派送，亚马逊地址以UPS打单为主，指定打单（需单独申请，如打单不亏损情况下允许指定打单+1） 偏远收费：商业地址偏远和住宅私人地址偏远，统收30元/件。（如私人地址偏远，私人地址+1，以及住宅偏远30元/件；） 报关件的商检费实报实销，最低收300/票 报关费统收200元/票。合并报关费，收250元/票。
A38: 我司承诺：所有客户送我司美森货物如我司装非美森渠道，退运费且赔偿40元/公斤，货物正常转运派送

Sheet 海派汇总表
A1: 华东区-同行价格表
B2: 海派 美森极速达 14天赔付 （CLX） | E2: 海派 美森加班限时达 16天赔付 （MAX） | H2: 海派 美森加班船 （MAX） | K2: 如需要走13天的CLX时效赔付，按照海派极速达表价+0.5； 下单渠道：海派 美森极速达 13天赔付 （CLX） 第14天开始赔偿1元/kg*天 最高赔付2元每公斤
A3: 国家/重量 | B3: 12KG-49KG | C3: 50KG-99KG | D3: 100KG+ | E3: 12KG-49KG | F3: 50KG-99KG | G3: 100KG+ | H3: 12KG-49KG | I3: 50KG-99KG | J3: 100KG+
A4: 美西(USW) 邮编8.9 | B4: 14.8 | C4: 12.8 | D4: 11.8 | E4: 13.8 | F4: 11.8 | G4: 10.8 | H4: 13.4 | I4: 11.4 | J4: 10.4
A5: 美中(USM) 邮编4.5.6.7 | B5: 16.3 | C5: 14.3 | D5: 13.3 | E5: 15.3 | F5: 13.3 | G5: 12.3 | H5: 14.9 | I5: 12.9 | J5: 11.9
A6: 美东(USE) 邮编0.1.2.3 | B6: 17.3 | C6: 15.3 | D6: 14.3 | E6: 16.3 | F6: 14.3 | G6: 13.3 | H6: 15.9 | I6: 13.9 | J6: 12.9
A7: 下单渠道 | B7: 下单渠道：海派 美森极速达 14天赔付 （CLX） | E7: 下单渠道：海派 美森加班限时达 16天赔付 （MAX） | H7: 下单渠道：海派 美森加班船 | K7: 如需要走12天的CLX时效赔付，按照海派极速达表价+1.5； 下单渠道：海派 美森极速达 12天赔付 （CLX） 第13天开始赔偿1元/kg*天 最高赔付2元每公斤
A8: 承诺时效 | B8: 开船后第二天开始算第14天提取 第15天开始赔偿1元/kg*天 最高赔付2元每公斤 （如遇海关查验，赔偿1元每公斤） （如遇节假日、码头停摆、港口罢工、晚到港等非人为因素，不参与赔付） | E8: 开船后第二天开始算16天提取 第17天开始赔偿1元/kg*天 最高赔付2元每公斤 （如遇海关查验，赔偿1元每公斤） 如遇节假日、码头停摆、港口罢工、晚到港等非人为因素，不参与赔付） | H8: 开船后16天-20天提取
B11: 海派 普船经济线 （周六开船，25天航程，开船后30天内提取） | E11: 海派 OA普船定提统配 | H11: 海派 OA稳速达统配 25天赔付 （OA 统配） | K11: 海派 稳速达统配 22天赔付 （OA/合德/以星 统配）
A12: 国家/重量 | B12: 12KG-49KG | C12: 50KG-99KG | D12: 100KG+ | E12: 12KG-49KG | F12: 50KG-99KG | G12: 100KG+ | H12: 12KG-49KG | I12: 50KG-99KG | J12: 100KG+ | K12: 12KG-49KG | L12: 50KG-99KG | M12: 100KG+
A13: 美西(USW) 邮编8.9 | B13: 10.7 | C13: 8.7 | D13: 7.7 | E13: 10.8 | F13: 8.8 | G13: 7.8 | H13: 10.9 | I13: 8.9 | J13: 7.9 | K13: 11.2 | L13: 9.2 | M13: 8.2
A14: 美中(USM) 邮编4.5.6.7 | B14: 12.2 | C14: 10.2 | D14: 9.2 | E14: 12.3 | F14: 10.3 | G14: 9.3 | H14: 12.4 | I14: 10.4 | J14: 9.4 | K14: 12.7 | L14: 10.7 | M14: 9.7
A15: 美东(USE) 邮编0.1.2.3 | B15: 13.2 | C15: 11.2 | D15: 10.2 | E15: 13.3 | F15: 11.3 | G15: 10.3 | H15: 13.4 | I15: 11.4 | J15: 10.4 | K15: 13.7 | L15: 11.7 | M15: 10.7
A16: 下单渠道 | B16: 下单渠道：海派 普船经济线 | E16: 下单渠道：海派 OA普船定提统配 | H16: 下单渠道：海派 稳速达统配 25天赔付 | K16: 下单渠道：海派 稳速达统配 22天赔付
A17: 承诺时效 | B17: 开船后25-30天左右提取 【宁波万海、SLS 、TSL、CMA、CUL为主】 不走杨明、马士基、现代、地中海等慢船 | E17: 开船后22-25天左右提取 【周三OA 、保舱CMA、周四SML、周日EX1、周日以星 、合德为主】 不走杨明、马士基、中联、现代、地中海等慢船 | H17: 开船后第二天开始算25天提取 第26天开始赔偿0.5元/kg*天 最高赔付1元每公斤 （如遇海关查验，赔偿0.5元每公斤） 如遇节假日、码头停摆、港口罢工、晚到港等非人为因素，不参与赔付） | K17: 开船后第二天开始算22天提取 第23天开始赔偿0.5元/kg*天 最高赔付1元每公斤 （如遇海关查验，赔偿0.5元每公斤） 如遇节假日、码头停摆、港口罢工、晚到港等非人为因素，不参与赔付）
B20: 海派 EXX限时达 18天赔付 | E20: 海派 华东合德/以星快提统配 18天赔付 华东开 二截四开 最晚周二进仓 | H20: 海派 合德/以星统配 20天赔付
A21: 国家/重量 | B21: 12KG-49KG | C21: 50KG-99KG | D21: 100KG+ | E21: 12KG-49KG | F21: 50KG-99KG | G21: 100KG+ | H21: 12KG-49KG | I21: 50KG-99KG | J21: 100KG+
A22: 美西(USW) 邮编8.9 | B22: 12 | C22: 10 | D22: 9 | E22: 11.7 | F22: 9.7 | G22: 8.7 | H22: 11.5 | I22: 9.5 | J22: 8.5
A23: 美中(USM) 邮编4.5.6.7 | B23: 13.5 | C23: 11.5 | D23: 10.5 | E23: 13.2 | F23: 11.2 | G23: 10.2 | H23: 13 | I23: 11 | J23: 10
A24: 美东(USE) 邮编0.1.2.3 | B24: 14.5 | C24: 12.5 | D24: 11.5 | E24: 14.2 | F24: 12.2 | G24: 11.2 | H24: 14 | I24: 12 | J24: 11
A25: 下单渠道 | B25: 下单渠道：海派 EXX限时达 18天赔付 | E25: 下单渠道：海派 华东合德/以星快提统配 18天赔付 | H25: 下单渠道：海派 合德/以星统配 20天赔付
A26: 承诺时效 | B26: 开船后第二天开始算18天提取 第19天开始赔偿1元/kg*天 最高赔付2元每公斤 （如遇海关查验，赔偿1元每公斤） 如遇节假日、码头停摆、港口罢工、晚到港等非人为因素，不参与赔付） | E26: 开船后第二天开始算18天提取 第19天开始赔偿0.5元/kg*天 最高赔付1元每公斤 （如遇海关查验，赔偿0.5元每公斤） 如遇节假日、码头停摆、港口罢工、晚到港等非人为因素，不参与赔付 | H26: 开船后第二天开始算20天提取 第21天开始赔偿0.5元/kg*天 最高赔付1元每公斤 （如遇海关查验，赔偿0.5元每公斤） 如遇节假日、码头停摆、港口罢工、晚到港等非人为因素，不参与赔付）
B29: 海派 休斯顿OA快普 （开船后35-40天内提取） | E29: 海派 芝加哥OA快普 （开船后35-40天内提取） | H29: 海派 美东OA快普 （开船后35-40天内提取）
A30: 国家/重量 | B30: 12KG-49KG | C30: 50KG-99KG | D30: 100KG+ | E30: 12KG-49KG | F30: 50KG-99KG | G30: 100KG+ | H30: 12KG-49KG | I30: 50KG-99KG | J30: 100KG+
A31: 邮编7 | B31: 11.9 | C31: 9.9 | D31: 8.9 | E31: / | F31: / | G31: / | H31: / | I31: / | J31: /
A32: 邮编4.5.6 | B32: / | C32: / | D32: / | E32: 12.2 | F32: 10.2 | G32: 9.2 | H32: / | I32: / | J32: /
A33: 邮编0.1.2.3 | B33: / | C33: / | D33: / | E33: / | F33: / | G33: / | H33: 11.9 | I33: 9.9 | J33: 8.9
A34: 下单渠道 | B34: 下单渠道：海派 休斯顿OA快普 | E34: 下单渠道：海派 芝加哥OA快普 | H34: 下单渠道：海派 美东OA快普
A35: 承诺时效 | B35: 开船后30-40天左右提取 以OA船直航为主 | E35: 开船后25-35天左右提取 以EXX-芝加哥、OA船为主 | H35: 开船后35-45天左右提取 以OA船直航为主
A36: 货重比：整票实重大于100公斤以上，享受重货比优惠：整票实重/整票方数=货重比 美森/EXX货重比优惠：1:190 减0.2元 / 1:200 减0.3元 / 1:220 减0.5元 / 1:250 减0.8元 / 1:300 减1.2元 / 1:350 减1.5元 / 1:400 减1.8元 / 1:450 减2元 / 1:500 减2.2元 / 1:550 减2.5元 / ；超550以上单询； 合德/以星/普船： 1:220 减0.2元 / 1:250 减0.5元 / 1:300 减0.8元 / 1:400 减1.5元 / 1:500 减1.8元 ；超550以上单询；
A37: 单件最低计费12KG，单件不超22公斤； 非FBA地址（私人地址）：+1元/KG； 免商业地址附加费 后程UPS/联邦双渠道派送，亚马逊地址以UPS打单为主，指定打单（需单独申请，如打单不亏损情况下允许指定打单+1） 偏远收费：商业地址偏远和住宅私人地址偏远，统收30元/件。（如私人地址偏远，私人地址+1，以及住宅偏远30元/件；） 报关件的商检费实报实销，最低收300/票 报关费统收200元/票。合并报关费，收250元/票。
A38: 我司承诺：所有客户送我司美森货物如我司装非美森渠道，退运费且赔偿40元/公斤，货物正常转运派送

Sheet 美西海卡汇总表
A1: 华东区-美西海卡各渠道拆柜汇总表
A2: FBA仓库代码 | B2: 目的邮编 | C2: 计费重起收点 | D2: 下单渠道： 海卡/美森极速达（CLX） 【带赔付】 | F2: 下单渠道： 海卡/美森极速达（CLX） | H2: 下单渠道： 海卡/美森加班船（MAX ） 【带赔付】 | J2: 下单渠道： 海卡/美森加班船（MAX ） | L2: 下单渠道： 海卡/EXX限时达【带赔付】 | N2: 下单渠道： 海卡/华东合德/以星限时达统配 【带赔付】 （最晚周二进仓） | P2: 下单渠道： 海卡/OA稳速达【带赔付】 （最晚周一进仓） | R2: 下单渠道： 海卡/OA普船定提统配 | T2: 下单渠道： 海卡/普船经济线 （周六开船，25天航程）
D3: CLX 周三开 | E3: 赔付时效 签收提供POD | F3: CLX 周三开 | G3: 最快时效 | H3: MAX周四开 | I3: 赔付时效 签收提供POD | J3: MAX 周四开 | K3: 最快时效 | L3: 周四开 | M3: 赔付时效 签收提供POD | N3: 二截四开 | O3: 赔付时效 签收提供POD | P3: 周四开 | Q3: 赔付时效 签收提供POD
A4: ONT8 | B4: 92551 | C4: A【一区】 12KG+ | D4: 8.3 | E4: 19天赔付 | F4: 8 | G4: 15-22天 | H4: 7.3 | I4: 20天赔付 | J4: 7 | K4: 17-23天 | L4: 5.3 | M4: 21天赔付 | N4: 4.7 | O4: 25天赔付 | P4: 4.4 | Q4: 28天赔付 | R4: 4.3 | S4: 20-25天 | T4: 4.2 | U4: 25-30天
A5: LAX9 | B5: 92337 | D5: 8.3 | E5: 19天赔付 | F5: 8 | G5: 15-22天 | H5: 7.3 | I5: 20天赔付 | J5: 7 | K5: 17-23天 | L5: 5.3 | M5: 21天赔付 | N5: 4.7 | O5: 25天赔付 | P5: 4.4 | Q5: 28天赔付 | R5: 4.3 | S5: 20-25天 | T5: 4.2 | U5: 25-30天
A6: LGB8 | B6: 92376 | D6: 8.3 | E6: 19天赔付 | F6: 8 | G6: 15-22天 | H6: 7.3 | I6: 20天赔付 | J6: 7 | K6: 17-23天 | L6: 5.3 | M6: 21天赔付 | N6: 4.7 | O6: 25天赔付 | P6: 4.4 | Q6: 28天赔付 | R6: 4.3 | S6: 20-25天 | T6: 4.2 | U6: 25-30天
A7: SBD1 | B7: 92316-3819 | D7: 8.3 | E7: 19天赔付 | F7: 8 | G7: 15-22天 | H7: 7.3 | I7: 20天赔付 | J7: 7 | K7: 17-23天 | L7: 5.3 | M7: 21天赔付 | N7: 4.7 | O7: 25天赔付 | P7: 4.4 | Q7: 28天赔付 | R7: 4.3 | S7: 20-25天 | T7: 4.2 | U7: 25-30天
A8: SNA4 | B8: 92376 | C8: B【一区】 12KG+ | D8: 8.4 | E8: 19天赔付 | F8: 8.1 | G8: 15-22天 | H8: 7.4 | I8: 20天赔付 | J8: 7.1 | K8: 17-23天 | L8: 5.4 | M8: 21天赔付 | N8: 4.8 | O8: 25天赔付 | P8: 4.5 | Q8: 28天赔付 | R8: 4.4 | S8: 20-25天 | T8: 4.3 | U8: 25-30天
A9: SBD2 | B9: 92408 | D9: 8.4 | E9: 19天赔付 | F9: 8.1 | G9: 15-22天 | H9: 7.4 | I9: 20天赔付 | J9: 7.1 | K9: 17-23天 | L9: 5.4 | M9: 21天赔付 | N9: 4.8 | O9: 25天赔付 | P9: 4.5 | Q9: 28天赔付 | R9: 4.4 | S9: 20-25天 | T9: 4.3 | U9: 25-30天
A10: SBD3 | B10: 92407 | D10: 8.4 | E10: 19天赔付 | F10: 8.1 | G10: 15-22天 | H10: 7.4 | I10: 20天赔付 | J10: 7.1 | K10: 17-23天 | L10: 5.4 | M10: 21天赔付 | N10: 4.8 | O10: 25天赔付 | P10: 4.5 | Q10: 28天赔付 | R10: 4.4 | S10: 20-25天 | T10: 4.3 | U10: 25-30天
A11: LGB4 | B11: 92374 | D11: 8.4 | E11: 19天赔付 | F11: 8.1 | G11: 15-22天 | H11: 7.4 | I11: 20天赔付 | J11: 7.1 | K11: 17-23天 | L11: 5.4 | M11: 21天赔付 | N11: 4.8 | O11: 25天赔付 | P11: 4.5 | Q11: 28天赔付 | R11: 4.4 | S11: 20-25天 | T11: 4.3 | U11: 25-30天
A12: LGB6 | B12: 92518-1513 | D12: 8.4 | E12: 19天赔付 | F12: 8.1 | G12: 15-22天 | H12: 7.4 | I12: 20天赔付 | J12: 7.1 | K12: 17-23天 | L12: 5.4 | M12: 21天赔付 | N12: 4.8 | O12: 25天赔付 | P12: 4.5 | Q12: 28天赔付 | R12: 4.4 | S12: 20-25天 | T12: 4.3 | U12: 25-30天
A13: LGB9 | B13: 90810 | D13: 8.4 | E13: 19天赔付 | F13: 8.1 | G13: 15-22天 | H13: 7.4 | I13: 20天赔付 | J13: 7.1 | K13: 17-23天 | L13: 5.4 | M13: 21天赔付 | N13: 4.8 | O13: 25天赔付 | P13: 4.5 | Q13: 28天赔付 | R13: 4.4 | S13: 20-25天 | T13: 4.3 | U13: 25-30天
A14: ONT2 | B14: 92408-0123 | D14: 8.4 | E14: 19天赔付 | F14: 8.1 | G14: 15-22天 | H14: 7.4 | I14: 20天赔付 | J14: 7.1 | K14: 17-23天 | L14: 5.4 | M14: 21天赔付 | N14: 4.8 | O14: 25天赔付 | P14: 4.5 | Q14: 28天赔付 | R14: 4.4 | S14: 20-25天 | T14: 4.3 | U14: 25-30天
A15: ONT6 | B15: 92551-9561 | D15: 8.4 | E15: 19天赔付 | F15: 8.1 | G15: 15-22天 | H15: 7.4 | I15: 20天赔付 | J15: 7.1 | K15: 17-23天 | L15: 5.4 | M15: 21天赔付 | N15: 4.8 | O15: 25天赔付 | P15: 4.5 | Q15: 28天赔付 | R15: 4.4 | S15: 20-25天 | T15: 4.3 | U15: 25-30天
A16: ONT9 | B16: 92374 | D16: 8.4 | E16: 19天赔付 | F16: 8.1 | G16: 15-22天 | H16: 7.4 | I16: 20天赔付 | J16: 7.1 | K16: 17-23天 | L16: 5.4 | M16: 21天赔付 | N16: 4.8 | O16: 25天赔付 | P16: 4.5 | Q16: 28天赔付 | R16: 4.4 | S16: 20-25天 | T16: 4.3 | U16: 25-30天
A17: XLX7 | B17: 92394 | D17: 8.4 | E17: 19天赔付 | F17: 8.1 | G17: 15-22天 | H17: 7.4 | I17: 20天赔付 | J17: 7.1 | K17: 17-23天 | L17: 5.4 | M17: 21天赔付 | N17: 4.8 | O17: 25天赔付 | P17: 4.5 | Q17: 28天赔付 | R17: 4.4 | S17: 20-25天 | T17: 4.3 | U17: 25-30天
A18: IUSJ | B18: 92223 | D18: 8.4 | E18: 19天赔付 | F18: 8.1 | G18: 15-22天 | H18: 7.4 | I18: 20天赔付 | J18: 7.1 | K18: 17-23天 | L18: 5.4 | M18: 21天赔付 | N18: 4.8 | O18: 25天赔付 | P18: 4.5 | Q18: 28天赔付 | R18: 4.4 | S18: 20-25天 | T18: 4.3 | U18: 25-30天
A19: IUSQ | B19: 92374 | D19: 8.4 | E19: 19天赔付 | F19: 8.1 | G19: 15-22天 | H19: 7.4 | I19: 20天赔付 | J19: 7.1 | K19: 17-23天 | L19: 5.4 | M19: 21天赔付 | N19: 4.8 | O19: 25天赔付 | P19: 4.5 | Q19: 28天赔付 | R19: 4.4 | S19: 20-25天 | T19: 4.3 | U19: 25-30天
A20: IUSP | B20: 92344 | D20: 8.4 | E20: 19天赔付 | F20: 8.1 | G20: 15-22天 | H20: 7.4 | I20: 20天赔付 | J20: 7.1 | K20: 17-23天 | L20: 5.4 | M20: 21天赔付 | N20: 4.8 | O20: 25天赔付 | P20: 4.5 | Q20: 28天赔付 | R20: 4.4 | S20: 20-25天 | T20: 4.3 | U20: 25-30天
A21: POC1 | B21: 92336-1123 | D21: 8.4 | E21: 19天赔付 | F21: 8.1 | G21: 15-22天 | H21: 7.4 | I21: 20天赔付 | J21: 7.1 | K21: 17-23天 | L21: 5.4 | M21: 21天赔付 | N21: 4.8 | O21: 25天赔付 | P21: 4.5 | Q21: 28天赔付 | R21: 4.4 | S21: 20-25天 | T21: 4.3 | U21: 25-30天
A22: POC2 | B22: 91761 | D22: 8.4 | E22: 19天赔付 | F22: 8.1 | G22: 15-22天 | H22: 7.4 | I22: 20天赔付 | J22: 7.1 | K22: 17-23天 | L22: 5.4 | M22: 21天赔付 | N22: 4.8 | O22: 25天赔付 | P22: 4.5 | Q22: 28天赔付 | R22: 4.4 | S22: 20-25天 | T22: 4.3 | U22: 25-30天
A23: POC3 | B23: 92509 | D23: 8.4 | E23: 19天赔付 | F23: 8.1 | G23: 15-22天 | H23: 7.4 | I23: 20天赔付 | J23: 7.1 | K23: 17-23天 | L23: 5.4 | M23: 21天赔付 | N23: 4.8 | O23: 25天赔付 | P23: 4.5 | Q23: 28天赔付 | R23: 4.4 | S23: 20-25天 | T23: 4.3 | U23: 25-30天
A24: IUTI | B24: 92374-5015 | D24: 8.4 | E24: 19天赔付 | F24: 8.1 | G24: 15-22天 | H24: 7.4 | I24: 20天赔付 | J24: 7.1 | K24: 17-23天 | L24: 5.4 | M24: 21天赔付 | N24: 4.8 | O24: 25天赔付 | P24: 4.5 | Q24: 28天赔付 | R24: 4.4 | S24: 20-25天 | T24: 4.3 | U24: 25-30天
A25: IUSW | B25: 92344 | D25: 8.4 | E25: 19天赔付 | F25: 8.1 | G25: 15-22天 | H25: 7.4 | I25: 20天赔付 | J25: 7.1 | K25: 17-23天 | L25: 5.4 | M25: 21天赔付 | N25: 4.8 | O25: 25天赔付 | P25: 4.5 | Q25: 28天赔付 | R25: 4.4 | S25: 20-25天 | T25: 4.3 | U25: 25-30天
A26: IUTE | B26: 85338 | D26: 8.4 | E26: 19天赔付 | F26: 8.1 | G26: 15-22天 | H26: 7.4 | I26: 20天赔付 | J26: 7.1 | K26: 17-23天 | L26: 5.4 | M26: 21天赔付 | N26: 4.8 | O26: 25天赔付 | P26: 4.5 | Q26: 28天赔付 | R26: 4.4 | S26: 20-25天 | T26: 4.3 | U26: 25-30天
A27: LAS1 | B27: 89044 | C27: A【二区】 12KG+ | D27: 9 | E27: 21天赔付 | F27: 8.7 | G27: 15-22天 | H27: 8 | I27: 22天赔付 | J27: 7.7 | K27: 17-23天 | L27: 6 | M27: 23天赔付 | N27: 5.4 | O27: 28天赔付 | P27: 5.1 | Q27: 31天赔付 | R27: 5 | S27: 23-30天 | T27: 4.9 | U27: 25-35天
A28: VGT2 | B28: 89115 | D28: 9 | E28: 21天赔付 | F28: 8.7 | G28: 15-22天 | H28: 8 | I28: 22天赔付 | J28: 7.7 | K28: 17-23天 | L28: 6 | M28: 23天赔付 | N28: 5.4 | O28: 28天赔付 | P28: 5.1 | Q28: 31天赔付 | R28: 5 | S28: 23-30天 | T28: 4.9 | U28: 25-35天
A29: GYR2 | B29: 85395 | D29: 9 | E29: 21天赔付 | F29: 8.7 | G29: 15-22天 | H29: 8 | I29: 22天赔付 | J29: 7.7 | K29: 17-23天 | L29: 6 | M29: 23天赔付 | N29: 5.4 | O29: 28天赔付 | P29: 5.1 | Q29: 31天赔付 | R29: 5 | S29: 23-30天 | T29: 4.9 | U29: 25-35天
A30: GYR3 | B30: 85043 | D30: 9 | E30: 21天赔付 | F30: 8.7 | G30: 15-22天 | H30: 8 | I30: 22天赔付 | J30: 7.7 | K30: 17-23天 | L30: 6 | M30: 23天赔付 | N30: 5.4 | O30: 28天赔付 | P30: 5.1 | Q30: 31天赔付 | R30: 5 | S30: 23-30天 | T30: 4.9 | U30: 25-35天
A31: SMF3 | B31: 95206 | D31: 9 | E31: 21天赔付 | F31: 8.7 | G31: 15-22天 | H31: 8 | I31: 22天赔付 | J31: 7.7 | K31: 17-23天 | L31: 6 | M31: 23天赔付 | N31: 5.4 | O31: 28天赔付 | P31: 5.1 | Q31: 31天赔付 | R31: 5 | S31: 23-30天 | T31: 4.9 | U31: 25-35天
A32: SCK4 | B32: 95215 | D32: 9 | E32: 21天赔付 | F32: 8.7 | G32: 15-22天 | H32: 8 | I32: 22天赔付 | J32: 7.7 | K32: 17-23天 | L32: 6 | M32: 23天赔付 | N32: 5.4 | O32: 28天赔付 | P32: 5.1 | Q32: 31天赔付 | R32: 5 | S32: 23-30天 | T32: 4.9 | U32: 25-35天
A33: MIT2 | B33: 93263 | D33: 9 | E33: 21天赔付 | F33: 8.7 | G33: 15-22天 | H33: 8 | I33: 22天赔付 | J33: 7.7 | K33: 17-23天 | L33: 6 | M33: 23天赔付 | N33: 5.4 | O33: 28天赔付 | P33: 5.1 | Q33: 31天赔付 | R33: 5 | S33: 23-30天 | T33: 4.9 | U33: 25-35天
A34: GEU2 | B34: 85340 | D34: 9 | E34: 21天赔付 | F34: 8.7 | G34: 15-22天 | H34: 8 | I34: 22天赔付 | J34: 7.7 | K34: 17-23天 | L34: 6 | M34: 23天赔付 | N34: 5.4 | O34: 28天赔付 | P34: 5.1 | Q34: 31天赔付 | R34: 5 | S34: 23-30天 | T34: 4.9 | U34: 25-35天
A35: GEU3 | B35: 85326 | D35: 9 | E35: 21天赔付 | F35: 8.7 | G35: 15-22天 | H35: 8 | I35: 22天赔付 | J35: 7.7 | K35: 17-23天 | L35: 6 | M35: 23天赔付 | N35: 5.4 | O35: 28天赔付 | P35: 5.1 | Q35: 31天赔付 | R35: 5 | S35: 23-30天 | T35: 4.9 | U35: 25-35天
A36: GEU5 | B36: 85395 | D36: 9 | E36: 21天赔付 | F36: 8.7 | G36: 15-22天 | H36: 8 | I36: 22天赔付 | J36: 7.7 | K36: 17-23天 | L36: 6 | M36: 23天赔付 | N36: 5.4 | O36: 28天赔付 | P36: 5.1 | Q36: 31天赔付 | R36: 5 | S36: 23-30天 | T36: 4.9 | U36: 25-35天
A37: HLI2 | B37: 95023 | D37: 9 | E37: 21天赔付 | F37: 8.7 | G37: 15-22天 | H37: 8 | I37: 22天赔付 | J37: 7.7 | K37: 17-23天 | L37: 6 | M37: 23天赔付 | N37: 5.4 | O37: 28天赔付 | P37: 5.1 | Q37: 31天赔付 | R37: 5 | S37: 23-30天 | T37: 4.9 | U37: 25-35天
A38: TCY1 | B38: 95206 | D38: 9 | E38: 21天赔付 | F38: 8.7 | G38: 15-22天 | H38: 8 | I38: 22天赔付 | J38: 7.7 | K38: 17-23天 | L38: 6 | M38: 23天赔付 | N38: 5.4 | O38: 28天赔付 | P38: 5.1 | Q38: 31天赔付 | R38: 5 | S38: 23-30天 | T38: 4.9 | U38: 25-35天
A39: TCY2 | B39: 95215 | D39: 9 | E39: 21天赔付 | F39: 8.7 | G39: 15-22天 | H39: 8 | I39: 22天赔付 | J39: 7.7 | K39: 17-23天 | L39: 6 | M39: 23天赔付 | N39: 5.4 | O39: 28天赔付 | P39: 5.1 | Q39: 31天赔付 | R39: 5 | S39: 23-30天 | T39: 4.9 | U39: 25-35天
A40: SCK8 | B40: 94561 | D40: 9 | E40: 21天赔付 | F40: 8.7 | G40: 15-22天 | H40: 8 | I40: 22天赔付 | J40: 7.7 | K40: 17-23天 | L40: 6 | M40: 23天赔付 | N40: 5.4 | O40: 28天赔付 | P40: 5.1 | Q40: 31天赔付 | R40: 5 | S40: 23-30天 | T40: 4.9 | U40: 25-35天
...

Sheet 普船海卡整柜直送
A1: 华东区-普船整柜直送汇总表
A2: 美西 七大仓直送价
A3: FBA仓库代码 | B3: 目的邮编 | C3: 计费重起收点 | D3: 价格 | E3: 整柜直送 整柜价 （我司仓库装柜，全包到门） | F3: 签收时效 | G3: 配送方式 | H3: 下单渠道：美西普船海卡/整柜直送
A4: ONT8 | B4: 92551 | C4: 12KG+ | D4: 4.1 | E4: / | F4: 25-32天 | G4: 专车配送 | H4: 指定船型：周三OA普船、周四SML、周四合德/以星
A5: LAX9 | B5: 92337 | C5: 12KG+ | D5: 4.1 | F5: 25-32天 | G5: 专车配送
A6: LGB8 | B6: 92376 | C6: 12KG+ | D6: 4.1 | F6: 25-32天 | G6: 专车配送
A7: SBD1 | B7: 92316-3819 | C7: 12KG+ | D7: 4.1 | F7: 25-32天 | G7: 专车配送
A8: IUSJ | B8: 92223 | C8: 12KG+ | D8: 4.3 | F8: 25-32天 | G8: 专车配送
A9: IUSQ | B9: 92374 | C9: 12KG+ | D9: 4.3 | F9: 25-32天 | G9: 专车配送
A10: IUSP | B10: 92344 | C10: 12KG+ | D10: 4.3 | F10: 25-32天 | G10: 专车配送
A11: POC1 | B11: 92336-1123 | C11: 12KG+ | D11: 4.3 | F11: 25-32天 | G11: 专车配送
A12: POC2 | B12: 91761 | C12: 12KG+ | D12: 4.3 | F12: 25-32天 | G12: 专车配送
A13: POC3 | B13: 92509 | C13: 12KG+ | D13: 4.3 | F13: 25-32天 | G13: 专车配送
A14: VGT2 | B14: 89115 | C14: 12KG+ | D14: 4.6 | E14: / | F14: 25-32天 | G14: 专车配送
A15: LAS1 | B15: 89044 | C15: 12KG+ | D15: 4.6 | F15: 25-32天 | G15: 专车配送
A16: GYR3 | B16: 85043 | C16: 12KG+ | D16: 4.6 | F16: 25-32天 | G16: 专车配送
A17: GYR2 | B17: 85395 | C17: 12KG+ | D17: 4.6 | F17: 25-32天 | G17: 专车配送
A18: MIT2 | B18: 93263 | C18: 12KG+ | D18: 4.6 | F18: 25-32天 | G18: 专车配送
A19: GEU2 | B19: 85340 | C19: 12KG+ | D19: 4.6 | F19: 25-32天 | G19: 专车配送
A20: GEU3 | B20: 85326 | C20: 12KG+ | D20: 4.6 | F20: 25-32天 | G20: 专车配送
A21: GEU5 | B21: 85395 | C21: 12KG+ | D21: 4.6 | F21: 25-32天 | G21: 专车配送
A22: ABQ2 | B22: 87031 | C22: 12KG+ | D22: 6 | E22: / | F22: 25-32天 | G22: 专车配送
A24: 奥克兰 三大仓直送价
A25: FBA仓库代码 | B25: 目的邮编 | C25: 计费重起收点 | D25: 价格 | E25: 整柜直送 整柜价 （我司仓库装柜，全包到门） | F25: 签收时效 | G25: 配送方式 | H25: 下单渠道：奥克兰普船海卡/整柜直送
A26: SCK4 | B26: 95215 | C26: 12KG+ | D26: 4.6 | E26: / | F26: 25-32天 | G26: 专车配送 | H26: 指定船型：OA普船、EXX、EX1统配
A27: SMF3 | B27: 95206 | C27: 12KG+ | D27: 4.6 | F27: 25-32天 | G27: 专车配送
A28: OAK3 | B28: 95363 | C28: 12KG+ | D28: 4.6 | F28: 25-32天 | G28: 专车配送
A29: HLI2 | B29: 95023 | C29: 12KG+ | D29: 4.6 | F29: 25-32天 | G29: 专车配送
A30: TCY1 | B30: 95206 | C30: 12KG+ | D30: 4.6 | F30: 25-32天 | G30: 专车配送
A31: TCY2 | B31: 95215 | C31: 12KG+ | D31: 4.6 | F31: 25-32天 | G31: 专车配送
A33: 美西 七大仓直送价 盐田普船经济线 （周日开船，25天航程）
A34: FBA仓库代码 | B34: 目的邮编 | C34: 计费重起收点 | D34: 价格 | E34: 整柜直送 整柜价 （我司仓库装柜，全包到门） | F34: 签收时效 | G34: 配送方式 | H34: 下单渠道：美西普船海卡/整柜直送 普船经济线
A35: ONT8 | B35: 92551 | C35: 12KG+ | D35: 4 | E35: / | F35: 30-35天 | G35: 专车配送 | H35: 指定船型：宁波万海 宁波海领 宁波CUL
A36: LAX9 | B36: 92337 | C36: 12KG+ | D36: 4 | F36: 30-35天 | G36: 专车配送
A37: LGB8 | B37: 92376 | C37: 12KG+ | D37: 4 | F37: 30-35天 | G37: 专车配送
A38: SBD1 | B38: 92316-3819 | C38: 12KG+ | D38: 4 | F38: 30-35天 | G38: 专车配送
A39: IUSJ | B39: 92223 | C39: 12KG+ | D39: 4.2 | F39: 25-32天 | G39: 专车配送
A40: IUSQ | B40: 92374 | C40: 12KG+ | D40: 4.2 | F40: 25-32天 | G40: 专车配送
A41: IUSP | B41: 92344 | C41: 12KG+ | D41: 4.2 | F41: 25-32天 | G41: 专车配送
A42: POC1 | B42: 92336-1123 | C42: 12KG+ | D42: 4.2 | F42: 25-32天 | G42: 专车配送
...

Sheet 美中专线（休斯顿、芝加哥）
A1: 华东区-美中卡派专线
A2: 芝加哥 普船海卡/美中专线
A3: FBA仓库代码 | B3: 目的邮编 | C3: 12KG+ | D3: 签收时效 | E3: 配送方式 | F3: 下单渠道：芝加哥 普船海卡/美中专线
A4: MDW2 | B4: 60433 | C4: 6.3 | D4: 30-38天 | E4: 专车配送 | F4: 指定船型：EXX、OA船、以星统配
A5: ORD2 | B5: 60410 | C5: 6.3 | D5: 30-38天 | E5: 专车配送
A6: IGQ2 | B6: 60484 | C6: 6.3 | D6: 30-38天 | E6: 专车配送 | F6: 沃尔玛下单渠道：芝加哥 沃尔玛卡派
A7: MDW6 | B7: 60446 | C7: 6.3 | D7: 30-38天 | E7: 专车配送
A8: MDW9 | B8: 60502 | C8: 6.3 | D8: 30-38天 | E8: 专车配送
A9: RFD2 | B9: 60142 | C9: 6.3 | D9: 30-38天 | E9: 专车配送
A10: RFD4 | B10: 60142 | C10: 6.3 | D10: 30-38天 | E10: 专车配送
A11: JVL1 | B11: 53511 | C11: 6.3 | D11: 30-38天 | E11: 专车配送
A12: 沃尔玛—ORD1S | B12: / | C12: 6.3 | D12: 30-38天 | E12: 专车配送
A13: IND9 | B13: 46143 | C13: 7.5 | D13: 30-38天 | E13: 专车配送
A14: FWA4 | B14: 46809-9771 | C14: 7.5 | D14: 30-38天 | E14: 专车配送
A15: MQJ1 | B15: 46140-7099 | C15: 7.5 | D15: 30-38天 | E15: 专车配送
A16: MQJ2 | B16: 46184 | C16: 7.5 | D16: 30-38天 | E16: 专车配送
A17: STL4 | B17: 62025-2815 | C17: 7.5 | D17: 30-38天 | E17: 专车配送
A18: IND2 | B18: 46168 | C18: 7.5 | D18: 30-38天 | E18: 专车配送
A19: IND4 | B19: 46231 | C19: 7.5 | D19: 30-38天 | E19: 专车配送
A20: IND5 | B20: 46168 | C20: 7.5 | D20: 30-38天 | E20: 专车配送
A21: PPO4 | B21: 46410 | C21: 7.5 | D21: 30-38天 | E21: 专车配送
A22: 沃尔玛—IND2 | B22: / | C22: 7.5 | D22: 30-38天 | E22: 专车配送
A23: 沃尔玛—IND3 | B23: / | C23: 7.5 | D23: 30-38天 | E23: 专车配送
A24: DET1 | B24: 48150 | C24: 7.8 | D24: 35-45天 | E24: 专车配送
A25: DET2 | B25: 48317 | C25: 7.8 | D25: 35-45天 | E25: 专车配送
A26: LAN2 | B26: 48917 | C26: 7.8 | D26: 35-45天 | E26: 专车配送
A27: CMH2 | B27: 43125 | C27: 7.8 | D27: 35-45天 | E27: 专车配送
A28: CMH3 | B28: 45050 | C28: 7.8 | D28: 35-45天 | E28: 专车配送
A29: CMH7 | B29: 43054-7762 | C29: 7.8 | D29: 35-45天 | E29: 专车配送
A30: FOE1 | B30: 66109 | C30: 8.1 | D30: 35-45天 | E30: 专车配送
A31: MKC4 | B31: 66021-9588 | C31: 8.1 | D31: 35-45天 | E31: 专车配送
A32: MEM1 | B32: 38118-8102 | C32: 8.1 | D32: 35-45天 | E32: 专车配送
A33: MEM6 | B33: 38654-2510 | C33: 8.1 | D33: 35-45天 | E33: 专车配送
A34: MCI3 | B34: 64068 | C34: 8.1 | D34: 35-45天 | E34: 专车配送
A35: STL3 | B35: 65738-2779 | C35: 8.1 | D35: 35-45天 | E35: 专车配送
A36: 沃尔玛—MCI1N | B36: / | C36: 8.1 | D36: 35-45天 | E36: 专车配送
A37: 沃尔玛—KS1 | B37: / | C37: 8.1 | D37: 35-45天 | E37: 专车配送
A38: 请注意：非以上芝加哥渠道的代码请务必单询，并且价格会比较高昂！！
A39: 货重比：整票实重大于100公斤以上，享受重货比优惠：整票实重/整票方数=货重比 1:190 减0.2元 / 1:200 减0.3元 / 1:220 减0.5元 / 1:250 减0.8元 / 1:300 减1.2元 / 1:350 减1.5元 / 1:400 减1.8元 / 1:450 减2元 / 1:500 减2.2元 / 1:550 减2.5元 / ；超550以上单询；
A41: 休斯顿专线 卡派特价
...

Sheet 萨凡纳海卡专线
A1: 华东区-萨凡纳海卡专线
A2: FBA仓库代码 | B2: 目的邮编 | C2: 12KG+ | D2: 签收时效 | E2: 配送方式 | F2: 下单渠道：海卡/萨凡纳直航普船
A3: XLX6 | B3: 28134 | C3: 5.6 | D3: 30-38天 | E3: 专车配送 | F3: 指定船型：OA普船AWE快线、以星
A4: SAV3 | B4: 31216-6427 | C4: 5.6 | D4: 30-38天 | E4: 专车配送
A5: XAV3 | B5: 31407 | C5: 5.6 | D5: 30-38天 | E5: 专车配送 | F5: 沃尔玛下单渠道：萨凡纳 沃尔玛卡派
A6: CLT2 | B6: 28214 | C6: 5.6 | D6: 30-38天 | E6: 专车配送
A7: CLT3 | B7: 28027-7995 | C7: 5.6 | D7: 30-38天 | E7: 专车配送
A8: GSP1 | B8: 29303 | C8: 5.6 | D8: 30-38天 | E8: 专车配送
A9: IUSR | B9: 29330 | C9: 5.6 | D9: 30-38天 | E9: 专车配送
A10: ATL8 | B10: 30122 | C10: 5.6 | D10: 30-38天 | E10: 专车配送
A11: RDU4 | B11: 28303 | C11: 5.6 | D11: 30-38天 | E11: 专车配送
A12: RYY2 | B12: 30184 | C12: 5.6 | D12: 30-38天 | E12: 专车配送
A13: MGE1 | B13: 30517 | C13: 5.6 | D13: 30-38天 | E13: 专车配送
A14: MGE3 | B14: 30549 | C14: 5.6 | D14: 30-38天 | E14: 专车配送
A15: JAX3 | B15: 32210-8686 | C15: 5.6 | D15: 30-38天 | E15: 专车配送
A16: GSO1 | B16: 27284 | C16: 5.9 | D16: 30-38天 | E16: 专车配送
A17: CLT6 | B17: 28134-9457 | C17: 5.9 | D17: 30-38天 | E17: 专车配送
A18: CLT4 | B18: 28214 | C18: 5.9 | D18: 30-38天 | E18: 专车配送
A19: MCO2 | B19: 32725 | C19: 5.9 | D19: 30-38天 | E19: 专车配送
A20: TPA2 | B20: 33811-1808 | C20: 5.9 | D20: 30-38天 | E20: 专车配送
A21: TPA3 | B21: 33823-9429 | C21: 5.9 | D21: 35-45天 | E21: 专车配送
A22: TPA6 | B22: 33811 | C22: 5.9 | D22: 35-45天 | E22: 专车配送
A23: RDU2 | B23: 27577 | C23: 5.9 | D23: 35-45天 | E23: 专车配送
A24: ATL2 | B24: 30087-3506 | C24: 5.9 | D24: 35-45天 | E24: 专车配送
A25: Walmart-ATL3 | B25: / | C25: 5.9 | D25: 35-45天 | E25: 专车配送
A26: Walmart-ATL2n | B26: / | C26: 5.9 | D26: 35-45天 | E26: 专车配送
A27: Walmart-ATL1 | B27: / | C27: 5.9 | D27: 35-45天 | E27: 专车配送
A28: Walmart-MCO1 | B28: / | C28: 5.9 | D28: 35-45天 | E28: 专车配送
A29: CHA2 | B29: 37310 | C29: 6.2 | D29: 35-45天 | E29: 专车配送
A30: BNA2 | B30: 37090-8123 | C30: 6.2 | D30: 35-45天 | E30: 专车配送
A31: BNA6 | B31: 37040-5502 | C31: 6.2 | D31: 35-45天 | E31: 专车配送
A32: PBI3 | B32: 34986 | C32: 6.2 | D32: 35-45天 | E32: 专车配送
A33: MQY1 | B33: 37122 | C33: 6.2 | D33: 35-45天 | E33: 专车配送
A34: ORF2 | B34: 23297 | C34: 6.2 | D34: 35-45天 | E34: 专车配送
A35: RMN3 | B35: 22406 | C35: 6.2 | D35: 35-45天 | E35: 专车配送
A36: TMB8 | B36: 33032 | C36: 6.2 | D36: 35-45天 | E36: 专车配送
A37: MEM8 | B37: 38611 | C37: 6.2 | D37: 35-45天 | E37: 专车配送
A38: HSV1 | B38: 35756-4403 | C38: 6.2 | D38: 35-45天 | E38: 专车配送
A39: HSV2 | B39: 35676 | C39: 6.2 | D39: 35-45天 | E39: 专车配送
A40: PBI2 | B40: 33478 | C40: 6.2 | D40: 35-45天 | E40: 专车配送
...

Sheet 美东纽约海卡专线
A1: 海卡/纽约直航普船 （以星/OA船） | F1: 海卡/纽约以星海铁快线
A2: FBA仓库代码 （红色字体为美东热门仓） | B2: 目的邮编 | C2: 海卡包税 | E2: 签收时效 | F2: 海卡包税 | H2: 签收时效
C3: 下单渠道： 海卡/纽约直航普船 | D3: 下单渠道： 海卡/纽约直航普船 | F3: 下单渠道：海卡/纽约海铁快线【带赔付】 | I3: 注意：以星LA转铁路 或者 EXX LA 转铁路
C4: 1方起收；400折算 | D4: 12KG+ | F4: 12KG-99KG 价格 | G4: 100KG+ 价格
A5: ABE8 | B5: 08518-2200 | C5: =D5*200 -> 960 | D5: 4.8 | E5: 35-45天 | F5: 15.22 | G5: 14.22 | H5: 30天签收提供POD
A6: TEB9 | B6: 08873 | C6: =D6*200 -> 960 | D6: 4.8 | E6: 35-45天 | F6: 15.22 | G6: 14.22 | H6: 30天签收提供POD
A7: XEW5 | B7: 08077 | C7: =D7*200 -> 960 | D7: 4.8 | E7: 35-45天 | F7: 15.22 | G7: 14.22 | H7: 30天签收提供POD
A8: ACY2 | B8: 08016-1934 | C8: =D8*200 -> 960 | D8: 4.8 | E8: 35-45天 | F8: 15.22 | G8: 14.22 | H8: 30天签收提供POD
A9: ABE3 | B9: 18031 | C9: =D9*200 -> 960 | D9: 4.8 | E9: 35-45天 | F9: 15.22 | G9: 14.22 | H9: 30天签收提供POD
A10: ABE4 | B10: 18045 | C10: =D10*200 -> 960 | D10: 4.8 | E10: 35-45天 | F10: 15.22 | G10: 14.22 | H10: 30天签收提供POD
A11: TEB3 | B11: 08085-4503 | C11: =D11*200 -> 960 | D11: 4.8 | E11: 35-45天 | F11: 15.22 | G11: 14.22 | H11: 30天签收提供POD
A12: TEB4 | B12: 08069 | C12: =D12*200 -> 960 | D12: 4.8 | E12: 35-45天 | F12: 15.22 | G12: 14.22 | H12: 30天签收提供POD
A13: TEB6 | B13: 08873 | C13: =D13*200 -> 960 | D13: 4.8 | E13: 35-45天 | F13: 15.22 | G13: 14.22 | H13: 30天签收提供POD
A14: TTN2 | B14: 08512-3253 | C14: =D14*200 -> 960 | D14: 4.8 | E14: 35-45天 | F14: 15.72 | G14: 14.72 | H14: 30天签收提供POD
A15: AVP1 | B15: 18202-9361 | C15: =D15*200 -> 1100 | D15: 5.5 | E15: 35-45天 | F15: 16.24 | G15: 15.24 | H15: 30天签收提供POD
A16: AVP3 | B16: 18424-9492 | C16: =D16*200 -> 1100 | D16: 5.5 | E16: 35-45天 | F16: 16.24 | G16: 15.24 | H16: 30天签收提供POD
A17: AVP9 | B17: 18434-1153 | C17: =D17*200 -> 1100 | D17: 5.5 | E17: 35-45天 | F17: 16.24 | G17: 15.24 | H17: 30天签收提供POD
A18: ILG1 | B18: 19720-4610 | C18: =D18*200 -> 1100 | D18: 5.5 | E18: 35-45天 | F18: 15.93 | G18: 14.93 | H18: 30天签收提供POD
A19: SWF1 | B19: 12575 | C19: =D19*200 -> 1100 | D19: 5.5 | E19: 35-45天 | F19: 15.22 | G19: 14.22 | H19: 30天签收提供POD
A20: SWF2 | B20: 12533 | C20: =D20*200 -> 1100 | D20: 5.5 | E20: 35-45天 | F20: 15.22 | G20: 14.22 | H20: 30天签收提供POD
A21: PHL4 | B21: 17015 | C21: =D21*200 -> 1100 | D21: 5.5 | E21: 35-45天 | F21: 15.74 | G21: 14.74 | H21: 30天签收提供POD
A22: PHL5 | B22: 17339-8725 | C22: =D22*200 -> 1100 | D22: 5.5 | E22: 35-45天 | F22: 15.74 | G22: 14.74 | H22: 30天签收提供POD
A23: PHL6 | B23: 17015 | C23: =D23*200 -> 1100 | D23: 5.5 | E23: 35-45天 | F23: 15.74 | G23: 14.74 | H23: 30天签收提供POD
A24: PHL7 | B24: 19709 | C24: =D24*200 -> 1100 | D24: 5.5 | E24: 35-45天 | F24: 15.74 | G24: 14.74 | H24: 30天签收提供POD
A25: MDT1 | B25: 17015 | C25: =D25*200 -> 1100 | D25: 5.5 | E25: 35-45天 | F25: 16.24 | G25: 15.24 | H25: 30天签收提供POD
A26: MDT2 | B26: 21901 | C26: =D26*200 -> 1100 | D26: 5.5 | E26: 35-45天 | F26: 16.24 | G26: 15.24 | H26: 30天签收提供POD
A27: MDT4 | B27: 17408 | C27: =D27*200 -> 1100 | D27: 5.5 | E27: 35-45天 | F27: 16.24 | G27: 15.24 | H27: 30天签收提供POD
A28: WBW2 | B28: 18447 | C28: =D28*200 -> 1100 | D28: 5.5 | E28: 35-45天 | F28: 16.24 | G28: 15.24 | H28: 30天签收提供POD
A29: HEA2 | B29: 18031-1536 | C29: =D29*200 -> 1100 | D29: 5.5 | E29: 35-45天 | F29: 16.24 | G29: 15.24 | H29: 30天签收提供POD
A30: XLX1 | B30: 21740-8126 | C30: =D30*200 -> 1180 | D30: 5.9 | E30: 35-45天 | F30: 16.26 | G30: 15.26 | H30: 32天签收提供POD
A31: DCA6 | B31: 21219 | C31: =D31*200 -> 1180 | D31: 5.9 | E31: 35-45天 | F31: 16.56 | G31: 15.56 | H31: 32天签收提供POD
A32: ALB1 | B32: 12033 | C32: =D32*200 -> 1180 | D32: 5.9 | E32: 35-45天 | F32: 18.1 | G32: 17.1 | H32: 32天签收提供POD
A33: HGR2 | B33: 21901 | C33: =D33*200 -> 1180 | D33: 5.9 | E33: 35-45天 | F33: 18.9 | G33: 17.9 | H33: 32天签收提供POD
A34: HGR6 | B34: 21740-7301 | C34: =D34*200 -> 1180 | D34: 5.9 | E34: 35-45天 | F34: 18.9 | G34: 17.9 | H34: 32天签收提供POD
A35: BWI4 | B35: 22624-1568 | C35: =D35*200 -> 1180 | D35: 5.9 | E35: 35-45天 | F35: 18.9 | G35: 17.9 | H35: 32天签收提供POD
A36: HIA1 | B36: 17057 | C36: =D36*200 -> 1180 | D36: 5.9 | E36: 35-45天 | F36: 18.9 | G36: 17.9 | H36: 32天签收提供POD
A37: BDL3 | B37: 06473 | C37: =D37*200 -> 1260 | D37: 6.3 | E37: 40-45天 | F37: 17.9 | G37: 16.9 | H37: 32天签收提供POD
A38: BDL6 | B38: 06416 | C38: =D38*200 -> 1260 | D38: 6.3 | E38: 40-45天 | F38: 17.9 | G38: 16.9 | H38: 32天签收提供POD
A39: BOS7 | B39: 02720 | C39: =D39*200 -> 1260 | D39: 6.3 | E39: 40-45天 | F39: 18.4 | G39: 17.4 | H39: 32天签收提供POD
A40: RIC1 | B40: 23803 | C40: =D40*200 -> 1260 | D40: 6.3 | E40: 40-45天 | F40: 17.39 | G40: 16.39 | H40: 32天签收提供POD
...

Sheet 全美私人卡派
A1: 华东区-全美私人卡派
A2: 美森正班私人卡派（CLX）
A3: 国家/重量 | B3: 350KG+ | C3: 700KG+ | D3: 1000KG+ | E3: 1500KG+ | F3: 2000KG+ | G3: 3000KG+ | H3: 4000KG+ | I3: 5000KG+ | J3: 6000KG+ | K3: 6吨以上单询
A4: 90-92邮编 （50miles内商业地址） | B4: 15 | C4: 12.5 | D4: 11.5 | E4: 11 | F4: 10.5 | G4: 10.5 | H4: 10.5 | I4: 10.3 | J4: 10.3 | K4: 单询
A5: 下单渠道：美森正班/私人卡派—50英里内（CLX） 注意：务必找我司业务员确认是否为50英里范围内
A6: 美西(USW) 邮编8.9 商业地址 （不含97、98、99邮编区域） | B6: 18.33 | C6: 16.33 | D6: 13.83 | E6: 13.83 | F6: 13.33 | G6: 13.33 | H6: 12.83 | I6: 12.83 | J6: 12.83 | K6: 单询
A7: 美中(USM) 邮编4.5.6.7 商业地址 （含97、98、99邮编区域） | B7: 20.33 | C7: 17.33 | D7: 15.83 | E7: 15.33 | F7: 14.83 | G7: 14.83 | H7: 14.33 | I7: 14.33 | J7: 14.33 | K7: 单询
A8: 美东(USE) 邮编0.1.2.3 商业地址 | B8: 22.83 | C8: 18.83 | D8: 17.33 | E8: 16.83 | F8: 16.83 | G8: 16.33 | H8: 15.83 | I8: 15.83 | J8: 15.83 | K8: 单询
A9: 下单渠道：美森正班/私人卡派（CLX）
A11: 美森加班私人卡派（MAX）
A12: 国家/重量 | B12: 350KG+ | C12: 700KG+ | D12: 1000KG+ | E12: 1500KG+ | F12: 2000KG+ | G12: 3000KG+ | H12: 4000KG+ | I12: 5000KG+ | J12: 6000KG+ | K12: 6吨以上单询
A13: 90-92邮编 （50miles内商业地址） | B13: 14.2 | C13: 11.7 | D13: 10.7 | E13: 10.2 | F13: 9.7 | G13: 9.7 | H13: 9.7 | I13: 9.5 | J13: 9.5 | K13: 单询
A14: 下单渠道：美森加班/私人卡派—50英里内（MAX） 注意：务必找我司业务员确认是否为50英里范围内
A15: 美西(USW) 邮编8.9 商业地址 （不含97、98、99邮编区域） | B15: 17.53 | C15: 15.53 | D15: 13.03 | E15: 13.03 | F15: 12.53 | G15: 12.53 | H15: 12.03 | I15: 12.03 | J15: 12.03 | K15: 单询
A16: 美中(USM) 邮编4.5.6.7 商业地址 （含97、98、99邮编区域） | B16: 19.53 | C16: 16.53 | D16: 15.03 | E16: 14.53 | F16: 14.03 | G16: 14.03 | H16: 13.53 | I16: 13.53 | J16: 13.53 | K16: 单询
A17: 美东(USE) 邮编0.1.2.3 商业地址 | B17: 22.03 | C17: 18.03 | D17: 16.53 | E17: 16.03 | F17: 16.03 | G17: 15.53 | H17: 15.03 | I17: 15.03 | J17: 15.03 | K17: 单询
A18: 下单渠道：美森加班/私人卡派（MAX）
A20: EXX/私人卡派
A21: 国家/重量 | B21: 350KG+ | C21: 700KG+ | D21: 1000KG+ | E21: 1500KG+ | F21: 2000KG+ | G21: 3000KG+ | H21: 4000KG+ | I21: 5000KG+ | J21: 6000KG+ | K21: 6吨以上单询
A22: 90-92邮编 （50miles内商业地址） | B22: 10.9 | C22: 8.4 | D22: 7.4 | E22: 6.9 | F22: 6.4 | G22: 6.4 | H22: 6.4 | I22: 6.2 | J22: 6.2 | K22: 单询
A23: 下单渠道：EXX/私人卡派—50英里内 注意：务必找我司业务员确认是否为50英里范围内
A24: 美西(USW) 邮编8.9 商业地址 （不含97、98、99邮编区域） | B24: 14.43 | C24: 12.43 | D24: 9.93 | E24: 9.93 | F24: 9.43 | G24: 9.43 | H24: 8.93 | I24: 8.93 | J24: 8.93 | K24: 单询
A25: 美中(USM) 邮编4.5.6.7 商业地址 （含97、98、99邮编区域） | B25: 16.43 | C25: 13.43 | D25: 11.93 | E25: 11.43 | F25: 10.93 | G25: 10.93 | H25: 10.43 | I25: 10.43 | J25: 10.43 | K25: 单询
A26: 美东(USE) 邮编0.1.2.3 商业地址 | B26: 18.43 | C26: 14.43 | D26: 12.93 | E26: 12.43 | F26: 12.43 | G26: 11.93 | H26: 11.43 | I26: 11.43 | J26: 11.43 | K26: 单询
A27: 下单渠道：EXX/私人卡派
A29: 华东合德/以星统配 私人卡派 最晚周一进仓
A30: 国家/重量 | B30: 350KG+ | C30: 700KG+ | D30: 1000KG+ | E30: 1500KG+ | F30: 2000KG+ | G30: 3000KG+ | H30: 4000KG+ | I30: 5000KG+ | J30: 6000KG+ | K30: 6吨以上单询
A31: 90-92邮编 （50miles内商业地址） | B31: 10.2 | C31: 7.7 | D31: 6.7 | E31: 6.2 | F31: 5.7 | G31: 5.7 | H31: 5.7 | I31: 5.5 | J31: 5.5 | K31: 单询
A32: 下单渠道：华东合德/以星统配 私人卡派—50英里内 注意：务必找我司业务员确认是否为50英里范围内
A33: 美西(USW) 邮编8.9 商业地址 （不含97、98、99邮编区域） | B33: 13.73 | C33: 11.73 | D33: 9.23 | E33: 9.23 | F33: 8.73 | G33: 8.73 | H33: 8.23 | I33: 8.23 | J33: 8.23 | K33: 单询
A34: 美中(USM) 邮编4.5.6.7 商业地址 （含97、98、99邮编区域） | B34: 15.73 | C34: 12.73 | D34: 11.23 | E34: 10.73 | F34: 10.23 | G34: 10.23 | H34: 9.73 | I34: 9.73 | J34: 9.73 | K34: 单询
A35: 美东(USE) 邮编0.1.2.3 商业地址 | B35: 17.73 | C35: 13.73 | D35: 12.23 | E35: 11.73 | F35: 11.73 | G35: 11.23 | H35: 10.73 | I35: 10.73 | J35: 10.73 | K35: 单询
A36: 下单渠道：华东合德/以星统配 私人卡派
A38: 美西洛杉矶普船私人卡派 | L38: 这是洛杉矶海外仓普船渠道，OA、合德统配
A39: 国家/重量 | B39: 350KG+ | C39: 700KG+ | D39: 1000KG+ | E39: 1500KG+ | F39: 2000KG+ | G39: 3000KG+ | H39: 4000KG+ | I39: 5000KG+ | J39: 6000KG+ | K39: 6吨以上单询
A40: 90-92邮编 （50miles内商业地址） | B40: 9.9 | C40: 7.4 | D40: 6.4 | E40: 5.9 | F40: 5.4 | G40: 5.4 | H40: 5.4 | I40: 5.2 | J40: 5.2 | K40: 单询
A41: 下单渠道：美西普船/私人卡派—50英里内 注意：务必找我司业务员确认是否为50英里范围内
A42: 美西(USW) 邮编8.9 商业地址 （不含97、98、99邮编区域） | B42: 13.43 | C42: 11.43 | D42: 8.93 | E42: 8.93 | F42: 8.43 | G42: 8.43 | H42: 7.93 | I42: 7.93 | J42: 7.93 | K42: 单询
A43: 美中(USM) 邮编4.5.6.7 商业地址 （含97、98、99邮编区域） | B43: 15.43 | C43: 12.43 | D43: 10.93 | E43: 10.43 | F43: 9.93 | G43: 9.93 | H43: 9.43 | I43: 9.43 | J43: 9.43 | K43: 单询
A44: 美东(USE) 邮编0.1.2.3 商业地址 | B44: 17.43 | C44: 13.43 | D44: 11.93 | E44: 11.43 | F44: 11.43 | G44: 10.93 | H44: 10.43 | I44: 10.43 | J44: 10.43 | K44: 单询
...

Sheet 美国转加拿大海派
A1: 华东区-同行价格表
A2: 加拿大 美森海派 极速达 18天赔付（指定正班船CLX，美国稳定提取）
A3: FBA仓库/重量 | B3: 21KG+ | C3: 51KG+ | D3: 71KG+ | E3: 101KG+ | F3: 备注 | G3: 下单渠道：加拿大 美森海派 极速达
A4: 亚马逊 （多伦多、渥太华）-只接FBA （YYZ/YOO/YHM/YOW/YXU1) | B4: 21.5 | C4: 18.5 | D4: 17.5 | E4: 16.5 | F4: 开船后第二天开始算18天提取 第19天开始赔偿1元/kg*天 最高赔付3元每公斤 （如遇海关查验，赔偿1元每公斤） （如遇节假日、码头停摆、港口罢工等非人为因素，不参与赔付） | G4: 一截三开
A5: 亚马逊 （温哥华、卡尔加里）-只接FBA （YVR/YXX/YYC/YEG ） | B5: 22.5 | C5: 19.5 | D5: 18.5 | E5: 17.5
A6: 其他亚马逊仓库 | B6: 23.5 | C6: 20.5 | D6: 19.5 | E6: 18.5
A7: 商业地址/私人地址 | B7: 24.5 | C7: 21.5 | D7: 20.5 | E7: 19.5
A8: 重货比优惠：整票实重大于100公斤以上，1:220 减0.2元 / 1:250 减0.5元 / 1:300 减1元 / 1:400以上 减2元；超500以上单询；整票实重/整票方数=货重比
A10: 加拿大 美森海派 限时达 20天赔付（指定加班船MAX，美国稳定提取）
A11: FBA仓库/重量 | B11: 21KG+ | C11: 51KG+ | D11: 71KG+ | E11: 101KG+ | F11: 备注 | G11: 下单渠道：加拿大 美森海派 限时达
A12: 亚马逊 （多伦多、渥太华）-只接FBA （YYZ/YOO/YHM/YOW/YXU1) | B12: 20.5 | C12: 17.5 | D12: 16.5 | E12: 15.5 | F12: 开船后第二天开始算20天提取 第21天开始赔偿1元/kg*天 最高赔付3元每公斤 （如遇海关查验，赔偿1元每公斤） （如遇节假日、码头停摆、港口罢工等非人为因素，不参与赔付） | G12: 二截四开
A13: 亚马逊 （温哥华、卡尔加里）-只接FBA （YVR/YXX/YYC/YEG ） | B13: 21.5 | C13: 18.5 | D13: 17.5 | E13: 16.5
A14: 其他亚马逊仓库 | B14: 22.5 | C14: 19.5 | D14: 18.5 | E14: 17.5
A15: 商业地址/私人地址 | B15: 23.5 | C15: 20.5 | D15: 19.5 | E15: 18.5
A16: 重货比优惠：整票实重大于100公斤以上，1:220 减0.2元 / 1:250 减0.5元 / 1:300 减1元 / 1:400以上 减2元；超500以上单询；整票实重/整票方数=货重比
A18: 加拿大 EXX 限时达 20天赔付（美国稳定提取）
A19: FBA仓库/重量 | B19: 21KG+ | C19: 51KG+ | D19: 71KG+ | E19: 101KG+ | F19: 备注 | G19: 下单渠道：加拿大 EXX海派 限时达
A20: 亚马逊 （多伦多、渥太华）-只接FBA （YYZ/YOO/YHM/YOW/YXU1) | B20: 19.5 | C20: 16.5 | D20: 15.5 | E20: 14.5 | F20: 开船后第二天开始算20天提取 第21天开始赔偿1元/kg*天 最高赔付3元每公斤 （如遇海关查验，赔偿1元每公斤） （如遇节假日、码头停摆、港口罢工等非人为因素，不参与赔付） | G20: 二截四开
A21: 亚马逊 （温哥华、卡尔加里）-只接FBA （YVR/YXX/YYC/YEG ） | B21: 20.5 | C21: 17.5 | D21: 16.5 | E21: 15.5
A22: 其他亚马逊仓库 | B22: 21.5 | C22: 18.5 | D22: 17.5 | E22: 16.5
A23: 商业地址/私人地址 | B23: 22.5 | C23: 19.5 | D23: 18.5 | E23: 17.5
A24: 重货比优惠：整票实重大于100公斤以上，1:220 减0.2元 / 1:250 减0.5元 / 1:300 减1元 / 1:400以上 减2元；超500以上单询；整票实重/整票方数=货重比
A26: 加拿大 以星限时达 20天赔付（带车架，美国稳定提取）
A27: FBA仓库/重量 | B27: 21KG+ | C27: 51KG+ | D27: 71KG+ | E27: 101KG+ | F27: 备注 | G27: 下单渠道：加拿大 以星限时达海派
A28: 亚马逊 （多伦多、渥太华）-只接FBA （YYZ/YOO/YHM/YOW/YXU1) | B28: 19 | C28: 16 | D28: 15 | E28: 14 | F28: 开船后第二天开始算20天提取 第21天开始赔偿1元/kg*天 最高赔付3元每公斤 （如遇海关查验，赔偿1元每公斤） （如遇节假日、码头停摆、港口罢工等非人为因素，不参与赔付） | G28: 二截四开
A29: 亚马逊 （温哥华、卡尔加里）-只接FBA （YVR/YXX/YYC/YEG ） | B29: 20 | C29: 17 | D29: 16 | E29: 15
A30: 其他亚马逊仓库 | B30: 21 | C30: 18 | D30: 17 | E30: 16
A31: 商业地址/私人地址 | B31: 22 | C31: 19 | D31: 18 | E31: 17
A32: 重货比优惠：整票实重大于100公斤以上，1:220 减0.2元 / 1:250 减0.5元 / 1:300 减1元 / 1:400以上 减2元；超500以上单询；整票实重/整票方数=货重比
A34: 加拿大 统配海派 定时达 25天赔付（COSCO/EMC OA统配，美国稳定提取）
A35: 国家/重量 | B35: 21KG+ | C35: 51KG+ | D35: 71KG+ | E35: 101KG+ | F35: 备注 | G35: 下单渠道：加拿大 统配海派 定时达
A36: 亚马逊 （多伦多、渥太华）-只接FBA （YYZ/YOO/YHM/YOW/YXU1) | B36: 18.5 | C36: 15.5 | D36: 14.5 | E36: 13.5 | F36: 开船后第二天开始算25天提取 第26天开始赔偿0.5元/kg*天 最高赔付2元每公斤 （如遇海关查验，赔偿1元每公斤） （如遇节假日、码头停摆、港口罢工等非人为因素，不参与赔付） | G36: 以COSCO/EMC等OA船开船时间为准
A37: 亚马逊 （温哥华、卡尔加里）-只接FBA （YVR/YXX/YYC/YEG ） | B37: 19.5 | C37: 16.5 | D37: 15.5 | E37: 14.5 | G37: 每周固定周四开船的森罗SML我们也会选择，时效堪比OA普船！
A38: 其他亚马逊仓库 | B38: 21.5 | C38: 18.5 | D38: 17.5 | E38: 16.5
A39: 商业地址/私人地址 | B39: 22.5 | C39: 19.5 | D39: 18.5 | E39: 17.5
A40: 重货比优惠：整票实重大于100公斤以上，1:220 减0.2元 / 1:250 减0.5元 / 1:300 减1元 / 1:400以上 减2元；超500以上单询；整票实重/整票方数=货重比
A41: 单件最低计费12KG，单件不超22公斤； // 后程UPS派送； // FBA偏远+2/KG，商业地址偏远+3元/KG，最低收190元一票； // 报关件，收取350元/票
A42: 此渠道是美国洛杉矶，UPS提取后，经过加拿大海关进行清关，再进入加拿大区域转运的；加拿大的关税是比较高的！！ 主要的附加费：纺织品，皮革，箱包，鞋服包加2元/KG
A43: 注意以下省份区域无法进行UPS派送：（Nunavut 邮编X0A - X0C） （Northwest Territories 邮编X0E - X9Z） （Yukon 邮编Y0A - Y9Z）
A44: 本渠道丢件赔偿100美金/件！！！！！！！！！

Sheet 奥克兰卡派专线
A1: 华东区-奥克兰卡派专线
A2: 奥克兰 直航 散货特价
A3: FBA仓库代码 | B3: 目的邮编 | C3: 12KG+ | D3: 整柜直送 整柜价 （我司仓库装柜，全包到门） | E3: 签收时效 | F3: 配送方式 | G3: 下单渠道：奥克兰普船海卡/散货特价
A4: SCK4 | B4: 95215 | C4: 4.8 | D4: / | E4: 25-35天 | F4: 专车配送 | G4: 指定船型：OA船、EXX船
A5: SCK1 | B5: 95215-9465 | C5: 4.8 | D5: / | E5: 25-35天 | F5: 专车配送
A6: SCK3 | B6: 95336 | C6: 4.8 | D6: / | E6: 25-35天 | F6: 专车配送
A7: SMF3 | B7: 95206 | C7: 4.8 | D7: / | E7: 25-35天 | F7: 专车配送
A8: OAK3 | B8: 95363 | C8: 4.8 | D8: / | E8: 25-35天 | F8: 专车配送
A9: SJC7 | B9: 95377 | C9: 4.8 | D9: / | E9: 25-35天 | F9: 专车配送
A10: SCK8 | B10: 94561 | C10: 4.8 | D10: / | E10: 25-35天 | F10: 专车配送
A11: SCK8 | B11: 94561 | C11: 4.8 | D11: / | E11: 25-35天 | F11: 专车配送
A12: TCY2 | B12: 95215 | C12: 4.8 | D12: / | E12: 25-35天 | F12: 专车配送
A13: SMF6 | B13: 95837 | C13: 4.8 | D13: / | E13: 25-35天 | F13: 专车配送
A14: SMF7 | B14: 95688 | C14: 4.8 | D14: / | E14: 25-35天 | F14: 专车配送
A15: MCC1 | B15: 95742 | C15: 4.8 | D15: / | E15: 25-35天 | F15: 专车配送
A16: MCE1 | B16: 95380-9684 | C16: 4.8 | D16: / | E16: 25-35天 | F16: 专车配送
A17: HLI2 | B17: 95023 | C17: 4.8 | D17: / | E17: 25-35天 | F17: 专车配送
A18: FAT2 | B18: 93725 | C18: 5.1 | D18: / | E18: 25-35天 | F18: 专车配送
A19: RNO4 | B19: 89506 | C19: 5.4 | D19: / | E19: 25-35天 | F19: 专车配送
A20: 货重比：整票实重大于100公斤以上，享受重货比优惠：整票实重/整票方数=货重比 1:190 减0.2元 / 1:200 减0.3元 / 1:220 减0.5元 / 1:250 减0.8元 / 1:300 减1.2元 / 1:350 减1.5元 / 1:400 减1.8元 / 1:450 减2元 / 1:500 减2.2元 / 1:550 减2.5元 / ；超550以上单询；

Sheet UPS海运小包特价
A1: UPS海运小包特价
A2: 海派 美森正班极速达 16天赔付 海运小包 （CLX）
B3: 3KG+ | C3: 5KG+ | D3: 7KG+ | E3: 9KG+ | F3: 11KG+ | G3: 备注
A4: 邮编 8 9 | B4: 30.5 | C4: 24.5 | D4: 23.5 | E4: 21.5 | F4: 20.5 | G4: 开船后第二天开始算16天提取 第17天开始赔偿1元/kg*天 最高赔付2元每公斤 （如遇海关查验，赔偿1元每公斤） （如遇节假日、码头停摆、港口罢工等非人为因素，不参与赔付）
A5: 邮编5 6 7 | B5: 31.5 | C5: 25.5 | D5: 24.5 | E5: 23.5 | F5: 22.5
A6: 邮编 0 1 2 3 4 | B6: 32.5 | C6: 27.5 | D6: 26.5 | E6: 25.5 | F6: 25.5
A7: 下单渠道：海派 美森正班极速达 16天赔付 海运小包 （CLX）
A9: 海派 美森加班限时达 18天赔付 海运小包 （MAX）
B10: 3KG+ | C10: 5KG+ | D10: 7KG+ | E10: 9KG+ | F10: 11KG+ | G10: 备注
A11: 邮编 8 9 | B11: 29.5 | C11: 23.5 | D11: 22.5 | E11: 20.5 | F11: 19.5 | G11: 开船后第二天开始算18天提取 第19天开始赔偿1元/kg*天 最高赔付2元每公斤 （如遇海关查验，赔偿1元每公斤） （如遇节假日、码头停摆、港口罢工等非人为因素，不参与赔付）
A12: 邮编5 6 7 | B12: 30.5 | C12: 24.5 | D12: 23.5 | E12: 22.5 | F12: 21.5
A13: 邮编 0 1 2 3 4 | B13: 31.5 | C13: 26.5 | D13: 25.5 | E13: 24.5 | F13: 24.5
A14: 下单渠道：海派 美森加班限时达 18天赔付 海运小包
A16: 海派 EXX限时达 18天赔付 海运小包
B17: 3KG+ | C17: 5KG+ | D17: 7KG+ | E17: 9KG+ | F17: 11KG+ | G17: 备注
A18: 邮编 8 9 | B18: 28.5 | C18: 22.5 | D18: 21.5 | E18: 19.5 | F18: 18.5 | G18: 开船后第二天开始算18天提取 第19天开始赔偿0.5元/kg*天 最高赔付1元每公斤 （如遇海关查验，赔偿0.5元每公斤） （如遇节假日、码头停摆、港口罢工等非人为因素，不参与赔付）
A19: 邮编5 6 7 | B19: 29.5 | C19: 23.5 | D19: 22.5 | E19: 21.5 | F19: 20.5
A20: 邮编 0 1 2 3 4 | B20: 30.5 | C20: 25.5 | D20: 24.5 | E20: 23.5 | F20: 23.5
A21: 下单渠道：海派 EXX限时达 18天赔付 海运小包
A23: 海派 以星限时达 18天赔付 海运小包 （带车架）
B24: 3KG+ | C24: 5KG+ | D24: 7KG+ | E24: 9KG+ | F24: 11KG+ | G24: 备注
A25: 邮编 8 9 | B25: 28 | C25: 22 | D25: 21 | E25: 19 | F25: 18 | G25: 开船后第二天开始算18天提取 第19天开始赔偿0.5元/kg*天 最高赔付1元每公斤 （如遇海关查验，赔偿0.5元每公斤） （如遇节假日、码头停摆、港口罢工等非人为因素，不参与赔付）
A26: 邮编5 6 7 | B26: 29 | C26: 23 | D26: 22 | E26: 21 | F26: 20
A27: 邮编 0 1 2 3 4 | B27: 30 | C27: 25 | D27: 24 | E27: 23 | F27: 23
A28: 下单渠道：海派 以星限时达 18天赔付 海运小包
A30: 海派 OA快普 海运小包
B31: 3KG+ | C31: 5KG+ | D31: 7KG+ | E31: 9KG+ | F31: 11KG+ | G31: 备注
A32: 邮编 8 9 | B32: 27.5 | C32: 21.5 | D32: 20.5 | E32: 18.5 | F32: 17.5 | G32: 20-25天
A33: 邮编5 6 7 | B33: 28.5 | C33: 22.5 | D33: 21.5 | E33: 20.5 | F33: 19.5
A34: 邮编 0 1 2 3 4 | B34: 29.5 | C34: 24.5 | D34: 23.5 | E34: 22.5 | F34: 22.5
A35: 下单渠道：海派 OA快普 海运小包
A36: 本渠道没有货重比优惠，丢件按照40元/公斤赔付
A37: 非FBA地址：整票+5元/KG； FBA地址和商业地址：无附加费 偏远收费：30元/件 商检费300/票 报关件350/票

Sheet 美西海卡不包税
A1: 华东区-美西海卡-不包税 各渠道汇总表 注意：不接0税率产品！！！！
A2: FBA仓库代码 目的邮编 | E2: 下单渠道： 海卡/美森正班船-不包税 | G2: 下单渠道： 海卡/美森加班船-不包税 | I2: 下单渠道： 海卡/EXX-不包税 | K2: 下单渠道： 海卡/以星带车架-不包税 | M2: 下单渠道： 海卡/合德快提-不包税 | O2: 下单渠道： 海卡/COSCO、EMC定提 普船统配-不包税 | Q2: 下单渠道： 海卡/普船经济线-不包税
