Workbook
Name FBA仓库代码: [1]亚马逊地址库!$C$2:$C$428
Name 城市: [1]亚马逊地址库!$K$2:$K$428
Name 地址编码: [1]亚马逊地址库!$B$2:$B$428
Name 地址二: [1]亚马逊地址库!$I$2:$I$428
Name 地址简称: [1]亚马逊地址库!$A$2:$A$428
Name 地址三: [1]亚马逊地址库!$J$2:$J$428
Name 地址一: [1]亚马逊地址库!$H$2:$H$428
Name 公司名: [1]亚马逊地址库!$E$2:$E$428
Name 国家: [1]亚马逊地址库!$M$2:$M$428
Name 联系电话: [1]亚马逊地址库!$F$2:$F$428
Name 联系人: [1]亚马逊地址库!$D$2:$D$428
Name 联系手机: [1]亚马逊地址库!$G$2:$G$428
Name 渠道: OFFSET([1]亚马逊地址库!$O$1,1,,COUNTA([1]亚马逊地址库!$O$1:$O$65536)-1,1)
Name 省_洲: [1]亚马逊地址库!$L$2:$L$428
Name 邮编: [1]亚马逊地址库!$N$2:$N$428
Name \0: #REF!
Name _Loc11: [3]Request!$M$135

Sheet 目录
B1: 深圳市商速航供应链有限公司
B3: 区域 | C3: 渠道名称 | D3: 链接价格 | E3: 派送方式 | F3: 渠道优势简介 | G3: 价格动态 | H3: 执行日期
B4: 美国海运 (卡派) | C4: 美森正班-卡派 | D4: 点击进入 | E4: 卡车派 | F4: 预计时效：最快13-22个自然日入仓,热门仓有时效延误理赔！ | G4: 上调 | H4: 46112
C5: 美森MAX-卡派 | D5: 点击进入 | E5: 卡车派 | F5: 预计时效：最快14-24个自然日入仓,热门仓有时效延误理赔！ | G5: 上调 | H5: 46112
C6: 快船EXX-卡派 | D6: 点击进入 | E6: 卡车派 | F6: 预计时效：最快14-24个自然日入仓,热门仓有时效延误理赔！ | G6: 上调 | H6: 46112
C7: 盐田以星南沙合德限时达卡派 | D7: 点击进入 | E7: 卡车派 | F7: 预计时效：最快18-25个自然日入仓.热门仓有时效延误理赔！ | G7: 上调 | H7: 46112
C8: 义乌合德以星限时达卡派 | D8: 点击进入 | E8: 卡车派 | F8: 预计时效：最快18-25个自然日入仓.热门仓有时效延误理赔！ | G8: 上调 | H8: 46112
C9: 普船洛杉矶-卡派 | D9: 点击进入 | E9: 卡车派 | F9: 洛杉矶拆柜-南加州FBA仓库价格优惠,组合仓点大幅调整 | G9: 上调 | H9: 46112
C10: 普船纽约-卡派 | D10: 点击进入 | E10: 卡车派 | F10: 纽约拆柜-美东及周边仓库价格实惠 | G10: 上调 | H10: 46112
C11: 普船萨凡纳-卡派 | D11: 点击进入 | E11: 卡车派 | F11: 萨凡纳拆柜-美东南附近FBA仓库及GA周边仓点最优选择 | G11: 上调 | H11: 46112
B12: 美国海运 (快递派) | C12: 美森正班-海派 | D12: 点击进入 | E12: FEDEX/UPS派 | F12: 预计提取时间:开船后12-15天提取，超时提取有赔付. | G12: 上调 | H12: 46112
C13: 美森加班-海派 | D13: 点击进入 | E13: FEDEX/UPS派 | F13: 预计提取时间:开船后13-16天提取，超时提取有赔付. | G13: 上调 | H13: 46112
C14: 快船EXX-海派 | D14: 点击进入 | E14: FEDEX/UPS派 | F14: 预计提取时间:开船后14-18天提取，超时提取有赔付. | G14: 上调 | H14: 46112
C15: 义乌合德以星限时达海派 | D15: 点击进入 | E15: FEDEX/UPS派 | F15: 预计提取时间:开船后14-18天提取，超时提取有赔付. | G15: 上调 | H15: 46112
C16: 普船洛杉矶-海派 | D16: 点击进入 | E16: FEDEX/UPS派 | F16: 预计提取时间:开船后20-25天提取. | G16: 上调 | H16: 46112
C17: 预配船期表 | D17: 点击进入 | E17: —— | F17: 海运各渠道预配当周及下一周对应船期表. | H17: 46112
B18: 海外仓 | C18: 海外仓收费明细 | D18: 点击进入 | E18: 综合 | F18: 自营海外仓综合服务，一件代发价格单询； | H18: 46112
B21: 其它 | C21: 注意事项 | D21: 点击进入 | E21: —— | F21: 出货前请详细查阅 | H21: 46112
C22: 赔偿说明 | D22: 点击进入 | E22: —— | F22: 出货前请详细查阅 | H22: 46112
C23: 专线出货资料模版 | D23: 点击进入 | E23: —— | F23: 根据渠道仓点变化会不定期更新 | H23: 46112
C24: FBA仓库邮编地址对照表 | D24: 点击进入 | E24: —— | F24: 亚马逊仓点会不定期新增或关闭 | H24: 46112
C25: 交接清单模版 | D25: 点击进入 | E25: —— | F25: 可用任意签名盖章的交接清单 | H25: 46112
C26: 禁运品反倾销及特殊监管产品 | D26: 点击进入 | E26: —— | F26: 美线接货原则，相关产品需要资质认证大体明细 | H26: 46112
C27: 美国对华反倾销产品目录表 | D27: 点击进入 | E27: —— | F27: 美国对于反倾销产品的归类会不定期更新,以实际出货清关为准! | H27: 46112
B28: 特别提示:如客户一旦同意接受我司服务，我司将默认为客户已详细阅读过此价格表内所有备注条款内容，并接受各条款的约束，严格按照备注条款内容执行!
B29: 货物下单网址：http://shangs.nextsls.com/wos
B30: 中性查件网址：http://tracking.nextsls.com/trace?app=607444a03aff974cf203c187
B31: 特别提示：各代理，交货前请下单备好交接清单明细并签名盖章，谢谢配合！
B32: 福永仓库地址：深圳市宝安区福海街道福园一路高新建工业区一楼商速航供应链(岗亭直走到底最里面左手边) （导航：商速航福永仓） 联系人：陆先生：15677767671（紧急联系人李先生：15625507507) 收货时间：周一至周六上午9:00~晚上21:00
B33: 龙华仓库地址：深圳市龙华区福城街道福民社区富康工业区A2栋厂房1楼（商速航龙华仓） 联系人：党先生：15591381931 收货时间：周一至周六12:00~24:00
B34: 义乌仓库地址：浙江省金华市义乌市义乌京东亚洲一号物流园祥瑞路3号门进来右手边上天桥二楼开到头右手边4号库（导航：4栋2楼4号商速航义乌仓） 晚班-联系人：钱先生 电话：18386399460（晚班） 早班-联系人：蔡先生 18083572991（早班） 收货时间：周一至周六上午9:00~晚上21:00
B35: 广州仓地址：广东省广州市白云区狮子岭路35号四横路同星空间A101室 联系人：徐生 13376654475 联系人：李生 19128676486 联系人：袁生 19124276567 收货时间：周一至周六12:00~21:00
B36: 厦门仓库地址：厦门市湖里区渔港中路18号自贸园12号仓（进门左前方）导航搜索：天鹰快运（厦门中心） 电话：0592-5738618 电话：0592-5738628 联系人：张友 13950174628 收货时间：周一至周六9:00~22:00
B37: 泉州仓库地址：泉州市晋江池店镇凤池路凤池路鸿运物流城天鹰快运 电话:0595-22594288 0595-22429199 联系人：黄小姐 13850700342 收货时间：周一至周六9:00~22:00
B38: 福州收货地址：福州晓峰驾驶员培训有限公司（通鹤路东） 联系人：黄强强 19196240796 收货时间：周一至周六10:00~21:00
B39: 美森/义乌普船报关行 义乌市欣扬报关代理有限公司 33189800E6 离境口岸 (310703) ：上海外高桥保税区 出境关别 (2225)：外港海关
B44: 盐田渠道报关件委托报关行更新： 深圳普船 以星 盐田出 报关行请委托以下报关行 深圳市友缘国际物流有限公司 4403980C4Q 离境口岸：盐田（470601） 出境关别（：大鹏海关 （5316）

Sheet 预配船期表
B1: 商速航美国海运装柜计划 (4月1日-4月7日)
B2: 渠道 | C2: 起运港 | D2: 目的港 | E2: 船名航次 | F2: ETD 以实际开船为准 | G2: ETA 以实际到港为准 | H2: 截单时间 收满提前截单 | I2: 预计装柜时间 | J2: 预计最晚装柜时间 | K2: 剩余舱位/CBM
B3: 美森限时达CLX 深圳装柜 | C3: 上海 | D3: 长滩 | E3: MATSON WAIKIKI 023E | F3: 46120 | G3: 46131 | H3: 周六 | I3: 周六 | J3: 周日 | K3: 仓位充足
B4: 美森限时达CLX 义乌装柜 | E4: MATSON WAIKIKI 023E | F4: 46120 | G4: 46131 | H4: 周六 | I4: 周六 | J4: 周一 | K4: 仓位充足
B5: 美森加班MAX 深圳装柜 | C5: 上海 | D5: 长滩 | E5: MANUKAI 254E | F5: 46121 | G5: 46132 | H5: 周六 | I5: 周六 | J5: 周一 | K5: 仓位充足
B6: 美森加班MAX 义乌装柜 | E6: MANUKAI 254E | F6: 46121 | G6: 46132 | H6: 周六 | I6: 周六 | J6: 周二 | K6: 仓位充足
B7: JF美森加班MAX 深圳装柜 | C7: 宁波 | D7: 长滩 | E7: MANUKAI 254E | F7: 46119 | G7: 46132 | H7: 周六下午六点福永截 | I7: 周六 | J7: 周六 | K7: 仓位充足
B8: EXX 快船 深圳装柜 | C8: 上海 | D8: 洛杉矶 | E8: CMA CGM SWORDFISH 0GVMCE1MA | F8: 46121 | G8: 46132 | H8: 周六 | I8: 周六 | J8: 周一 | K8: 仓位充足
B9: EXX 快船 义乌装柜 | C9: 上海 | D9: 洛杉矶 | E9: CMA CGM SWORDFISH 0GVMCE1MA | F9: 46121 | G9: 46132 | H9: 周六 | I9: 周六 | J9: 周二 | K9: 仓位充足
B10: JFEXX 快船 深圳装柜 | C10: 上海 | D10: 洛杉矶 | E10: CMA CGM SWORDFISH 0GVMCE1MA | F10: 46120 | G10: 46132 | H10: 周六下午六点福永截 | I10: 周六 | J10: 周六 | K10: 仓位充足
B11: 盐田以星南沙合德限时达 交货深圳/广州 统配 | C11: 盐田 | D11: 洛杉矶 | E11: NESTOS 15E | F11: 46120 | G11: 46133 | H11: 周六 | I11: 周六 | J11: 周日 | K11: 仓位充足
B12: 盐田以星南沙合德限时达 交货深圳/广州 统配 | C12: 南沙 | D12: 洛杉矶 | E12: HELGOLAND 2603E | F12: 46120 | G12: 46134 | H12: 周六 | I12: 周六 | J12: 周日 | K12: 仓位充足
B13: 义乌合德/以星 统配 交货深圳/广州/义乌装柜 | C13: 上海 | D13: 洛杉矶 | E13: DORIS OCEAN 2603E | F13: 46121 | G13: 46134 | H13: 周六 | I13: 周六 | J13: 周日 | K13: 仓位充足
B14: 义乌合德/以星 统配 交货深圳/广州/义乌装柜 | C14: 宁波 | D14: 洛杉矶 | E14: ZIM ALBATROSS 13E | F14: 46121 | G14: 46134 | H14: 周六 | I14: 周六 | J14: 周一 | K14: 仓位充足
B15: 盐田普船OA | C15: 盐田 | D15: 长滩 | E15: COSCO SHIPPING PANAMA 003E | F15: 46122 | G15: 46137 | H15: 周五 | I15: 周五 | J15: 周六 | K15: 仓位充足
B16: 盐田普船OA | C16: 盐田 | D16: 长滩 | E16: OOCL ATLANTA 172E | F16: 46126 | G16: 46140 | H16: 周五 | I16: 周五 | J16: 周五 | K16: 仓位充足
B17: 义乌普船 深圳装柜-循环装柜 | C17: 义乌 | D17: 长滩 | E17: COSCO ITALY 081E | F17: 46117 | G17: 46132 | H17: 周六 | I17: 周六 | J17: 周二 | K17: 仓位充足
B18: 义乌普船 义乌装柜-循环装柜 | E18: CSCL EAST CHINA SEA 076E | F18: 46121 | G18: 46137 | H18: 周六 | I18: 周六 | J18: 周二 | K18: 仓位充足
B19: 义乌普船 义乌装柜-循环装柜 | C19: 义乌 | D19: 洛杉矶 | E19: EVER LASTING 1215-092E | F19: 46119 | G19: 46133 | H19: 周六 | I19: 周六 | J19: 周二 | K19: 仓位充足
B20: 纽约海卡 | C20: 义乌 | D20: 纽约 | E20: COSCO SHIPPING ORCHID 033E | F20: 46119 | G20: 46149 | H20: 周三 | I20: 周三 | J20: 周三 | K20: 仓位充足
B21: 萨凡纳海卡 | C21: 义乌 | D21: 萨凡纳 | E21: EVER FOND 1260-022E | F21: 46121 | G21: 46152 | H21: 周三 | I21: 周三 | J21: 周三 | K21: 仓位充足
B22: 纽约海卡 | C22: 盐田 | D22: 纽约（两水统配） | E22: OOCL LAVENDER 002E | F22: 46124 | G22: 46154 | H22: 周二 | I22: 周二 | J22: 周二 | K22: 仓位充足
B23: 纽约海卡 | E23: EVER MAGI 1353-012E | F23: 46125 | G23: 46161 | H23: 周二 | I23: 周二 | J23: 周二 | K23: 仓位充足
B24: 萨凡纳海卡 | C24: 盐田 | D24: 萨凡纳（两水统配） | E24: EVER MAGI 1353-012E | F24: 46125 | G24: 46157 | H24: 周二 | I24: 周二 | J24: 周二 | K24: 仓位充足
B25: 萨凡纳海卡 | E25: OOCL LAVENDER 002E | F25: 46124 | G25: 46160 | H25: 周二 | I25: 周二 | J25: 周二 | K25: 仓位充足
B26: 船期来自船司官网，最终船司可能会有调整，包括但不仅限于出现延期或者空班等情况，最终时效以实际开船和到港时间为准！

Sheet 卡派FBA价格速查指引
A1: 输入仓码 | B1: 渠道名称 | C1: 深圳/广州交货价 | G1: 义乌交货价 | K1: 入仓参考时效 （开船后次日起算）
C2: 按方含税(2CBM+) | D2: 包税(12KG+) | E2: 包税(51KG+) | F2: 包税(300KG+) | G2: 按方含税(2CBM+) | H2: 包税(12KG+) | I2: 包税(51KG+) | J2: 包税(300KG+)
A3: SCK8 | B3: 美森正班卡派 | C3: {=IFERROR(VLOOKUP("*"&$A$3&"*",INDIRECT("'"&B3&"'!B:L"),{2,3,4,5,6,7,8,9,10},0),"无")} -> 1900 | D3: 10.5 | E3: 9.5 | F3: 9.5 | G3: 1820 | H3: 10.1 | I3: 9.1 | J3: 9.1 | K3: 13-16天
B4: 美森MAX卡派 | C4: {=IFERROR(VLOOKUP("*"&$A$3&"*",INDIRECT("'"&B4&"'!B:L"),{2,3,4,5,6,7,8,9,10},0),"无")} -> 1840 | D4: 10.2 | E4: 9.2 | F4: 9.2 | G4: 1760 | H4: 9.8 | I4: 8.8 | J4: 8.8 | K4: 14-17天
B5: EXX卡派 | C5: {=IFERROR(VLOOKUP("*"&$A$3&"*",INDIRECT("'"&B5&"'!B:L"),{2,3,4,5,6,7,8,9,10},0),"无")} -> 1360 | D5: 7.8 | E5: 6.8 | F5: 6.8 | G5: 1280 | H5: 7.4 | I5: 6.4 | J5: 6.4 | K5: 14-17天
B6: 美西限时达卡派 | C6: {=IFERROR(VLOOKUP("*"&$A$3&"*",INDIRECT("'"&B6&"'!B:L"),{2,3,4,5,6,7,8,9,10},0),"无")} -> 无
B7: 普船洛杉矶卡派 | C7: {=IFERROR(VLOOKUP("*"&$A$3&"*",INDIRECT("'"&B7&"'!B:L"),{2,3,4,5,6,7,8,9,10},0),"无")} -> 860 | D7: 5.3 | E7: 4.3 | F7: 4.3 | G7: 860 | H7: 5.3 | I7: 4.3 | J7: 4.3 | K7: 23-27天
B8: 美西特惠卡派 | C8: {=IFERROR(VLOOKUP("*"&$A$3&"*",INDIRECT("'"&B8&"'!B:L"),{2,3,4,5,6,7,8,9,10},0),"无")} -> 无 | D8: 无 | E8: 无 | F8: 无 | G8: 无 | H8: 无 | I8: 无 | J8: 无 | K8: 22-26天
A9: 输入仓码 | B9: 渠道名称 | C9: 专仓直送(深圳/广州交货价) | F9: 专仓直送(义乌交货价) | I9: 入仓参考时效 （开船后次日起算）
C10: 按方含税(1CBM+) | D10: 包税(12KG+) | E10: 包税(100KG+) | F10: 按方含税(1CBM+) | G10: 包税(12KG+) | H10: 包税(100KG+)
A11: =A3 -> SCK8 | B11: 普船奥克兰卡派 | C11: {=IFERROR(VLOOKUP("*"&A11&"*",INDIRECT("'"&B11&"'!B:L"),{2,3,4,5,6,7,8},0),"无")} -> 无
B12: 普船芝加哥卡派 | C12: {=IFERROR(VLOOKUP("*"&A11&"*",INDIRECT("'"&B12&"'!B:L"),{2,3,4,5,6,7,8},0),"无")} -> 无
B13: 普船纽约卡派 | C13: {=IFERROR(VLOOKUP("*"&A11&"*",INDIRECT("'"&B13&"'!B:L"),{2,3,4,5,6,7,8},0),"无")} -> 无
B14: 普船萨凡纳卡派 | C14: {=IFERROR(VLOOKUP("*"&A11&"*",INDIRECT("'"&B14&"'!B:L"),{2,3,4,5,6,7,8},0),"无")} -> 无

Sheet 价格汇总
B1: 分区/重量 | C1: 深圳/广州交货 | F1: 义乌交货
C2: 12KG+ | D2: 51KG+ | E2: 100KG+ | F2: 12KG+ | G2: 51KG+ | H2: 100KG+ | I2: 12KG+（系数） | J2: 51KG+（系数） | K2: 深圳和义乌系数
A3: SSH美森正班-海派 | B3: 美西 (邮编8,9开头) | C3: =E3+J3 -> 15.4 | D3: =E3+I3 -> 13.4 | E3: 12.4 | F3: =H3+J3 -> 15 | G3: =H3+I3 -> 13 | H3: =E3-K3 -> 12 | I3: 1 | J3: 3 | K3: 0.4 | M3: 80 | N3: 0.1
B4: 美中 (邮编4,5,6,7开头) | C4: =E4+J4 -> 16.6 | D4: =E4+I4 -> 14.6 | E4: 13.6 | F4: =H4+J4 -> 16.2 | G4: =H4+I4 -> 14.2 | H4: =E4-K4 -> 13.2 | I4: 1 | J4: 3 | K4: 0.4
B5: 美东 (邮编0,1,2,3开头) | C5: =E5+J5 -> 17.6 | D5: =E5+I5 -> 15.6 | E5: 14.6 | F5: =H5+J5 -> 17.2 | G5: =H5+I5 -> 15.2 | H5: =E5-K5 -> 14.2 | I5: 1 | J5: 3 | K5: 0.4
A6: SSH美森MAX-海派 | B6: 美西 (邮编8,9开头) | C6: =E6+J6 -> 15.1 | D6: =E6+I6 -> 13.1 | E6: 12.1 | F6: =H6+J6 -> 14.7 | G6: =H6+I6 -> 12.7 | H6: =E6-K6 -> 11.7 | I6: 1 | J6: 3 | K6: 0.4
B7: 美中 (邮编4,5,6,7开头) | C7: =E7+J7 -> 16.3 | D7: =E7+I7 -> 14.3 | E7: 13.3 | F7: =H7+J7 -> 15.9 | G7: =H7+I7 -> 13.9 | H7: =E7-K7 -> 12.9 | I7: 1 | J7: 3 | K7: 0.4
B8: 美东 (邮编0,1,2,3开头) | C8: =E8+J8 -> 17.3 | D8: =E8+I8 -> 15.3 | E8: 14.3 | F8: =H8+J8 -> 16.9 | G8: =H8+I8 -> 14.9 | H8: =E8-K8 -> 13.9 | I8: 1 | J8: 3 | K8: 0.4
A9: SSH快船EXX-海派 | B9: 美西 (邮编8,9开头) | C9: =E9+J9 -> 13.3 | D9: =E9+I9 -> 11.3 | E9: 10.3 | F9: =H9+J9 -> 12.9 | G9: =H9+I9 -> 10.9 | H9: =E9-K9 -> 9.9 | I9: 1 | J9: 3 | K9: 0.4
B10: 美中 (邮编4,5,6,7开头) | C10: =E10+J10 -> 14.5 | D10: =E10+I10 -> 12.5 | E10: 11.5 | F10: =H10+J10 -> 14.1 | G10: =H10+I10 -> 12.1 | H10: =E10-K10 -> 11.1 | I10: 1 | J10: 3 | K10: 0.4
B11: 美东 (邮编0,1,2,3开头) | C11: =E11+J11 -> 15.5 | D11: =E11+I11 -> 13.5 | E11: 12.5 | F11: =H11+J11 -> 15.1 | G11: =H11+I11 -> 13.1 | H11: =E11-K11 -> 12.1 | I11: 1 | J11: 3 | K11: 0.4
A12: SSH以星限时达海派&长荣定提海派&义乌合德限时达-海派 | B12: 美西 (邮编8,9开头) | C12: =E12+J12 -> 12 | D12: =E12+I12 -> 10 | E12: 9 | F12: =H12+J12 -> 12 | G12: =H12+I12 -> 10 | H12: =E12-K12 -> 9 | I12: 1 | J12: 3 | K12: 0
B13: 美中 (邮编4,5,6,7开头) | C13: =E13+J13 -> 13.2 | D13: =E13+I13 -> 11.2 | E13: 10.2 | F13: =H13+J13 -> 13.2 | G13: =H13+I13 -> 11.2 | H13: =E13-K13 -> 10.2 | I13: 1 | J13: 3 | K13: 0
B14: 美东 (邮编0,1,2,3开头) | C14: =E14+J14 -> 14.2 | D14: =E14+I14 -> 12.2 | E14: 11.2 | F14: =H14+J14 -> 14.2 | G14: =H14+I14 -> 12.2 | H14: =E14-K14 -> 11.2 | I14: 1 | J14: 3 | K14: 0
A15: SSH义乌合德以星限时达-海派 | B15: 美西 (邮编8,9开头) | C15: =E15+J15 -> 12.3 | D15: =E15+I15 -> 10.3 | E15: 9.3 | F15: =H15+J15 -> 12 | G15: =H15+I15 -> 10 | H15: =E15-K15 -> 9 | I15: 1 | J15: 3 | K15: 0.3
B16: 美中 (邮编4,5,6,7开头) | C16: =E16+J16 -> 13.5 | D16: =E16+I16 -> 11.5 | E16: 10.5 | F16: =H16+J16 -> 13.2 | G16: =H16+I16 -> 11.2 | H16: =E16-K16 -> 10.2 | I16: 1 | J16: 3 | K16: 0.3
B17: 美东 (邮编0,1,2,3开头) | C17: =E17+J17 -> 14.5 | D17: =E17+I17 -> 12.5 | E17: 11.5 | F17: =H17+J17 -> 14.2 | G17: =H17+I17 -> 12.2 | H17: =E17-K17 -> 11.2 | I17: 1 | J17: 3 | K17: 0.3
A18: SSH普船洛杉矶-海派 | B18: 美西 (邮编8,9开头) | C18: =E18+J18 -> 10.8 | D18: =E18+I18 -> 8.8 | E18: 7.8 | F18: =H18+J18 -> 10.8 | G18: =H18+I18 -> 8.8 | H18: =E18-K18 -> 7.8 | I18: 1 | J18: 3 | K18: 0
B19: 美中 (邮编4,5,6,7开头) | C19: =E19+J19 -> 12 | D19: =E19+I19 -> 10 | E19: 9 | F19: =H19+J19 -> 12 | G19: =H19+I19 -> 10 | H19: =E19-K19 -> 9 | I19: 1 | J19: 3 | K19: 0
B20: 美东 (邮编0,1,2,3开头) | C20: =E20+J20 -> 13 | D20: =E20+I20 -> 11 | E20: 10 | F20: =H20+J20 -> 13 | G20: =H20+I20 -> 11 | H20: =E20-K20 -> 10 | I20: 1 | J20: 3 | K20: 0
A22: SSH美森正班卡派 | B22: 仓库代码 | C22: 深圳/广州交货价 | G22: 义乌交货价
C23: 按方含税(2CBM+) | D23: 包税(12KG+) | E23: 包税(51KG+) | F23: 包税(300KG+) | G23: 按方含税(2CBM+) | H23: 包税(12KG+) | I23: 包税(51KG+) | J23: 包税(300KG+) | K23: 按方含税(2CBM+) | L23: 包税(12KG+) | M23: 包税(51KG+) | N23: 深圳和义乌系数
B24: ONT8/LGB8/LAX9/SBD1/IUSP IUSQ/IUSJ/POC1/POC2/POC3 | C24: =F24*200 -> 1800 | D24: =F24+L24 -> 10 | E24: =F24+M24 -> 9 | F24: =J24+N24 -> 9 | G24: =J24*200 -> 1720 | H24: =D24-N24 -> 9.6 | I24: =E24-N24 -> 8.6 | J24: 8.6 | K24: 80 | L24: 1 | M24: 0 | N24: 0.4 | P24: 0.3 | Q24: 80
B25: SNA4/SBD2/LGB4/LGB6 XLX7/IUTI/IUSW/PSP3 | C25: =F25*200 -> 1840 | D25: =F25+L25 -> 10.2 | E25: =F25+M25 -> 9.2 | F25: =J25+N25 -> 9.2 | G25: =J25*200 -> 1760 | H25: =D25-N25 -> 9.8 | I25: =E25-N25 -> 8.8 | J25: 8.8 | K25: 80 | L25: 1 | M25: 0 | N25: 0.4
B26: SMF3/SCK4/LAS1/GYR2/GYR3 MIT2/VGT2/GEU2/GEU3/GEU5 HLI2/TCY2/TCY1/SCK8/SMF6 OAK3/MCE1/LAS6/SJC7/FAT2 PHX5/PHX7/IUTE | C26: =F26*200 -> 1900 | D26: =F26+L26 -> 10.5 | E26: =F26+M26 -> 9.5 | F26: =J26+N26 -> 9.5 | G26: =J26*200 -> 1820 | H26: =D26-N26 -> 10.1 | I26: =E26-N26 -> 9.1 | J26: 9.1 | K26: 80 | L26: 1 | M26: 0 | N26: 0.4
B27: ABQ2/QXY8/MCC1 | C27: =F27*200 -> 2060 | D27: =F27+L27 -> 11.3 | E27: =F27+M27 -> 10.3 | F27: =J27+N27 -> 10.3 | G27: =J27*200 -> 1980 | H27: =D27-N27 -> 10.9 | I27: =E27-N27 -> 9.9 | J27: 9.9 | K27: 80 | L27: 1 | M27: 0 | N27: 0.4
B28: FTW1/IUSF/DFW6/IAH3/SAT1 FTW5/STL3/PSC2/PDX7 (标红仓点按12KG起收) 单价按100KG段+1/KG 51KG-100KG按100KG+同价 | C28: =F28*200 -> 2160 | D28: 100KG起收 | E28: 100KG起收 | F28: =J28+N28 -> 10.8 | G28: =J28*200 -> 2080 | H28: 100KG起收 | I28: 100KG起收 | J28: 10.4 | K28: 80 | L28: 1 | M28: 0 | N28: 0.4
B29: IND9/MDW2/FWA4/MEM1 MQJ1/DEN8/RFD2/ORD2/LFT1 (标红仓点按12KG起收) 单价按100KG段+1/KG 51KG-100KG按100KG+同价 | C29: =F29*200 -> 2200 | D29: 100KG起收 | E29: 100KG起收 | F29: =J29+N29 -> 11 | G29: =J29*200 -> 2120 | H29: 100KG起收 | I29: 100KG起收 | J29: 10.6 | K29: 80 | L29: 1 | M29: 0 | N29: 0.4
B30: CLT2/RDU2/CLT3/RDU4 (标红仓点按12KG起收) 单价按100KG段+1/KG 51KG-100KG按100KG+同价 | C30: =F30*200 -> 2380 | D30: 100KG起收 | E30: 100KG起收 | F30: =J30+N30 -> 11.9 | G30: =J30*200 -> 2300 | H30: 100KG起收 | I30: 100KG起收 | J30: 11.5 | K30: 80 | L30: 1 | M30: 0 | N30: 0.4
B31: ABE8/AVP1/TEB3/TEB9/TPA3 RMN3/ORF2/SWF2 (标红仓点按12KG起收) 单价按100KG段+1/KG 51KG-100KG按100KG+同价 | C31: =F31*200 -> 2460 | D31: 100KG起收 | E31: 100KG起收 | F31: =J31+N31 -> 12.3 | G31: =J31*200 -> 2380 | H31: 100KG起收 | I31: 100KG起收 | J31: 11.9 | K31: 80 | L31: 1.5 | M31: 0 | N31: 0.4
B32: 含税自提(含出库费） | C32: =F32*200 -> 1800 | D32: —— | E32: —— | F32: =J32+N32 -> 9 | G32: =J32*200 -> 1720 | H32: —— | I32: —— | J32: 8.6 | K32: 80 | N32: 0.4
A34: SSH美森MAX卡派 | B34: 仓库代码 | C34: 深圳/广州交货价 | G34: 义乌交货价
C35: 按方含税(2CBM+) | D35: 包税(12KG+) | E35: 包税(51KG+) | F35: 包税(300KG+) | G35: 按方含税(2CBM+) | H35: 包税(12KG+) | I35: 包税(51KG+) | J35: 包税(300KG+) | K35: 按方含税(2CBM+) | L35: 包税(12KG+) | M35: 包税(51KG+) | N35: 深圳和义乌系数
B36: ONT8/LGB8/LAX9/SBD1/IUSP IUSQ/IUSJ/POC1/POC2/POC3 | C36: =F36*200 -> 1740 | D36: =F36+L36 -> 9.7 | E36: =F36+M36 -> 8.7 | F36: =J36+N36 -> 8.7 | G36: =J36*200 -> 1660 | H36: =D36-N36 -> 9.3 | I36: =E36-N36 -> 8.3 | J36: 8.3 | K36: 80 | L36: 1 | M36: 0 | N36: 0.4 | P36: 80 | Q36: 0.3
B37: SNA4/SBD2/LGB4/LGB6 XLX7/IUTI/IUSW/PSP3 | C37: =F37*200 -> 1780 | D37: =F37+L37 -> 9.9 | E37: =F37+M37 -> 8.9 | F37: =J37+N37 -> 8.9 | G37: =J37*200 -> 1700 | H37: =D37-N37 -> 9.5 | I37: =E37-N37 -> 8.5 | J37: 8.5 | K37: 80 | L37: 1 | M37: 0 | N37: 0.4
B38: SMF3/SCK4/LAS1/GYR2/GYR3 MIT2/VGT2/GEU2/GEU3/GEU5 HLI2/TCY2/TCY1/SCK8/SMF6 OAK3/MCE1/LAS6/SJC7/FAT2 PHX5/PHX7/IUTE | C38: =F38*200 -> 1840 | D38: =F38+L38 -> 10.2 | E38: =F38+M38 -> 9.2 | F38: =J38+N38 -> 9.2 | G38: =J38*200 -> 1760 | H38: =D38-N38 -> 9.8 | I38: =E38-N38 -> 8.8 | J38: 8.8 | K38: 80 | L38: 1 | M38: 0 | N38: 0.4
B39: ABQ2/QXY8/MCC1 | C39: =F39*200 -> 2000 | D39: =F39+L39 -> 11 | E39: =F39+M39 -> 10 | F39: =J39+N39 -> 10 | G39: =J39*200 -> 1920 | H39: =D39-N39 -> 10.6 | I39: =E39-N39 -> 9.6 | J39: 9.6 | K39: 80 | L39: 1 | M39: 0 | N39: 0.4
B40: FTW1/IUSF/DFW6/IAH3/SAT1 FTW5/STL3/PSC2/PDX7 (标红仓点按12KG起收) 单价按100KG段+1/KG 51KG-100KG按100KG+同价 | C40: =F40*200 -> 2100 | D40: 100KG起收 | E40: 100KG起收 | F40: =J40+N40 -> 10.5 | G40: =J40*200 -> 2020 | H40: 100KG起收 | I40: 100KG起收 | J40: 10.1 | K40: 80 | L40: 1 | M40: 0 | N40: 0.4
B41: IND9/MDW2/FWA4/MEM1 MQJ1/DEN8/RFD2/ORD2/LFT1 (标红仓点按12KG起收) 单价按100KG段+1/KG 51KG-100KG按100KG+同价 | C41: =F41*200 -> 2140 | D41: 100KG起收 | E41: 100KG起收 | F41: =J41+N41 -> 10.7 | G41: =J41*200 -> 2060 | H41: 100KG起收 | I41: 100KG起收 | J41: 10.3 | K41: 80 | L41: 1 | M41: 0 | N41: 0.4
B42: CLT2/RDU2/CLT3/RDU4 (标红仓点按12KG起收) 单价按100KG段+1/KG 51KG-100KG按100KG+同价 | C42: =F42*200 -> 2320 | D42: 100KG起收 | E42: 100KG起收 | F42: =J42+N42 -> 11.6 | G42: =J42*200 -> 2240 | H42: 100KG起收 | I42: 100KG起收 | J42: 11.2 | K42: 80 | L42: 1 | M42: 0 | N42: 0.4
...

Sheet 美国海派总表
B1: SSH美森正班-海派 渠道代码：SSH01 （进福建内陆费+0.4/KG）
B2: 交货下单渠道：SSH01-海派
B3: 人民币计价 | J3: 执行日期：2026-3-31
B4: 分区/重量 | C4: 深圳/广州交货 | F4: 义乌交货 | I4: 预计提取时间 | J4: 比重货优惠 | K4: 备注 | L4: 预计派送时效 | M4: 返回主页
C5: 21KG+ | D5: 51KG+ | E5: 100KG+ | F5: 21KG+ | G5: 51KG+ | H5: 100KG+
B6: 美西 (邮编8,9开头) | C6: =价格汇总!C3 -> 15.4 | D6: =价格汇总!D3 -> 13.4 | E6: =价格汇总!E3 -> 12.4 | F6: =价格汇总!F3 -> 15 | G6: =价格汇总!G3 -> 13 | H6: =价格汇总!H3 -> 12 | I6: 开船后第二天开始算,15天内提取-晚一天赔1元,提取当天不计赔偿日,最高赔付3元/KG. (如遇海关查验,节假日,码头停摆，码头罢工等不可抗拒因素，不参与时效赔偿) | J6: 单票51KG以上 重货比优惠： 1:200 表价减0.5元 1:250 表价减1.5元 1:300 表价减2元 1:350 表价减2.5元 1:400 表价减3元 1:500以上 表价减3.5元 | K6: 1，尾程FEDEX/UPS派送 2，材积/6000,不分泡 3，包含关税及查验费 4，报关件5CBM起接 5，入仓清单请注明： 美森正班-海派 | L6: 1-2天
B7: 美中 (邮编4,5,6,7开头) | C7: =价格汇总!C4 -> 16.6 | D7: =价格汇总!D4 -> 14.6 | E7: =价格汇总!E4 -> 13.6 | F7: =价格汇总!F4 -> 16.2 | G7: =价格汇总!G4 -> 14.2 | H7: =价格汇总!H4 -> 13.2 | L7: 3-4天
B8: 美东 (邮编0,1,2,3开头) | C8: =价格汇总!C5 -> 17.6 | D8: =价格汇总!D5 -> 15.6 | E8: =价格汇总!E5 -> 14.6 | F8: =价格汇总!F5 -> 17.2 | G8: =价格汇总!G5 -> 15.2 | H8: =价格汇总!H5 -> 14.2 | L8: 4-5天
B9: SSH美森MAX-海派 渠道代码：SSH02 （进福建内陆费+0.4/KG）
B10: 交货下单渠道：SSH02-海派/SSHJF02-海派
B11: 分区/重量 | C11: 深圳/广州交货 | F11: 义乌交货 | I11: 预计提取时间 | J11: 比重货优惠 | K11: 备注 | L11: 预计派送时效
C12: 21KG+ | D12: 51KG+ | E12: 100KG+ | F12: 21KG+ | G12: 51KG+ | H12: 100KG+
B13: 美西 (邮编8,9开头) | C13: =价格汇总!C6 -> 15.1 | D13: =价格汇总!D6 -> 13.1 | E13: =价格汇总!E6 -> 12.1 | F13: =价格汇总!F6 -> 14.7 | G13: =价格汇总!G6 -> 12.7 | H13: =价格汇总!H6 -> 11.7 | I13: 开船后第二天开始算,16天内提取-晚一天赔1元,提取当天不计赔偿日,最高赔付3元/KG.（海关查验及不可抗因素除外） | J13: 单票51KG以上 重货比优惠： 1:200 表价减0.5元 1:250 表价减1.5元 1:300 表价减2元 1:350 表价减2.5元 1:400 表价减3元 1:500以上 表价减3.5元 | K13: 1，尾程FEDEX/UPS派送 2，材积/6000，不分泡 3，包含关税及查验费 4，入仓清单请注明： 美森加班-海派 | L13: 1-2天
B14: 美中 (邮编4,5,6,7开头) | C14: =价格汇总!C7 -> 16.3 | D14: =价格汇总!D7 -> 14.3 | E14: =价格汇总!E7 -> 13.3 | F14: =价格汇总!F7 -> 15.9 | G14: =价格汇总!G7 -> 13.9 | H14: =价格汇总!H7 -> 12.9 | L14: 3-4天
B15: 美东 (邮编0,1,2,3开头) | C15: =价格汇总!C8 -> 17.3 | D15: =价格汇总!D8 -> 15.3 | E15: =价格汇总!E8 -> 14.3 | F15: =价格汇总!F8 -> 16.9 | G15: =价格汇总!G8 -> 14.9 | H15: =价格汇总!H8 -> 13.9 | L15: 4-5天
B16: SSH快船EXX-海派 渠道代码：SSH03 （进福建内陆费+0.4/KG）
B17: 交货下单渠道：SSH03-海派/SSHJF03-海派
B18: 分区/重量 | C18: 深圳/广州交货 | F18: 义乌交货 | I18: 预计提取时间 | J18: 比重货优惠 | K18: 备注 | L18: 预计派送时效
C19: 21KG+ | D19: 51KG+ | E19: 100KG+ | F19: 21KG+ | G19: 51KG+ | H19: 100KG+
B20: 美西 (邮编8,9开头) | C20: =价格汇总!C9 -> 13.3 | D20: =价格汇总!D9 -> 11.3 | E20: =价格汇总!E9 -> 10.3 | F20: =价格汇总!F9 -> 12.9 | G20: =价格汇总!G9 -> 10.9 | H20: =价格汇总!H9 -> 9.9 | I20: 开船后第二天开始算,16天内提取-晚一天赔1元,提取当天不计赔偿日,最高赔付2元/KG.（海关查验及不可抗因素除外） | J20: 单票51KG以上 重货比优惠： 1:200 表价减0.5元 1:250 表价减1.5元 1:300 表价减2元 1:350 表价减2.5元 1:400 表价减3元 1:500以上 表价减3.5元 | K20: 1，尾程FEDEX/UPS派送 2，材积/6000，不分泡 3，包含关税及查验费 4，入仓清单请注明： 快船EXX-海派 | L20: 1-2天
B21: 美中 (邮编4,5,6,7开头) | C21: =价格汇总!C10 -> 14.5 | D21: =价格汇总!D10 -> 12.5 | E21: =价格汇总!E10 -> 11.5 | F21: =价格汇总!F10 -> 14.1 | G21: =价格汇总!G10 -> 12.1 | H21: =价格汇总!H10 -> 11.1 | L21: 3-4天
B22: 美东 (邮编0,1,2,3开头) | C22: =价格汇总!C11 -> 15.5 | D22: =价格汇总!D11 -> 13.5 | E22: =价格汇总!E11 -> 12.5 | F22: =价格汇总!F11 -> 15.1 | G22: =价格汇总!G11 -> 13.1 | H22: =价格汇总!H11 -> 12.1 | L22: 4-5天
B23: SSH盐田以星南沙合德限时达-海派 渠道代码：SSH04
B24: 交货深圳/广州下单渠道：SSH04-海派
B25: 分区/重量 | C25: 深圳交货 | F25: 广州交货 | I25: 预计提取时间 | J25: 比重货优惠 | K25: 备注 | L25: 预计派送时效
C26: 21KG+ | D26: 51KG+ | E26: 100KG+ | F26: 21KG+ | G26: 51KG+ | H26: 100KG+
B27: 美西 (邮编8,9开头) | C27: =价格汇总!C12 -> 12 | D27: =价格汇总!D12 -> 10 | E27: =价格汇总!E12 -> 9 | F27: =价格汇总!F12 -> 12 | G27: =价格汇总!G12 -> 10 | H27: =价格汇总!H12 -> 9 | I27: 开船后第二天开始算,18天内提取-晚一天赔0.5元,提取当天不计赔偿日,最高赔付1元/KG.（海关查验及不可抗因素除外） | J27: 单票51KG以上 重货比优惠： 1:200减0.5 1:250减1 1:300减1.5 1:350减2 1:450及以上减2.5 | K27: 1，尾程FEDEX/UPS派送 2，材积/6000，不分泡 3，包含关税及查验费 4，入仓清单请注明： 美西限时达-海派 | L27: 1-2天
B28: 美中 (邮编4,5,6,7开头) | C28: =价格汇总!C13 -> 13.2 | D28: =价格汇总!D13 -> 11.2 | E28: =价格汇总!E13 -> 10.2 | F28: =价格汇总!F13 -> 13.2 | G28: =价格汇总!G13 -> 11.2 | H28: =价格汇总!H13 -> 10.2 | L28: 3-4天
B29: 美东 (邮编0,1,2,3开头) | C29: =价格汇总!C14 -> 14.2 | D29: =价格汇总!D14 -> 12.2 | E29: =价格汇总!E14 -> 11.2 | F29: =价格汇总!F14 -> 14.2 | G29: =价格汇总!G14 -> 12.2 | H29: =价格汇总!H14 -> 11.2 | L29: 4-5天
B30: SSH义乌合德以星限时达-海派 渠道代码：SSHYW05（进福建内陆费+0.4/KG）
B31: 交货深圳/广州/义乌下单渠道：SSHYW05-海派/SSHYWJF05-海派
B32: 分区/重量 | C32: 深圳、广州交货 | F32: 义乌交货 | I32: 预计提取时间 | J32: 比重货优惠 | K32: 备注 | L32: 预计派送时效
C33: 21KG+ | D33: 51KG+ | E33: 100KG+ | F33: 21KG+ | G33: 51KG+ | H33: 100KG+
B34: 美西 (邮编8,9开头) | C34: =价格汇总!C15 -> 12.3 | D34: =价格汇总!D15 -> 10.3 | E34: =价格汇总!E15 -> 9.3 | F34: =价格汇总!F15 -> 12 | G34: =价格汇总!G15 -> 10 | H34: =价格汇总!H15 -> 9 | I34: 开船后第二天开始算,18天内提取-晚一天赔0.5元,提取当天不计赔偿日,最高赔付1元/KG.（海关查验及不可抗因素除外） | J34: 单票51KG以上 重货比优惠： 1:200减0.5 1:250减1 1:300减1.5 1:350减2 1:450及以上减2.5 | K34: 1，尾程FEDEX/UPS派送 2，材积/6000，不分泡 3，包含关税及查验费 4，入仓清单请注明： 美西限时达-海派 | L34: 1-2天
B35: 美中 (邮编4,5,6,7开头) | C35: =价格汇总!C16 -> 13.5 | D35: =价格汇总!D16 -> 11.5 | E35: =价格汇总!E16 -> 10.5 | F35: =价格汇总!F16 -> 13.2 | G35: =价格汇总!G16 -> 11.2 | H35: =价格汇总!H16 -> 10.2 | L35: 3-4天
B36: 美东 (邮编0,1,2,3开头) | C36: =价格汇总!C17 -> 14.5 | D36: =价格汇总!D17 -> 12.5 | E36: =价格汇总!E17 -> 11.5 | F36: =价格汇总!F17 -> 14.2 | G36: =价格汇总!G17 -> 12.2 | H36: =价格汇总!H17 -> 11.2 | L36: 4-5天
B37: SSH普船洛杉矶-海派 渠道代码：SSH07 （进福建内陆费+0.4/KG）
B38: 交货深圳下单渠道：SSH07-海派 交货义乌下单渠道：SSHYW07-海派/SSHYWJF07--海派（义乌普船进深圳、广州内陆费+0.3/KG）
B39: 分区/重量 | C39: 深圳/广州交货 | F39: 义乌交货 | I39: 预计提取时间 | J39: 比重货优惠 | K39: 备注 | L39: 预计派送时效
C40: 21KG+ | D40: 51KG+ | E40: 100KG+ | F40: 21KG+ | G40: 51KG+ | H40: 100KG+
...

Sheet 美森正班卡派
B1: SSH美森正班卡派 渠道代码：SSH01 （进福建内陆费+0.4/KG）
B3: 下单渠道：SSH01卡派/SSH01卡派-按方计费
B4: 人民币报价 | K4: 执行日期：2026-3-31
B5: 仓库代码 | C5: 深圳/广州交货价 | G5: 义乌交货价 | K5: 入仓参考时效 （开船后次日起算） | L5: 理赔时效 (自然日) | M5: 返回主页
C6: 按方含税(2CBM+) | D6: 包税(12KG+) | E6: 包税(51KG+) | F6: 包税(100KG+) | G6: 按方含税(2CBM+) | H6: 包税(12KG+) | I6: 包税(51KG+) | J6: 包税(100KG+)
B7: ONT8/LGB8/LAX9/SBD1 IUSP/IUSQ/IUSJ/POC1 POC2/POC3 | C7: =价格汇总!C24 -> 1800 | D7: =价格汇总!D24 -> 10 | E7: =价格汇总!E24 -> 9 | F7: =价格汇总!F24 -> 9 | G7: =价格汇总!G24 -> 1720 | H7: =价格汇总!H24 -> 9.6 | I7: =价格汇总!I24 -> 8.6 | J7: =价格汇总!J24 -> 8.6 | K7: 12-15天 | L7: 16天 (开船第二天开始,承诺16天内入仓(送仓当日不算赔付时效),第17天开始, 退0.5元/KG/每天,最多退2元/KG)
B8: SNA4/SBD2/LGB4/LGB6 XLX7/IUTI/IUSW/PSP3 | C8: =价格汇总!C25 -> 1840 | D8: =价格汇总!D25 -> 10.2 | E8: =价格汇总!E25 -> 9.2 | F8: =价格汇总!F25 -> 9.2 | G8: =价格汇总!G25 -> 1760 | H8: =价格汇总!H25 -> 9.8 | I8: =价格汇总!I25 -> 8.8 | J8: =价格汇总!J25 -> 8.8 | K8: 13-16天 | L8: 无时效理赔
B9: SMF3/SCK4/LAS1/GYR2 GYR3/MIT2/VGT2/GEU2 GEU3/GEU5/HLI2/TCY2 TCY1/SCK8/SMF6/OAK3 MCE1/LAS6/SJC7/FAT2 PHX5/PHX7/IUTE | C9: =价格汇总!C26 -> 1900 | D9: =价格汇总!D26 -> 10.5 | E9: =价格汇总!E26 -> 9.5 | F9: =价格汇总!F26 -> 9.5 | G9: =价格汇总!G26 -> 1820 | H9: =价格汇总!H26 -> 10.1 | I9: =价格汇总!I26 -> 9.1 | J9: =价格汇总!J26 -> 9.1 | K9: 13-16天 | L9: 无时效理赔
B10: ABQ2/QXY8/MCC1 | C10: =价格汇总!C27 -> 2060 | D10: =价格汇总!D27 -> 11.3 | E10: =价格汇总!E27 -> 10.3 | F10: =价格汇总!F27 -> 10.3 | G10: =价格汇总!G27 -> 1980 | H10: =价格汇总!H27 -> 10.9 | I10: =价格汇总!I27 -> 9.9 | J10: =价格汇总!J27 -> 9.9 | K10: 13-16天 | L10: 17天 (开船第二天开始,承诺17天内入仓(送仓当日不算赔付时效),第18天开始, 退0.5元/KG/每天,最多退2元/KG)
B11: FTW1/IUSF/DFW6/IAH3 SAT1/FTW5/STL3/PSC2 PDX7 (标红仓点按12KG起收) 单价按100KG段+1/KG 51KG-100KG按100KG+同价 | C11: =价格汇总!C28 -> 2160 | D11: =价格汇总!D28 -> 100KG起收 | E11: =价格汇总!E28 -> 100KG起收 | F11: =价格汇总!F28 -> 10.8 | G11: =价格汇总!G28 -> 2080 | H11: =价格汇总!H28 -> 100KG起收 | I11: =价格汇总!I28 -> 100KG起收 | J11: =价格汇总!J28 -> 10.4 | K11: 14-17天 | L11: 无时效理赔
B12: IND9/MDW2/FWA4/MEM1 MQJ1/DEN8/RFD2/ORD2 LFT1 (标红仓点按12KG起收) 单价按100KG段+1/KG 51KG-100KG按100KG+同价 | C12: =价格汇总!C29 -> 2200 | D12: =价格汇总!D29 -> 100KG起收 | E12: =价格汇总!E29 -> 100KG起收 | F12: =价格汇总!F29 -> 11 | G12: =价格汇总!G29 -> 2120 | H12: =价格汇总!H29 -> 100KG起收 | I12: =价格汇总!I29 -> 100KG起收 | J12: =价格汇总!J29 -> 10.6 | K12: 15-18天 | L12: 无时效理赔
B13: CLT2/RDU2/CLT3/RDU4 (标红仓点按12KG起收) 单价按100KG段+1/KG 51KG-100KG按100KG+同价 | C13: =价格汇总!C30 -> 2380 | D13: =价格汇总!D30 -> 100KG起收 | E13: =价格汇总!E30 -> 100KG起收 | F13: =价格汇总!F30 -> 11.9 | G13: =价格汇总!G30 -> 2300 | H13: =价格汇总!H30 -> 100KG起收 | I13: =价格汇总!I30 -> 100KG起收 | J13: =价格汇总!J30 -> 11.5 | K13: 15-18天 | L13: 无时效理赔
B14: ABE8/AVP1/TEB3/TEB9 TPA3 /RMN3/ORF2/SWF2 (标红仓点按12KG起收) 单价按100KG段+1/KG 51KG-100KG按100KG+同价 | C14: =价格汇总!C31 -> 2460 | D14: =价格汇总!D31 -> 100KG起收 | E14: =价格汇总!E31 -> 100KG起收 | F14: =价格汇总!F31 -> 12.3 | G14: =价格汇总!G31 -> 2380 | H14: =价格汇总!H31 -> 100KG起收 | I14: =价格汇总!I31 -> 100KG起收 | J14: =价格汇总!J31 -> 11.9 | K14: 18-20天 | L14: 无时效理赔
B15: 含税自提(出库费15美金/托 汇率7） | C15: =价格汇总!C32 -> 1800 | D15: =价格汇总!D32 -> —— | E15: =价格汇总!E32 -> —— | F15: =价格汇总!F32 -> 9 | G15: =价格汇总!G32 -> 1720 | H15: =价格汇总!H32 -> —— | I15: =价格汇总!I32 -> —— | J15: =价格汇总!J32 -> 8.6 | K15: 13-16天 | L15: 无时效理赔
B16: 单票51KG以上,重货减免优惠：1:200减0.5,1:250减1.5,1:300减2,1:350减2.5,1:450减3,1:500及以上减3.5.
B17: 理赔注意事项
B18: 1>以上按方/按公斤含税价格含海关查验及查验引起的其它费用.包税价格含查验费,除查验费外的其他费用，例如亚马逊爆仓引起的仓租/柜租，非我司原因导致的亚马逊拒收产生的相关费用，申报不符海关惩罚金,扣关,退运等包税价格都是不包含的，请客户将这些官方收费也考虑到成本中，以免引起误会； 2>按方含税价格包含海关查验费，如因报关资料问题引起的出口查验由客人承担所有相关费用（如仓租，柜租，改船费等),因为国外清关资质认证问题或者产品本身问题导致的查验费及额外费用由这票货来承担； 3>不可抗力因素造成的时效延误不在赔偿范围内，如：海关查验，如自然灾害、如台风、地震、洪水、冰雹,，暴风雪；政府行为，社会异常事件，如罢工、骚乱三方面，疫情原因导致仓库预约困难或延识误等。 4>拒收一切敏感货，冲货如被海关扣货罚没销毁等，不退运费，我司也不承担任何责任.品名必需如实申报,如遇查验,申报与实际品名不一致将会产生巨额关税,客户自负.
B22: 服务小贴士
B23: 1>为了更好的服务客户和统计仓位，来货请务必贴上我司的进仓标签. 2>空仓费产生情况：过了截单时间做的行为；更改渠道、客户原因延船期等；货物在截货时间前未到我司国内仓库.
B25: 其它费用
B26: 按方渠道的计费重是按实际立方数和实重/363取大值计算的,卡派单箱无最低计费重量限制，托盘货物不按方算. 最长边超过120CM小于165CM加收RMB1/KG(按方含税+200/CBM),单边超过165CM拒收； 报关费按200RMB/票。 托盘、木架、木箱类货物泡货计费重*1.1*1.1算计费重； 实重托盘比重达到1:200的比重系数*0.75算比重系数，计费重不*1.1。 自提出库费按“单板限2方/1200磅”取较大值计费，超出部分按第二板计算；超大件自提费用请单独咨询客服。

Sheet 美森MAX卡派
B1: SSH美森MAX卡派 渠道代码：SSH02 （进福建内陆费+0.4/KG）
B3: 下单渠道：SSH02卡派/SSHJF02卡派 SSH02卡派-按方计费/SSHJF02-按方计费
B4: 人民币报价 | K4: 执行日期：2026-3-31
B5: 仓库代码 | C5: 深圳/广州交货价 | G5: 义乌交货价 | K5: 入仓参考时效 （开船后次日起算） | L5: 理赔时效 (自然日) | M5: 返回主页
C6: 按方含税(2CBM+) | D6: 包税(12KG+) | E6: 包税(51KG+) | F6: 包税(100KG+) | G6: 按方含税(2CBM+) | H6: 包税(12KG+) | I6: 包税(51KG+) | J6: 包税(100KG+)
B7: ONT8/LGB8/LAX9/SBD1 IUSP/IUSQ/IUSJ/POC1 POC2/POC3 | C7: =价格汇总!C36 -> 1740 | D7: =价格汇总!D36 -> 9.7 | E7: =价格汇总!E36 -> 8.7 | F7: =价格汇总!F36 -> 8.7 | G7: =价格汇总!G36 -> 1660 | H7: =价格汇总!H36 -> 9.3 | I7: =价格汇总!I36 -> 8.3 | J7: =价格汇总!J36 -> 8.3 | K7: 13-16天 | L7: 17天 (开船第二天开始,承诺17天内入仓(送仓当日不算赔付时效),第18天开始, 退0.5元/KG/每天,最多退2元/KG)
B8: SNA4/SBD2/LGB4/LGB6 XLX7/IUTI/IUSW/PSP3 | C8: =价格汇总!C37 -> 1780 | D8: =价格汇总!D37 -> 9.9 | E8: =价格汇总!E37 -> 8.9 | F8: =价格汇总!F37 -> 8.9 | G8: =价格汇总!G37 -> 1700 | H8: =价格汇总!H37 -> 9.5 | I8: =价格汇总!I37 -> 8.5 | J8: =价格汇总!J37 -> 8.5 | K8: 14-17天 | L8: 无时效理赔
B9: SMF3/SCK4/LAS1/GYR2 GYR3/MIT2/VGT2/GEU2 GEU3/GEU5/HLI2/TCY2 TCY1/SCK8/SMF6/OAK3 MCE1/LAS6/SJC7/FAT2 PHX5/PHX7/IUTE | C9: =价格汇总!C38 -> 1840 | D9: =价格汇总!D38 -> 10.2 | E9: =价格汇总!E38 -> 9.2 | F9: =价格汇总!F38 -> 9.2 | G9: =价格汇总!G38 -> 1760 | H9: =价格汇总!H38 -> 9.8 | I9: =价格汇总!I38 -> 8.8 | J9: =价格汇总!J38 -> 8.8 | K9: 14-17天 | L9: 18天 (开船第二天开始,承诺18天内入仓(送仓当日不算赔付时效),第19天开始, 退0.5元/KG/每天,最多退2元/KG)
B10: ABQ2/QXY8/MCC1 | C10: =价格汇总!C39 -> 2000 | D10: =价格汇总!D39 -> 11 | E10: =价格汇总!E39 -> 10 | F10: =价格汇总!F39 -> 10 | G10: =价格汇总!G39 -> 1920 | H10: =价格汇总!H39 -> 10.6 | I10: =价格汇总!I39 -> 9.6 | J10: =价格汇总!J39 -> 9.6 | K10: 15-18天 | L10: 无时效理赔
B11: FTW1/IUSF/DFW6/IAH3 SAT1/FTW5/STL3/PSC2 PDX7 (标红仓点按12KG起收) 单价按100KG段+1/KG 51KG-100KG按100KG+同价 | C11: =价格汇总!C40 -> 2100 | D11: =价格汇总!D40 -> 100KG起收 | E11: =价格汇总!E40 -> 100KG起收 | F11: =价格汇总!F40 -> 10.5 | G11: =价格汇总!G40 -> 2020 | H11: =价格汇总!H40 -> 100KG起收 | I11: =价格汇总!I40 -> 100KG起收 | J11: =价格汇总!J40 -> 10.1 | K11: 15-18天 | L11: 无时效理赔
B12: IND9/MDW2/FWA4/MEM1 MQJ1/DEN8/RFD2/ORD2 LFT1 (标红仓点按12KG起收) 单价按100KG段+1/KG 51KG-100KG按100KG+同价 | C12: =价格汇总!C41 -> 2140 | D12: =价格汇总!D41 -> 100KG起收 | E12: =价格汇总!E41 -> 100KG起收 | F12: =价格汇总!F41 -> 10.7 | G12: =价格汇总!G41 -> 2060 | H12: =价格汇总!H41 -> 100KG起收 | I12: =价格汇总!I41 -> 100KG起收 | J12: =价格汇总!J41 -> 10.3 | K12: 19-25天 | L12: 无时效理赔
B13: CLT2/RDU2/CLT3/RDU4 (标红仓点按12KG起收) 单价按100KG段+1/KG 51KG-100KG按100KG+同价 | C13: =价格汇总!C42 -> 2320 | D13: =价格汇总!D42 -> 100KG起收 | E13: =价格汇总!E42 -> 100KG起收 | F13: =价格汇总!F42 -> 11.6 | G13: =价格汇总!G42 -> 2240 | H13: =价格汇总!H42 -> 100KG起收 | I13: =价格汇总!I42 -> 100KG起收 | J13: =价格汇总!J42 -> 11.2 | K13: 19-25天 | L13: 无时效理赔
B14: ABE8/AVP1/TEB3/TEB9 TPA3 /RMN3/ORF2/SWF2 (标红仓点按12KG起收) 单价按100KG段+1/KG 51KG-100KG按100KG+同价 | C14: =价格汇总!C43 -> 2400 | D14: =价格汇总!D43 -> 100KG起收 | E14: =价格汇总!E43 -> 100KG起收 | F14: =价格汇总!F43 -> 12 | G14: =价格汇总!G43 -> 2320 | H14: =价格汇总!H43 -> 100KG起收 | I14: =价格汇总!I43 -> 100KG起收 | J14: =价格汇总!J43 -> 11.6 | K14: 19-25天 | L14: 无时效理赔
B15: 含税自提(出库费15美金/托 汇率7） | C15: =价格汇总!C44 -> 1740 | D15: =价格汇总!D44 -> —— | E15: =价格汇总!E44 -> —— | F15: =价格汇总!F44 -> 8.7 | G15: =价格汇总!G44 -> 1660 | H15: =价格汇总!H44 -> —— | I15: =价格汇总!I44 -> —— | J15: =价格汇总!J44 -> 8.3 | K15: 13-15天 | L15: 无时效理赔
B16: 单票51KG以上,重货减免优惠：1:200减0.5,1:250减1.5,1:300减2,1:350减2.5,1:450减3,1:500及以上减3.5.
B17: 理赔注意事项
B18: 1>以上按方/按公斤含税价格含海关查验及查验引起的其它费用.包税价格含查验费,除查验费外的其他费用，例如亚马逊爆仓引起的仓租/柜租，非我司原因导致的亚马逊拒收产生的相关费用，申报不符海关惩罚金,扣关,退运等包税价格都是不包含的，请客户将这些官方收费也考虑到成本中，以免引起误会； 2>按方含税价格包含海关查验费，如因报关资料问题引起的出口查验由客人承担所有相关费用（如仓租，柜租，改船费等),因为国外清关资质认证问题或者产品本身问题导致的查验费及额外费用由这票货来承担； 3>不可抗力因素造成的时效延误不在赔偿范围内，如：海关查验，如自然灾害、如台风、地震、洪水、冰雹,，暴风雪；政府行为，社会异常事件，如罢工、骚乱三方面，疫情原因导致仓库预约困难或延识误等。 4>拒收一切敏感货，冲货如被海关扣货罚没销毁等，不退运费，我司也不承担任何责任.品名必需如实申报,如遇查验,申报与实际品名不一致将会产生巨额关税,客户自负.
B22: 服务小贴士
B23: 1>为了更好的服务客户和统计仓位，来货请务必贴上我司的进仓标签.
B24: 2>空仓费产生情况：过了截单时间做的行为；更改渠道、客户原因延船期等；货物在截货时间前未到我司国内仓库.
B25: 其它费用
B26: 按方渠道的计费重是按实际立方数和实重/363取大值计算的,卡派单箱无最低计费重量限制，托盘货物不按方算. 最长边超过120CM小于165CM加收RMB1/KG(按方含税+200/CBM),单边超过165CM拒收； 报关费按200RMB/票。 托盘、木架、木箱类货物泡货计费重*1.1*1.1算计费重； 实重托盘比重达到1:200的比重系数*0.75算比重系数，计费重不*1.1。 自提出库费按“单板限2方/1200磅”取较大值计费，超出部分按第二板计算；超大件自提费用请单独咨询客服。

Sheet EXX卡派
B1: SSH快船EXX卡派 渠道代码：SSH03 （进福建内陆费+0.4/KG）
B3: 下单渠道：SSH03卡派/SSHJF03卡派 SSH03卡派-按方计费/SSHJF03-按方计费
B4: 人民币报价 | K4: 执行日期：2026-3-31
B5: 仓库代码 | C5: 深圳/广州交货价 | G5: 义乌交货价 | K5: 入仓参考时效 （开船后次日起算） | L5: 理赔时效 (自然日) | M5: 返回主页
C6: 按方含税(2CBM+) | D6: 包税(12KG+) | E6: 包税(51KG+) | F6: 包税(100KG+) | G6: 按方含税(2CBM+) | H6: 包税(12KG+) | I6: 包税(51KG+) | J6: 包税(100KG+)
B7: ONT8/LGB8/LAX9/SBD1 IUSP/IUSQ/IUSJ/POC1 POC2/POC3 | C7: =价格汇总!C48 -> 1260 | D7: =价格汇总!D48 -> 7.3 | E7: =价格汇总!E48 -> 6.3 | F7: =价格汇总!F48 -> 6.3 | G7: =价格汇总!G48 -> 1180 | H7: =价格汇总!H48 -> 6.9 | I7: =价格汇总!I48 -> 5.9 | J7: =价格汇总!J48 -> 5.9 | K7: 14-17天 | L7: 18天 (开船第二天开始,承诺18天内入仓(送仓当日不算赔付时效),第19天开始, 退0.5元/KG/每天,最多退2元/KG)
B8: SNA4/SBD2/LGB4/LGB6 XLX7/IUTI/IUSW/PSP3 | C8: =价格汇总!C49 -> 1300 | D8: =价格汇总!D49 -> 7.5 | E8: =价格汇总!E49 -> 6.5 | F8: =价格汇总!F49 -> 6.5 | G8: =价格汇总!G49 -> 1220 | H8: =价格汇总!H49 -> 7.1 | I8: =价格汇总!I49 -> 6.1 | J8: =价格汇总!J49 -> 6.1 | K8: 14-17天 | L8: 无时效理赔
B9: SMF3/SCK4/LAS1/GYR2 GYR3/MIT2/VGT2/GEU2 GEU3/GEU5/HLI2/TCY2 TCY1/SCK8/SMF6/OAK3 MCE1/LAS6/SJC7/FAT2 PHX5/PHX7/IUTE | C9: =价格汇总!C50 -> 1360 | D9: =价格汇总!D50 -> 7.8 | E9: =价格汇总!E50 -> 6.8 | F9: =价格汇总!F50 -> 6.8 | G9: =价格汇总!G50 -> 1280 | H9: =价格汇总!H50 -> 7.4 | I9: =价格汇总!I50 -> 6.4 | J9: =价格汇总!J50 -> 6.4 | K9: 14-17天 | L9: 19天 (开船第二天开始,承诺19天内入仓(送仓当日不算赔付时效),第20天开始, 退0.5元/KG/每天,最多退2元/KG)
B10: ABQ2/QXY8/MCC1 | C10: =价格汇总!C51 -> 1520 | D10: =价格汇总!D51 -> 8.6 | E10: =价格汇总!E51 -> 7.6 | F10: =价格汇总!F51 -> 7.6 | G10: =价格汇总!G51 -> 1440 | H10: =价格汇总!H51 -> 8.2 | I10: =价格汇总!I51 -> 7.2 | J10: =价格汇总!J51 -> 7.2 | K10: 15-18天 | L10: 无时效理赔
B11: FTW1/IUSF/DFW6/IAH3 SAT1/FTW5/STL3/PSC2 PDX7 (标红仓点按12KG起收) 单价按100KG段+1/KG 51KG-100KG按100KG+同价 | C11: =价格汇总!C52 -> 1620 | D11: =价格汇总!D52 -> 100KG起收 | E11: =价格汇总!E52 -> 100KG起收 | F11: =价格汇总!F52 -> 8.1 | G11: =价格汇总!G52 -> 1540 | H11: =价格汇总!H52 -> 100KG起收 | I11: =价格汇总!I52 -> 100KG起收 | J11: =价格汇总!J52 -> 7.7 | K11: 15-18天 | L11: 无时效理赔
B12: IND9/MDW2/FWA4/MEM1 MQJ1/DEN8/RFD2/ORD2 LFT1 (标红仓点按12KG起收) 单价按100KG段+1/KG 51KG-100KG按100KG+同价 | C12: =价格汇总!C53 -> 1660 | D12: =价格汇总!D53 -> 100KG起收 | E12: =价格汇总!E53 -> 100KG起收 | F12: =价格汇总!F53 -> 8.3 | G12: =价格汇总!G53 -> 1580 | H12: =价格汇总!H53 -> 100KG起收 | I12: =价格汇总!I53 -> 100KG起收 | J12: =价格汇总!J53 -> 7.9 | K12: 19-25天 | L12: 无时效理赔
B13: CLT2/RDU2/CLT3/RDU4 (标红仓点按12KG起收) 单价按100KG段+1/KG 51KG-100KG按100KG+同价 | C13: =价格汇总!C54 -> 1840 | D13: =价格汇总!D54 -> 100KG起收 | E13: =价格汇总!E54 -> 100KG起收 | F13: =价格汇总!F54 -> 9.2 | G13: =价格汇总!G54 -> 1760 | H13: =价格汇总!H54 -> 100KG起收 | I13: =价格汇总!I54 -> 100KG起收 | J13: =价格汇总!J54 -> 8.8 | K13: 19-25天 | L13: 无时效理赔
B14: ABE8/AVP1/TEB3/TEB9 TPA3 /RMN3/ORF2/SWF2 (标红仓点按12KG起收) 单价按100KG段+1/KG 51KG-100KG按100KG+同价 | C14: =价格汇总!C55 -> 1920 | D14: =价格汇总!D55 -> 100KG起收 | E14: =价格汇总!E55 -> 100KG起收 | F14: =价格汇总!F55 -> 9.6 | G14: =价格汇总!G55 -> 1840 | H14: =价格汇总!H55 -> 100KG起收 | I14: =价格汇总!I55 -> 100KG起收 | J14: =价格汇总!J55 -> 9.2 | K14: 19-25天 | L14: 无时效理赔
B15: 含税自提(出库费15美金/托 汇率7） | C15: =价格汇总!C56 -> 1260 | D15: =价格汇总!D56 -> —— | E15: =价格汇总!E56 -> —— | F15: =价格汇总!F56 -> 6.3 | G15: =价格汇总!G56 -> 1180 | H15: =价格汇总!H56 -> —— | I15: =价格汇总!I56 -> —— | J15: =价格汇总!J56 -> 5.9 | K15: 13-16天 | L15: 无时效理赔
B16: 单票51KG以上,重货减免优惠：1:200减0.5,1:250减1.5,1:300减2,1:350减2.5,1:450减3,1:500及以上减3.5.
B17: 理赔注意事项
B18: 1>以上按方/按公斤含税价格含海关查验及查验引起的其它费用.包税价格含查验费,除查验费外的其他费用，例如亚马逊爆仓引起的仓租/柜租，非我司原因导致的亚马逊拒收产生的相关费用，申报不符海关惩罚金,扣关,退运等包税价格都是不包含的，请客户将这些官方收费也考虑到成本中，以免引起误会； 2>按方含税价格包含海关查验费，如因报关资料问题引起的出口查验由客人承担所有相关费用（如仓租，柜租，改船费等),因为国外清关资质认证问题或者产品本身问题导致的查验费及额外费用由这票货来承担； 3>不可抗力因素造成的时效延误不在赔偿范围内，如：海关查验，如自然灾害、如台风、地震、洪水、冰雹,，暴风雪；政府行为，社会异常事件，如罢工、骚乱三方面，疫情原因导致仓库预约困难或延识误等。 4>拒收一切敏感货，冲货如被海关扣货罚没销毁等，不退运费，我司也不承担任何责任.品名必需如实申报,如遇查验,申报与实际品名不一致将会产生巨额关税,客户自负.
B22: 服务小贴士
B23: 1>为了更好的服务客户和统计仓位，来货请务必贴上我司的进仓标签.
B24: 2>空仓费产生情况：过了截单时间做的行为；更改渠道、客户原因延船期等；货物在截货时间前未到我司国内仓库.
B25: 其它费用
B26: 按方渠道的计费重是按实际立方数和实重/363取大值计算的,卡派单箱无最低计费重量限制，托盘货物不按方算. 最长边超过120CM小于165CM加收RMB1/KG(按方含税+200/CBM),单边超过165CM拒收； 报关费按200RMB/票。 托盘、木架、木箱类货物泡货计费重*1.1*1.1算计费重； 实重托盘比重达到1:200的比重系数*0.75算比重系数，计费重不*1.1。 自提出库费按“单板限2方/1200磅”取较大值计费，超出部分按第二板计算；超大件自提费用请单独咨询客服。

Sheet 盐田以星南沙合德限时达卡派
B1: SSH盐田以星南沙合德限时达卡派
B3: 下单渠道：SSH04卡派/SSH04卡派-按方计费
B4: 人民币报价 | K4: 执行日期：2026-3-31
B5: 仓库代码 | C5: 深圳交货价 | G5: 广州交货价 | K5: 入仓参考时效 （开船后次日起算） | L5: 理赔时效 (自然日) | M5: 返回主页
C6: 按方含税(2CBM+) | D6: 包税(12KG+) | E6: 包税(51KG+) | F6: 包税(100KG+) | G6: 按方含税(2CBM+) | H6: 包税(12KG+) | I6: 包税(51KG+) | J6: 包税(100KG+)
B7: ONT8/LGB8/LAX9/SBD1 IUSP/IUSQ/IUSJ/POC1 POC2/POC3 | C7: =价格汇总!C60 -> 1060 | D7: =价格汇总!D60 -> 6.3 | E7: =价格汇总!E60 -> 5.3 | F7: =价格汇总!F60 -> 5.3 | G7: =价格汇总!G60 -> 1060 | H7: =价格汇总!H60 -> 6.3 | I7: =价格汇总!I60 -> 5.3 | J7: =价格汇总!J60 -> 5.3 | K7: 18-20天 | L7: 18天 (开船第二天开始,承诺18天内入仓(送仓当日不算赔付时效),第19天开始, 退0.5元/KG/每天,最多退2元/KG)
B8: SNA4/SBD2/LGB4/LGB6 XLX7/IUTI/IUSW/PSP3 | C8: =价格汇总!C61 -> 1100 | D8: =价格汇总!D61 -> 6.5 | E8: =价格汇总!E61 -> 5.5 | F8: =价格汇总!F61 -> 5.5 | G8: =价格汇总!G61 -> 1100 | H8: =价格汇总!H61 -> 6.5 | I8: =价格汇总!I61 -> 5.5 | J8: =价格汇总!J61 -> 5.5 | K8: 18-20天 | L8: 无时效理赔
B9: SMF3/SCK4/LAS1/GYR2 GYR3/MIT2/VGT2/GEU2 GEU3/GEU5/HLI2/TCY2 TCY1/SCK8/SMF6/OAK3 MCE1/LAS6/SJC7/FAT2 PHX5/PHX7/IUTE | C9: =价格汇总!C62 -> 1160 | D9: =价格汇总!D62 -> 6.8 | E9: =价格汇总!E62 -> 5.8 | F9: =价格汇总!F62 -> 5.8 | G9: =价格汇总!G62 -> 1160 | H9: =价格汇总!H62 -> 6.8 | I9: =价格汇总!I62 -> 5.8 | J9: =价格汇总!J62 -> 5.8 | K9: 20-22天 | L9: 19天 (开船第二天开始,承诺19天内入仓(送仓当日不算赔付时效),第20天开始, 退0.5元/KG/每天,最多退2元/KG)
B10: ABQ2/QXY8/MCC1 | C10: =价格汇总!C63 -> 1320 | D10: =价格汇总!D63 -> 7.6 | E10: =价格汇总!E63 -> 6.6 | F10: =价格汇总!F63 -> 6.6 | G10: =价格汇总!G63 -> 1320 | H10: =价格汇总!H63 -> 7.6 | I10: =价格汇总!I63 -> 6.6 | J10: =价格汇总!J63 -> 6.6 | K10: 20-22天 | L10: 无时效理赔
B11: FTW1/IUSF/DFW6/IAH3 SAT1/FTW5/STL3/PSC2 PDX7 (标红仓点按12KG起收) 单价按100KG段+1/KG 51KG-100KG按100KG+同价 | C11: =价格汇总!C64 -> 1420 | D11: =价格汇总!D64 -> 100KG起收 | E11: =价格汇总!E64 -> 100KG起收 | F11: =价格汇总!F64 -> 7.1 | G11: =价格汇总!G64 -> 1420 | H11: =价格汇总!H64 -> 100KG起收 | I11: =价格汇总!I64 -> 100KG起收 | J11: =价格汇总!J64 -> 7.1 | K11: 20-22天 | L11: 无时效理赔
B12: IND9/MDW2/FWA4/MEM1 MQJ1/DEN8/RFD2/ORD2 LFT1 (标红仓点按12KG起收) 单价按100KG段+1/KG 51KG-100KG按100KG+同价 | C12: =价格汇总!C65 -> 1460 | D12: =价格汇总!D65 -> 100KG起收 | E12: =价格汇总!E65 -> 100KG起收 | F12: =价格汇总!F65 -> 7.3 | G12: =价格汇总!G65 -> 1460 | H12: =价格汇总!H65 -> 100KG起收 | I12: =价格汇总!I65 -> 100KG起收 | J12: =价格汇总!J65 -> 7.3 | K12: 20-22天 | L12: 无时效理赔
B13: CLT2/RDU2/CLT3/RDU4 (标红仓点按12KG起收) 单价按100KG段+1/KG 51KG-100KG按100KG+同价 | C13: =价格汇总!C66 -> 1640 | D13: =价格汇总!D66 -> 100KG起收 | E13: =价格汇总!E66 -> 100KG起收 | F13: =价格汇总!F66 -> 8.2 | G13: =价格汇总!G66 -> 1640 | H13: =价格汇总!H66 -> 100KG起收 | I13: =价格汇总!I66 -> 100KG起收 | J13: =价格汇总!J66 -> 8.2 | K13: 20-22天 | L13: 无时效理赔
B14: ABE8/AVP1/TEB3/TEB9 TPA3 /RMN3/ORF2/SWF2 (标红仓点按12KG起收) 单价按100KG段+1/KG 51KG-100KG按100KG+同价 | C14: =价格汇总!C67 -> 1720 | D14: =价格汇总!D67 -> 100KG起收 | E14: =价格汇总!E67 -> 100KG起收 | F14: =价格汇总!F67 -> 8.6 | G14: =价格汇总!G67 -> 1720 | H14: =价格汇总!H67 -> 100KG起收 | I14: =价格汇总!I67 -> 100KG起收 | J14: =价格汇总!J67 -> 8.6 | K14: 20-22天 | L14: 无时效理赔
B15: 含税自提(出库费15美金/托 汇率7） | C15: =价格汇总!C68 -> 1060 | D15: =价格汇总!D68 -> —— | E15: =价格汇总!E68 -> —— | F15: =价格汇总!F68 -> 5.3 | G15: =价格汇总!G68 -> 1060 | H15: =价格汇总!H68 -> —— | I15: =价格汇总!I68 -> —— | J15: =价格汇总!J68 -> 5.3 | K15: 16-20天 | L15: 无时效理赔
B16: 单票51KG以上,重货减免优惠：1:200减0.5,1:250减1.5,1:300减2,1:350减2.5,1:450减3,1:500及以上减3.5.
B17: 理赔注意事项
B18: 1>以上按方/按公斤含税价格含海关查验及查验引起的其它费用.包税价格含查验费,除查验费外的其他费用，例如亚马逊爆仓引起的仓租/柜租，非我司原因导致的亚马逊拒收产生的相关费用，申报不符海关惩罚金,扣关,退运等包税价格都是不包含的，请客户将这些官方收费也考虑到成本中，以免引起误会； 2>按方含税价格包含海关查验费，如因报关资料问题引起的出口查验由客人承担所有相关费用（如仓租，柜租，改船费等),因为国外清关资质认证问题或者产品本身问题导致的查验费及额外费用由这票货来承担； 3>不可抗力因素造成的时效延误不在赔偿范围内，如：海关查验，如自然灾害、如台风、地震、洪水、冰雹,，暴风雪；政府行为，社会异常事件，如罢工、骚乱三方面，疫情原因导致仓库预约困难或延识误等。 4>拒收一切敏感货，冲货如被海关扣货罚没销毁等，不退运费，我司也不承担任何责任.品名必需如实申报,如遇查验,申报与实际品名不一致将会产生巨额关税,客户自负.
B22: 服务小贴士
B23: 1>为了更好的服务客户和统计仓位，来货请务必贴上我司的进仓标签.
B24: 2>空仓费产生情况：过了截单时间做的行为；更改渠道、客户原因延船期等；货物在截货时间前未到我司国内仓库.
B25: 其它费用
B26: 按方渠道的计费重是按实际立方数和实重/363取大值计算的,卡派单箱无最低计费重量限制，托盘货物不按方算. 最长边超过120CM小于165CM加收RMB1/KG(按方含税+200/CBM),单边超过165CM拒收； 报关费按200RMB/票。 托盘、木架、木箱类货物泡货计费重*1.1*1.1算计费重； 实重托盘比重达到1:200的比重系数*0.75算比重系数，计费重不*1.1。 自提出库费按“单板限2方/1200磅”取较大值计费，超出部分按第二板计算；超大件自提费用请单独咨询客服。

Sheet 盐田以星南沙合德DG限时达卡派
B1: SSH盐田以星南沙合德DG限时达卡派
B3: 下单渠道：SSHDG04卡派
B4: 人民币报价 | I4: 执行日期：2026-3-31
B5: 仓库代码 | C5: 深圳交货价 | F5: 广州交货价 | I5: 入仓参考时效 （开船后次日起算） | J5: 理赔时效 (自然日) | K5: 返回主页
C6: 包税(12KG+) | D6: 包税(51KG+) | E6: 包税(100KG+) | F6: 包税(12KG+) | G6: 包税(51KG+) | H6: 包税(100KG+)
B7: ONT8/LGB8/LAX9/SBD1 IUSP/IUSQ/IUSJ/POC1 POC2/POC3 | C7: =价格汇总!D73 -> 7.6 | D7: =价格汇总!E73 -> 6.6 | E7: =价格汇总!F73 -> 6.6 | F7: =价格汇总!H73 -> 7.6 | G7: =价格汇总!I73 -> 6.6 | H7: =价格汇总!J73 -> 6.6 | I7: 18-20天 | J7: 18天 (开船第二天开始,承诺18天内入仓(送仓当日不算赔付时效),第19天开始, 退0.5元/KG/每天,最多退2元/KG)
B8: SNA4/SBD2/LGB4/LGB6 XLX7/IUTI/IUSW/PSP3 | C8: =价格汇总!D74 -> 7.8 | D8: =价格汇总!E74 -> 6.8 | E8: =价格汇总!F74 -> 6.8 | F8: =价格汇总!H74 -> 7.8 | G8: =价格汇总!I74 -> 6.8 | H8: =价格汇总!J74 -> 6.8 | I8: 18-20天 | J8: 无时效理赔
B9: SMF3/SCK4/LAS1/GYR2 GYR3/MIT2/VGT2/GEU2 GEU3/GEU5/HLI2/TCY2 TCY1/SCK8/SMF6/OAK3 MCE1/LAS6/SJC7/FAT2 PHX5/PHX7/IUTE | C9: =价格汇总!D75 -> 8.1 | D9: =价格汇总!E75 -> 7.1 | E9: =价格汇总!F75 -> 7.1 | F9: =价格汇总!H75 -> 8.1 | G9: =价格汇总!I75 -> 7.1 | H9: =价格汇总!J75 -> 7.1 | I9: 20-22天 | J9: 19天 (开船第二天开始,承诺19天内入仓(送仓当日不算赔付时效),第20天开始, 退0.5元/KG/每天,最多退2元/KG)
B10: ABQ2/QXY8/MCC1 | C10: =价格汇总!D76 -> 8.9 | D10: =价格汇总!E76 -> 7.9 | E10: =价格汇总!F76 -> 7.9 | F10: =价格汇总!H76 -> 8.9 | G10: =价格汇总!I76 -> 7.9 | H10: =价格汇总!J76 -> 7.9 | I10: 20-22天 | J10: 无时效理赔
B11: FTW1/IUSF/DFW6/IAH3 SAT1/FTW5/STL3/PSC2 PDX7 (标红仓点按12KG起收) 单价按100KG段+1/KG 51KG-100KG按100KG+同价 | C11: =价格汇总!D77 -> 100KG起收 | D11: =价格汇总!E77 -> 100KG起收 | E11: =价格汇总!F77 -> 8.4 | F11: =价格汇总!H77 -> 100KG起收 | G11: =价格汇总!I77 -> 100KG起收 | H11: =价格汇总!J77 -> 8.4 | I11: 20-22天 | J11: 无时效理赔
B12: IND9/MDW2/FWA4/MEM1 MQJ1/DEN8/RFD2/ORD2 LFT1 (标红仓点按12KG起收) 单价按100KG段+1/KG 51KG-100KG按100KG+同价 | C12: =价格汇总!D78 -> 100KG起收 | D12: =价格汇总!E78 -> 100KG起收 | E12: =价格汇总!F78 -> 8.6 | F12: =价格汇总!H78 -> 100KG起收 | G12: =价格汇总!I78 -> 100KG起收 | H12: =价格汇总!J78 -> 8.6 | I12: 20-22天 | J12: 无时效理赔
B13: CLT2/RDU2/CLT3/RDU4 (标红仓点按12KG起收) 单价按100KG段+1/KG 51KG-100KG按100KG+同价 | C13: =价格汇总!D79 -> 100KG起收 | D13: =价格汇总!E79 -> 100KG起收 | E13: =价格汇总!F79 -> 9.5 | F13: =价格汇总!H79 -> 100KG起收 | G13: =价格汇总!I79 -> 100KG起收 | H13: =价格汇总!J79 -> 9.5 | I13: 20-22天 | J13: 无时效理赔
B14: ABE8/AVP1/TEB3/TEB9 TPA3 /RMN3/ORF2/SWF2 (标红仓点按12KG起收) 单价按100KG段+1/KG 51KG-100KG按100KG+同价 | C14: =价格汇总!D80 -> 100KG起收 | D14: =价格汇总!E80 -> 100KG起收 | E14: =价格汇总!F80 -> 9.9 | F14: =价格汇总!H80 -> 100KG起收 | G14: =价格汇总!I80 -> 100KG起收 | H14: =价格汇总!J80 -> 9.9 | I14: 20-22天 | J14: 无时效理赔
B15: 含税自提(出库费15美金/托 汇率7） | C15: =价格汇总!D81 -> —— | D15: =价格汇总!E81 -> —— | E15: =价格汇总!F81 -> 6.6 | F15: =价格汇总!H81 -> —— | G15: =价格汇总!I81 -> —— | H15: =价格汇总!J81 -> 6.6 | I15: 16-20天 | J15: 无时效理赔
B16: 发货与责任条款 为保障运输顺利，请贵司务必遵守以下条款，使用我司服务即视为完全同意本规定。
B17: 一、发货须知 出货前，须与我司客服确认货物可运性与清关要求。发货人必须提供准确、完整的报关及产品认证文件（如MSDS、UN38.3、危包证等）。如因私自发货、资料不全或错误、货物不合规（含侵权、反倾销产品）导致的一切风险、退货费用及责任，概由贵司承担。
B18: 二、包装要求 所有货物外箱及产品上须有永久性“MADE IN CHINA”标识。纯电池/危险品货物须按我司要求使用合规包装，并牢固张贴对应危险品标签（如9类标签、UN标签）及运输标签（如FBA标签）。因包装或标识不合规导致的清关或派送问题，由贵司负责。
B19: 三、货物交付要求说明 对于派送货物，收货人签收POD单即视为妥投，异常须在签收时注明或于三日内反馈。亚马逊仓库货物，入仓后一个月内未反馈上架异常则视为正常签收。我司将以POD签收记录作为货物交付完成的最终凭证。
B20: 四、赔偿及索赔说明 如未购买保险，货物丢失、损毁赔偿上限为40元人民币/公斤（扣关/提取前），且不退运费。对于运输延误、海关查验、已签收未上架、包装完好内物破损等情况，我司不承担赔偿责任。任何索赔须在货物实际派送日起30天内提出，逾期无效。因贵司申报不符、资料问题或货物自身原因导致的任何损失，我司不承担赔偿责任。
B21: 服务小贴士
B22: 1>为了更好的服务客户和统计仓位，来货请务必贴上我司的进仓标签.
B23: 2>空仓费产生情况：过了截单时间做的行为；更改渠道、客户原因延船期等；货物在截货时间前未到我司国内仓库.
B24: 其它费用
B25: 按方渠道的计费重是按实际立方数和实重/363取大值计算的,卡派单箱无最低计费重量限制，托盘货物不按方算. 最长边超过120CM小于165CM加收RMB1/KG(按方含税+200/CBM),单边超过165CM拒收； 报关费按200RMB/票。 托盘、木架、木箱类货物泡货计费重*1.1*1.1算计费重； 实重托盘比重达到1:200的比重系数*0.75算比重系数，计费重不*1.1。 自提出库费按“单板限2方/1200磅”取较大值计费，超出部分按第二板计算；超大件自提费用请单独咨询客服。

Sheet 义乌合德以星限时达卡派
B1: SSH义乌合德以星限时达卡派 （进福建内陆费+0.4/KG）
B3: 下单渠道：SSHYW05卡派/SSHYW05卡派-按方计费 SSHYWJF05卡派/SSHYWJF05卡派-按方计费
B4: 人民币报价 | K4: 执行日期：2026-3-31
B5: 仓库代码 | C5: 深圳/广州交货价 | G5: 义乌交货价 | K5: 入仓参考时效 （开船后次日起算） | L5: 理赔时效 (自然日) | M5: 返回主页
C6: 按方含税(2CBM+) | D6: 包税(12KG+) | E6: 包税(51KG+) | F6: 包税(100KG+) | G6: 按方含税(2CBM+) | H6: 包税(12KG+) | I6: 包税(51KG+) | J6: 包税(100KG+)
B7: ONT8/LGB8/LAX9/SBD1 IUSP/IUSQ/IUSJ/POC1 POC2/POC3 | C7: =价格汇总!C86 -> 1120 | D7: =价格汇总!D86 -> 6.6 | E7: =价格汇总!E86 -> 5.6 | F7: =价格汇总!F86 -> 5.6 | G7: =价格汇总!G86 -> 1060 | H7: =价格汇总!H86 -> 6.3 | I7: =价格汇总!I86 -> 5.3 | J7: =价格汇总!J86 -> 5.3 | K7: 18-20天 | L7: 18天 (开船第二天开始,承诺18天内入仓(送仓当日不算赔付时效),第19天开始, 退0.5元/KG/每天,最多退2元/KG)
B8: SNA4/SBD2/LGB4/LGB6 XLX7/IUTI/IUSW/PSP3 | C8: =价格汇总!C87 -> 1160 | D8: =价格汇总!D87 -> 6.8 | E8: =价格汇总!E87 -> 5.8 | F8: =价格汇总!F87 -> 5.8 | G8: =价格汇总!G87 -> 1100 | H8: =价格汇总!H87 -> 6.5 | I8: =价格汇总!I87 -> 5.5 | J8: =价格汇总!J87 -> 5.5 | K8: 18-20天 | L8: 无时效理赔
B9: SMF3/SCK4/LAS1/GYR2 GYR3/MIT2/VGT2/GEU2 GEU3/GEU5/HLI2/TCY2 TCY1/SCK8/SMF6/OAK3 MCE1/LAS6/SJC7/FAT2 PHX5/PHX7/IUTE | C9: =价格汇总!C88 -> 1220 | D9: =价格汇总!D88 -> 7.1 | E9: =价格汇总!E88 -> 6.1 | F9: =价格汇总!F88 -> 6.1 | G9: =价格汇总!G88 -> 1160 | H9: =价格汇总!H88 -> 6.8 | I9: =价格汇总!I88 -> 5.8 | J9: =价格汇总!J88 -> 5.8 | K9: 20-22天 | L9: 19天 (开船第二天开始,承诺19天内入仓(送仓当日不算赔付时效),第20天开始, 退0.5元/KG/每天,最多退2元/KG)
B10: ABQ2/QXY8/MCC1 | C10: =价格汇总!C89 -> 1380 | D10: =价格汇总!D89 -> 7.9 | E10: =价格汇总!E89 -> 6.9 | F10: =价格汇总!F89 -> 6.9 | G10: =价格汇总!G89 -> 1320 | H10: =价格汇总!H89 -> 7.6 | I10: =价格汇总!I89 -> 6.6 | J10: =价格汇总!J89 -> 6.6 | K10: 20-22天 | L10: 无时效理赔
B11: FTW1/IUSF/DFW6/IAH3 SAT1/FTW5/STL3/PSC2 PDX7 (标红仓点按12KG起收) 单价按100KG段+1/KG 51KG-100KG按100KG+同价 | C11: =价格汇总!C90 -> 1480 | D11: =价格汇总!D90 -> 100KG起收 | E11: =价格汇总!E90 -> 100KG起收 | F11: =价格汇总!F90 -> 7.4 | G11: =价格汇总!G90 -> 1420 | H11: =价格汇总!H90 -> 100KG起收 | I11: =价格汇总!I90 -> 100KG起收 | J11: =价格汇总!J90 -> 7.1 | K11: 20-22天 | L11: 无时效理赔
B12: IND9/MDW2/FWA4/MEM1 MQJ1/DEN8/RFD2/ORD2 LFT1 (标红仓点按12KG起收) 单价按100KG段+1/KG 51KG-100KG按100KG+同价 | C12: =价格汇总!C91 -> 1520 | D12: =价格汇总!D91 -> 100KG起收 | E12: =价格汇总!E91 -> 100KG起收 | F12: =价格汇总!F91 -> 7.6 | G12: =价格汇总!G91 -> 1460 | H12: =价格汇总!H91 -> 100KG起收 | I12: =价格汇总!I91 -> 100KG起收 | J12: =价格汇总!J91 -> 7.3 | K12: 20-22天 | L12: 无时效理赔
B13: CLT2/RDU2/CLT3/RDU4 (标红仓点按12KG起收) 单价按100KG段+1/KG 51KG-100KG按100KG+同价 | C13: =价格汇总!C92 -> 1700 | D13: =价格汇总!D92 -> 100KG起收 | E13: =价格汇总!E92 -> 100KG起收 | F13: =价格汇总!F92 -> 8.5 | G13: =价格汇总!G92 -> 1640 | H13: =价格汇总!H92 -> 100KG起收 | I13: =价格汇总!I92 -> 100KG起收 | J13: =价格汇总!J92 -> 8.2 | K13: 20-22天 | L13: 无时效理赔
B14: ABE8/AVP1/TEB3/TEB9 TPA3 /RMN3/ORF2/SWF2 (标红仓点按12KG起收) 单价按100KG段+1/KG 51KG-100KG按100KG+同价 | C14: =价格汇总!C93 -> 1780 | D14: =价格汇总!D93 -> 100KG起收 | E14: =价格汇总!E93 -> 100KG起收 | F14: =价格汇总!F93 -> 8.9 | G14: =价格汇总!G93 -> 1720 | H14: =价格汇总!H93 -> 100KG起收 | I14: =价格汇总!I93 -> 100KG起收 | J14: =价格汇总!J93 -> 8.6 | K14: 20-22天 | L14: 无时效理赔
B15: 含税自提(出库费15美金/托 汇率7） | C15: =价格汇总!C94 -> 1120 | D15: =价格汇总!D94 -> —— | E15: =价格汇总!E94 -> —— | F15: =价格汇总!F94 -> 5.6 | G15: =价格汇总!G94 -> 1060 | H15: =价格汇总!H94 -> —— | I15: =价格汇总!I94 -> —— | J15: =价格汇总!J94 -> 5.3 | K15: 16-20天 | L15: 无时效理赔
B16: 单票51KG以上,重货减免优惠：1:200减0.5,1:250减1.5,1:300减2,1:350减2.5,1:450减3,1:500及以上减3.5.
B17: 理赔注意事项
B18: 1>以上按方/按公斤含税价格含海关查验及查验引起的其它费用.包税价格含查验费,除查验费外的其他费用，例如亚马逊爆仓引起的仓租/柜租，非我司原因导致的亚马逊拒收产生的相关费用，申报不符海关惩罚金,扣关,退运等包税价格都是不包含的，请客户将这些官方收费也考虑到成本中，以免引起误会； 2>按方含税价格包含海关查验费，如因报关资料问题引起的出口查验由客人承担所有相关费用（如仓租，柜租，改船费等),因为国外清关资质认证问题或者产品本身问题导致的查验费及额外费用由这票货来承担； 3>不可抗力因素造成的时效延误不在赔偿范围内，如：海关查验，如自然灾害、如台风、地震、洪水、冰雹,，暴风雪；政府行为，社会异常事件，如罢工、骚乱三方面，疫情原因导致仓库预约困难或延识误等。 4>拒收一切敏感货，冲货如被海关扣货罚没销毁等，不退运费，我司也不承担任何责任.品名必需如实申报,如遇查验,申报与实际品名不一致将会产生巨额关税,客户自负.
B22: 服务小贴士
B23: 1>为了更好的服务客户和统计仓位，来货请务必贴上我司的进仓标签.
B24: 2>空仓费产生情况：过了截单时间做的行为；更改渠道、客户原因延船期等；货物在截货时间前未到我司国内仓库.
B25: 其它费用
B26: 按方渠道的计费重是按实际立方数和实重/363取大值计算的,卡派单箱无最低计费重量限制，托盘货物不按方算. 最长边超过120CM小于165CM加收RMB1/KG(按方含税+200/CBM),单边超过165CM拒收； 报关费按200RMB/票。 托盘、木架、木箱类货物泡货计费重*1.1*1.1算计费重； 实重托盘比重达到1:200的比重系数*0.75算比重系数，计费重不*1.1。 自提出库费按“单板限2方/1200磅”取较大值计费，超出部分按第二板计算；超大件自提费用请单独咨询客服。

Sheet 盐田以星南沙合德普提卡派
B1: SSH盐田以星南沙合德普提卡派
B3: 下单渠道：SSH06卡派/SSH06卡派-按方计费
B4: 人民币报价 | K4: 执行日期：2026-2-26
B5: 仓库代码 | C5: 深圳交货价 | G5: 广州交货价 | K5: 入仓参考时效 （开船后次日起算） | L5: 理赔时效 (自然日) | M5: 返回主页
C6: 按方含税(2CBM+) | D6: 包税(12KG+) | E6: 包税(51KG+) | F6: 包税(100KG+) | G6: 按方含税(2CBM+) | H6: 包税(12KG+) | I6: 包税(51KG+) | J6: 包税(100KG+)
B7: ONT8/LGB8/LAX9/SBD1 IUSP/IUSQ/IUSJ/POC1 POC2/POC3 | C7: =价格汇总!#REF! -> #REF! | D7: =价格汇总!#REF! -> #REF! | E7: =价格汇总!#REF! -> #REF! | F7: =价格汇总!#REF! -> #REF! | G7: =价格汇总!#REF! -> #REF! | H7: =价格汇总!#REF! -> #REF! | I7: =价格汇总!#REF! -> #REF! | J7: =价格汇总!#REF! -> #REF! | K7: 18-20天 | L7: 无时效理赔
B8: SNA4/SBD2/LGB4/LGB6 XLX7/IUTI/IUSW/PSP3 | C8: =价格汇总!#REF! -> #REF! | D8: =价格汇总!#REF! -> #REF! | E8: =价格汇总!#REF! -> #REF! | F8: =价格汇总!#REF! -> #REF! | G8: =价格汇总!#REF! -> #REF! | H8: =价格汇总!#REF! -> #REF! | I8: =价格汇总!#REF! -> #REF! | J8: =价格汇总!#REF! -> #REF! | K8: 18-20天 | L8: 无时效理赔
B9: SMF3/SCK4/LAS1/GYR2 GYR3/MIT2/VGT2/GEU2 GEU3/GEU5/HLI2/TCY2 TCY1/SCK8/SMF6/OAK3 MCE1/LAS6/SJC7/FAT2 PHX5/PHX7/IUTE | C9: =价格汇总!#REF! -> #REF! | D9: =价格汇总!#REF! -> #REF! | E9: =价格汇总!#REF! -> #REF! | F9: =价格汇总!#REF! -> #REF! | G9: =价格汇总!#REF! -> #REF! | H9: =价格汇总!#REF! -> #REF! | I9: =价格汇总!#REF! -> #REF! | J9: =价格汇总!#REF! -> #REF! | K9: 20-22天 | L9: 无时效理赔
B10: ABQ2/QXY8/MCC1 | C10: =价格汇总!#REF! -> #REF! | D10: =价格汇总!#REF! -> #REF! | E10: =价格汇总!#REF! -> #REF! | F10: =价格汇总!#REF! -> #REF! | G10: =价格汇总!#REF! -> #REF! | H10: =价格汇总!#REF! -> #REF! | I10: =价格汇总!#REF! -> #REF! | J10: =价格汇总!#REF! -> #REF! | K10: 20-22天 | L10: 无时效理赔
B11: FTW1/IUSF/DFW6/IAH3 SAT1/FTW5/STL3/PSC2 PDX7 (标红仓点按12KG起收) 单价按100KG段+1/KG 51KG-100KG按100KG+同价 | C11: =价格汇总!#REF! -> #REF! | D11: =价格汇总!#REF! -> #REF! | E11: =价格汇总!#REF! -> #REF! | F11: =价格汇总!#REF! -> #REF! | G11: =价格汇总!#REF! -> #REF! | H11: =价格汇总!#REF! -> #REF! | I11: =价格汇总!#REF! -> #REF! | J11: =价格汇总!#REF! -> #REF! | K11: 20-22天 | L11: 无时效理赔
B12: IND9/MDW2/FWA4/MEM1 MQJ1/DEN8/RFD2/ORD2 LFT1 (标红仓点按12KG起收) 单价按100KG段+1/KG 51KG-100KG按100KG+同价 | C12: =价格汇总!#REF! -> #REF! | D12: =价格汇总!#REF! -> #REF! | E12: =价格汇总!#REF! -> #REF! | F12: =价格汇总!#REF! -> #REF! | G12: =价格汇总!#REF! -> #REF! | H12: =价格汇总!#REF! -> #REF! | I12: =价格汇总!#REF! -> #REF! | J12: =价格汇总!#REF! -> #REF! | K12: 20-22天 | L12: 无时效理赔
B13: CLT2/RDU2/CLT3/RDU4 (标红仓点按12KG起收) 单价按100KG段+1/KG 51KG-100KG按100KG+同价 | C13: =价格汇总!#REF! -> #REF! | D13: =价格汇总!#REF! -> #REF! | E13: =价格汇总!#REF! -> #REF! | F13: =价格汇总!#REF! -> #REF! | G13: =价格汇总!#REF! -> #REF! | H13: =价格汇总!#REF! -> #REF! | I13: =价格汇总!#REF! -> #REF! | J13: =价格汇总!#REF! -> #REF! | K13: 20-22天 | L13: 无时效理赔
B14: ABE8/AVP1/TEB3/TEB9 TPA3 /RMN3/ORF2/SWF2 (标红仓点按12KG起收) 单价按100KG段+1/KG 51KG-100KG按100KG+同价 | C14: =价格汇总!#REF! -> #REF! | D14: =价格汇总!#REF! -> #REF! | E14: =价格汇总!#REF! -> #REF! | F14: =价格汇总!#REF! -> #REF! | G14: =价格汇总!#REF! -> #REF! | H14: =价格汇总!#REF! -> #REF! | I14: =价格汇总!#REF! -> #REF! | J14: =价格汇总!#REF! -> #REF! | K14: 20-22天 | L14: 无时效理赔
B15: 含税自提(含出库费） | C15: =价格汇总!#REF! -> #REF! | D15: =价格汇总!#REF! -> #REF! | E15: =价格汇总!#REF! -> #REF! | F15: =价格汇总!#REF! -> #REF! | G15: =价格汇总!#REF! -> #REF! | H15: =价格汇总!#REF! -> #REF! | I15: =价格汇总!#REF! -> #REF! | J15: =价格汇总!#REF! -> #REF! | K15: 16-20天 | L15: 无时效理赔
B16: 单票51KG以上,重货减免优惠：1:200减0.3,1:250减0.6,1:300减0.9,1:350减1.2,1:450及以上减1.5.
B17: 理赔注意事项
B18: 1>以上按方/按公斤含税价格含海关查验及查验引起的其它费用.包税价格含查验费,除查验费外的其他费用，例如亚马逊爆仓引起的仓租/柜租，非我司原因导致的亚马逊拒收产生的相关费用，申报不符海关惩罚金,扣关,退运等包税价格都是不包含的，请客户将这些官方收费也考虑到成本中，以免引起误会； 2>按方含税价格包含海关查验费，如因报关资料问题引起的出口查验由客人承担所有相关费用（如仓租，柜租，改船费等),因为国外清关资质认证问题或者产品本身问题导致的查验费及额外费用由这票货来承担； 3>不可抗力因素造成的时效延误不在赔偿范围内，如：海关查验，如自然灾害、如台风、地震、洪水、冰雹,，暴风雪；政府行为，社会异常事件，如罢工、骚乱三方面，疫情原因导致仓库预约困难或延识误等。 4>拒收一切敏感货，冲货如被海关扣货罚没销毁等，不退运费，我司也不承担任何责任.品名必需如实申报,如遇查验,申报与实际品名不一致将会产生巨额关税,客户自负.
B22: 服务小贴士
B23: 1>为了更好的服务客户和统计仓位，来货请务必贴上我司的进仓标签.
B24: 2>空仓费产生情况：过了截单时间做的行为；更改渠道、客户原因延船期等；货物在截货时间前未到我司国内仓库.
B25: 其它费用
B26: 按方渠道的计费重是按实际立方数和实重/363取大值计算的,卡派单箱无最低计费重量限制，托盘货物不按方算. 最长边超过120CM小于165CM加收RMB1/KG(按方含税+200/CBM),单边超过165CM拒收； 报关费按200RMB/票。 托盘、木架、木箱类货物泡货计费重*1.1*1.1算计费重； 实重托盘比重达到1:200的比重系数*0.75算比重系数，计费重不*1.1。

Sheet 普船洛杉矶卡派
A1: SSH普船洛杉矶卡派 （进福建内陆费+0.4/KG）
A3: 交货深圳下单渠道：SSH07卡派/SSH07卡派-按方计费 交货义乌下单渠道：SSHYW07卡派/SSHYW07-按方计费 SSHYWJF07卡派/SSHYWJF07卡派-按方计费（义乌普船进深圳、广州内陆费+0.3/KG）
A4: 人民币报价 | K4: 执行日期：2026-3-31
A5: 组合/混拆 | B5: 仓库代码/渠道名称 | C5: 深圳/广州交货价 | G5: 义乌交货价 | K5: 入仓参考时效 （开船后次日起算） | L5: 备注 | M5: 返回主页
C6: 按方含税(2CBM+) | D6: 包税(12KG+) | E6: 包税(51KG+) | F6: 包税(100KG+) | G6: 按方含税(2CBM+) | H6: 包税(12KG+) | I6: 包税(51KG+) | J6: 包税(100KG+)
A7: 组合一区 | B7: ONT8/LGB8/LAX9/SBD1/IUSP IUSQ/IUSJ/POC1/POC2/POC3 | C7: =价格汇总!C100 -> 740 | D7: =价格汇总!D100 -> 4.7 | E7: =价格汇总!E100 -> 3.7 | F7: =价格汇总!F100 -> 3.7 | G7: =价格汇总!G100 -> 740 | H7: =价格汇总!H100 -> 4.7 | I7: =价格汇总!I100 -> 3.7 | J7: =价格汇总!J100 -> 3.7 | K7: 20-25天 | L7: 普船ZIM/合德/OA 等统配根据到货时间顺序就近 安排船期-循环装柜 (目的港：洛杉矶) 入仓单请注明渠道： 普船洛杉矶卡派 -组合柜 （按方包税/公斤包税）
A8: 组合二区 | B8: SNA4/SBD2/LGB4/LGB6 XLX7/IUTI/IUSW/PSP3 | C8: =价格汇总!C101 -> 800 | D8: =价格汇总!D101 -> 5 | E8: =价格汇总!E101 -> 4 | F8: =价格汇总!F101 -> 4 | G8: =价格汇总!G101 -> 800 | H8: =价格汇总!H101 -> 5 | I8: =价格汇总!I101 -> 4 | J8: =价格汇总!J101 -> 4 | K8: 22-26天
A9: 组合二区Plus | B9: SMF3/SCK4/LAS1/GYR2/GYR3 MIT2/VGT2/GEU2/GEU3/GEU5 HLI2/TCY2/TCY1/SCK8/SMF6 OAK3/MCE1/LAS6/SJC7/FAT2 PHX5/PHX7/IUTE | C9: =价格汇总!C102 -> 860 | D9: =价格汇总!D102 -> 5.3 | E9: =价格汇总!E102 -> 4.3 | F9: =价格汇总!F102 -> 4.3 | G9: =价格汇总!G102 -> 860 | H9: =价格汇总!H102 -> 5.3 | I9: =价格汇总!I102 -> 4.3 | J9: =价格汇总!J102 -> 4.3 | K9: 23-27天
A10: 组合三区 | B10: ABQ2/QXY8/MCC1 | C10: =价格汇总!C103 -> 1020 | D10: =价格汇总!D103 -> 6.1 | E10: =价格汇总!E103 -> 5.1 | F10: =价格汇总!F103 -> 5.1 | G10: =价格汇总!G103 -> 1020 | H10: =价格汇总!H103 -> 6.1 | I10: =价格汇总!I103 -> 5.1 | J10: =价格汇总!J103 -> 5.1 | K10: 25-28天
A11: 组合四区 | B11: FTW1/IUSF/DFW6/IAH3/SAT1 FTW5/STL3/PSC2/PDX7 (标红仓点按12KG起收) 单价按100KG段+1/KG 51KG-100KG按100KG+同价 | C11: =价格汇总!C104 -> 1120 | D11: =价格汇总!D104 -> 100KG起收 | E11: =价格汇总!E104 -> 100KG起收 | F11: =价格汇总!F104 -> 5.6 | G11: =价格汇总!G104 -> 1120 | H11: =价格汇总!H104 -> 100KG起收 | I11: =价格汇总!I104 -> 100KG起收 | J11: =价格汇总!J104 -> 5.6 | K11: 28-32天
A12: 组合五区 | B12: IND9/MDW2/FWA4/MEM1 MQJ1/DEN8/RFD2/ORD2/LFT1 (标红仓点按12KG起收) 单价按100KG段+1/KG 51KG-100KG按100KG+同价 | C12: =价格汇总!C105 -> 1160 | D12: =价格汇总!D105 -> 100KG起收 | E12: =价格汇总!E105 -> 100KG起收 | F12: =价格汇总!F105 -> 5.8 | G12: =价格汇总!G105 -> 1160 | H12: =价格汇总!H105 -> 100KG起收 | I12: =价格汇总!I105 -> 100KG起收 | J12: =价格汇总!J105 -> 5.8 | K12: 28-32天
A13: 组合六区 | B13: CLT2/RDU2/CLT3/RDU4 (标红仓点按12KG起收) 单价按100KG段+1/KG 51KG-100KG按100KG+同价 | C13: =价格汇总!C106 -> 1340 | D13: =价格汇总!D106 -> 100KG起收 | E13: =价格汇总!E106 -> 100KG起收 | F13: =价格汇总!F106 -> 6.7 | G13: =价格汇总!G106 -> 1340 | H13: =价格汇总!H106 -> 100KG起收 | I13: =价格汇总!I106 -> 100KG起收 | J13: =价格汇总!J106 -> 6.7 | K13: 30-35天
A14: 组合七区 | B14: ABE8/AVP1/TEB3/TEB9/TPA3 RMN3/ORF2/SWF2 (标红仓点按12KG起收) 单价按100KG段+1/KG 51KG-100KG按100KG+同价 | C14: =价格汇总!C107 -> 1420 | D14: =价格汇总!D107 -> 100KG起收 | E14: =价格汇总!E107 -> 100KG起收 | F14: =价格汇总!F107 -> 7.1 | G14: =价格汇总!G107 -> 1420 | H14: =价格汇总!H107 -> 100KG起收 | I14: =价格汇总!I107 -> 100KG起收 | J14: =价格汇总!J107 -> 7.1 | K14: 30-35天
A15: 含税自提(出库费15美金/托 汇率7） | C15: =价格汇总!C108 -> 740 | D15: =价格汇总!D108 -> —— | E15: =价格汇总!E108 -> —— | F15: =价格汇总!F108 -> 3.7 | G15: =价格汇总!G108 -> 740 | H15: =价格汇总!H108 -> —— | I15: =价格汇总!I108 -> —— | J15: =价格汇总!J108 -> 3.7 | K15: 20-25天
A16: 单票51KG以上,重货减免优惠：1:200减0.3,1:250减0.6,1:300减0.9,1:350减1.2,1:450及以上减1.5.
A17: 理赔注意事项
A18: 1>以上按方/按公斤含税价格含海关查验及查验引起的其它费用.包税价格含查验费,除查验费外的其他费用，例如亚马逊爆仓引起的仓租/柜租，非我司原因导致的亚马逊拒收产生的相关费用，申报不符海关惩罚金,扣关,退运等包税价格都是不包含的，请客户将这些官方收费也考虑到成本中，以免引起误会； 2>按方含税价格包含海关查验费，如因报关资料问题引起的出口查验由客人承担所有相关费用（如仓租，柜租，改船费等),因为国外清关资质认证问题或者产品本身问题导致的查验费及额外费用由这票货来承担； 3>不可抗力因素造成的时效延误不在赔偿范围内，如：海关查验，如自然灾害、如台风、地震、洪水、冰雹,，暴风雪；政府行为，社会异常事件，如罢工、骚乱三方面，疫情原因导致仓库预约困难或延识误等。 4>拒收一切敏感货，冲货如被海关扣货罚没销毁等，不退运费，我司也不承担任何责任.品名必需如实申报,如遇查验,申报与实际品名不一致将会产生巨额关税,客户自负.
A22: 服务小贴士
A23: 1>为了更好的服务客户和统计仓位，来货请务必贴上我司的进仓标签. 2>空仓费产生情况：过了截单时间做的行为；更改渠道、客户原因延船期等；货物在截货时间前未到我司国内仓库.
A25: 其它费用
A26: 按方渠道的计费重是按实际立方数和实重/363取大值计算的,卡派单箱无最低计费重量限制，托盘货物不按方算. 最长边超过120CM小于165CM加收RMB1/KG(按方含税+200/CBM),单边超过165CM拒收； 报关费按200RMB/票。 托盘、木架、木箱类货物泡货计费重*1.1*1.1算计费重； 实重托盘比重达到1:200的比重系数*0.75算比重系数，计费重不*1.1。 自提出库费按“单板限2方/1200磅”取较大值计费，超出部分按第二板计算；超大件自提费用请单独咨询客服。

Sheet 美西特惠卡派
B1: SSH美西特惠卡派（货满安排最近一水）
B3: 交货深圳下单渠道：SSH盐田美西特惠卡派一区 至 七区/SSH盐田美西特惠卡派一区 至 七区-按方计费 交货广州下单渠道：SSH广州美西特惠卡派一区 至 七区/SSH广州美西特惠卡派一区 至 七区-按方计费 交货义乌下单渠道：SSH义乌美西特惠卡派一区 至 七区/SSH义乌美西特惠卡派一区 至 七区-按方计费 SSH义乌JF美西特惠卡派一区 至 七区/SSH义乌JF美西特惠卡派一区 至 七区-按方计费
B4: 人民币报价 | K4: 执行日期：2025-8-12
A5: 组合/混拆 | B5: 仓库代码/渠道名称 | C5: 深圳/广州交货价 | G5: 义乌交货价 | K5: 入仓参考时效 （开船后次日起算） | L5: 备注 | M5: 返回主页
C6: 按方含税(2CBM+) | D6: 包税(12KG+) | E6: 包税(51KG+) | F6: 包税(100KG+) | G6: 按方含税(2CBM+) | H6: 包税(12KG+) | I6: 包税(51KG+) | J6: 包税(100KG+)
A7: 组合一区 | B7: ONT8/LGB8/LAX9/SBD1/POC1/ POC3/IUSP/IUSQ/IUSJ | C7: =价格汇总!#REF! -> #REF! | D7: =价格汇总!#REF! -> #REF! | E7: =价格汇总!#REF! -> #REF! | F7: =价格汇总!#REF! -> #REF! | G7: =价格汇总!#REF! -> #REF! | H7: =价格汇总!#REF! -> #REF! | I7: =价格汇总!#REF! -> #REF! | J7: =价格汇总!#REF! -> #REF! | K7: 20-25天 | L7: 普船SML/YML/ONE等统配根据到货时间顺序就近安排船期循环装柜 (目的港：洛杉矶) 入仓单请注明渠道： 美西特惠卡派 （按方包税/公斤包税）
A8: 组合二区 | B8: GYR3/GYR2/LAS1/SMF3/SCK4/ FAT2/GEU3/GEU2/GEU5/ MIT2/VGT2/TCY1/TCY2/SCK8 | C8: =价格汇总!#REF! -> #REF! | D8: =价格汇总!#REF! -> #REF! | E8: =价格汇总!#REF! -> #REF! | F8: =价格汇总!#REF! -> #REF! | G8: =价格汇总!#REF! -> #REF! | H8: =价格汇总!#REF! -> #REF! | I8: =价格汇总!#REF! -> #REF! | J8: =价格汇总!#REF! -> #REF! | K8: 22-26天
A9: 组合三区 | B9: SLC2/FTW1/SAT1/IAH3/ABQ2/ AMA1/SAT4/DFW6/IUSF/ FTW3/FTW5/SLC3/HOU7/HOU8 | C9: =价格汇总!#REF! -> #REF! | D9: =价格汇总!#REF! -> #REF! | E9: =价格汇总!#REF! -> #REF! | F9: =价格汇总!#REF! -> #REF! | G9: =价格汇总!#REF! -> #REF! | H9: =价格汇总!#REF! -> #REF! | I9: =价格汇总!#REF! -> #REF! | J9: =价格汇总!#REF! -> #REF! | K9: 25-28天
A10: 组合四区 | B10: IND9/MDW2/FWA4/MEM1/ MQJ1/DEN8/DEN2/PPO4/RFD2/ ORD2/LFT1/LIT2 | C10: =价格汇总!#REF! -> #REF! | D10: =价格汇总!#REF! -> #REF! | E10: =价格汇总!#REF! -> #REF! | F10: =价格汇总!#REF! -> #REF! | G10: =价格汇总!#REF! -> #REF! | H10: =价格汇总!#REF! -> #REF! | I10: =价格汇总!#REF! -> #REF! | J10: =价格汇总!#REF! -> #REF! | K10: 28-32天
A11: 组合五区 | B11: STL3/PSC2/STL4/OKC2/ICT2/ PDX7/GEG2/BFI3/OKC2/ ICT2/PDX7/GEG2 | C11: =价格汇总!#REF! -> #REF! | D11: =价格汇总!#REF! -> #REF! | E11: =价格汇总!#REF! -> #REF! | F11: =价格汇总!#REF! -> #REF! | G11: =价格汇总!#REF! -> #REF! | H11: =价格汇总!#REF! -> #REF! | I11: =价格汇总!#REF! -> #REF! | J11: =价格汇总!#REF! -> #REF! | K11: 28-32天
A12: 组合六区 | B12: CLT2/RDU2/CLT3/RDU4/GSO1 | C12: =价格汇总!#REF! -> #REF! | D12: =价格汇总!#REF! -> #REF! | E12: =价格汇总!#REF! -> #REF! | F12: =价格汇总!#REF! -> #REF! | G12: =价格汇总!#REF! -> #REF! | H12: =价格汇总!#REF! -> #REF! | I12: =价格汇总!#REF! -> #REF! | J12: =价格汇总!#REF! -> #REF! | K12: 30-35天
A13: 组合七区 | B13: ABE4/ABE8/AVP1/TEB3/TEB6/ TEB9/ACY2/TPA3/PBI3/ RMN3/ORF2/SWF2/SWF1/ALB1/CHO1 | C13: =价格汇总!#REF! -> #REF! | D13: =价格汇总!#REF! -> #REF! | E13: =价格汇总!#REF! -> #REF! | F13: =价格汇总!#REF! -> #REF! | G13: =价格汇总!#REF! -> #REF! | H13: =价格汇总!#REF! -> #REF! | I13: =价格汇总!#REF! -> #REF! | J13: =价格汇总!#REF! -> #REF! | K13: 30-35天
B14: 美西特惠卡派渠道有甩柜概率，仓保难度大，如介意请谨慎选择！对于时效要求高的可优先选择普船洛杉矶卡派仓保几率更高。
B15: 单票51KG以上,重货减免优惠：1:200减0.3,1:250减0.6,1:300减0.9,1:350减1.2,1:450及以上减1.5.
B16: 理赔注意事项
B17: 1>以上按方/按公斤含税价格含海关查验及查验引起的其它费用.包税价格含查验费,除查验费外的其他费用，例如亚马逊爆仓引起的仓租/柜租，非我司原因导致的亚马逊拒收产生的相关费用，申报不符海关惩罚金,扣关,退运等包税价格都是不包含的，请客户将这些官方收费也考虑到成本中，以免引起误会； 2>按方含税价格包含海关查验费，如因报关资料问题引起的出口查验由客人承担所有相关费用（如仓租，柜租，改船费等),因为国外清关资质认证问题或者产品本身问题导致的查验费及额外费用由这票货来承担； 3>不可抗力因素造成的时效延误不在赔偿范围内，如：海关查验，如自然灾害、如台风、地震、洪水、冰雹,，暴风雪；政府行为，社会异常事件，如罢工、骚乱三方面，疫情原因导致仓库预约困难或延识误等。 4>拒收一切敏感货，冲货如被海关扣货罚没销毁等，不退运费，我司也不承担任何责任.品名必需如实申报,如遇查验,申报与实际品名不一致将会产生巨额关税,客户自负.
B21: 服务小贴士
B22: 1>为了更好的服务客户和统计仓位，来货请务必贴上我司的进仓标签. 2>空仓费产生情况：过了截单时间做的行为；更改渠道、客户原因延船期等；货物在截货时间前未到我司国内仓库.
B24: 其它费用
B25: 按方渠道的计费重是按实际立方数和实重/363取大值计算的,卡派单箱无最低计费重量限制，托盘货物+0.5/KG附加，不按方算. 最长边超过120CM小于165CM加收RMB1/KG(按方含税+200/CBM),单边超过165CM拒收； 报关费按350RMB/票。 托盘、木架、木箱类货物计费重*1.1计费，例如：一块托盘货物的实重是500KG，材积重600KG，实际计费重取材积大600KG，因托盘类货物额外计费重按660KG计费。

Sheet DG洛杉矶卡派
A1: SSHDG洛杉矶卡派
A3: 交货深圳、广州下单渠道：SSHDG07卡派
A4: 人民币报价 | I4: 执行日期：2026-3-31
A5: 组合/混拆 | B5: 仓库代码/渠道名称 | C5: 深圳交货价 | F5: 广州交货价 | I5: 入仓参考时效 （开船后次日起算） | J5: 备注 | K5: 返回主页
C6: 包税(12KG+) | D6: 包税(51KG+) | E6: 包税(100KG+) | F6: 包税(12KG+) | G6: 包税(51KG+) | H6: 包税(100KG+)
A7: 组合一区 | B7: ONT8/LGB8/LAX9/SBD1/IUSP IUSQ/IUSJ/POC1/POC2/POC3 | C7: =价格汇总!D112 -> 6 | D7: =价格汇总!E112 -> 5 | E7: =价格汇总!F112 -> 5 | F7: =价格汇总!H112 -> 6 | G7: =价格汇总!I112 -> 5 | H7: =价格汇总!J112 -> 5 | I7: 20-25天 | J7: 普船ZIM/合德/OA 等统配根据到货时间顺序就近 安排船期-循环装柜 (目的港：洛杉矶) 入仓单请注明渠道： 普船洛杉矶卡派 -组合柜 （按方包税/公斤包税）
A8: 组合二区 | B8: SNA4/SBD2/LGB4/LGB6 XLX7/IUTI/IUSW/PSP3 | C8: =价格汇总!D113 -> 6.3 | D8: =价格汇总!E113 -> 5.3 | E8: =价格汇总!F113 -> 5.3 | F8: =价格汇总!H113 -> 6.3 | G8: =价格汇总!I113 -> 5.3 | H8: =价格汇总!J113 -> 5.3 | I8: 22-26天
A9: 组合二区Plus | B9: SMF3/SCK4/LAS1/GYR2/GYR3 MIT2/VGT2/GEU2/GEU3/GEU5 HLI2/TCY2/TCY1/SCK8/SMF6 OAK3/MCE1/LAS6/SJC7/FAT2 PHX5/PHX7/IUTE | C9: =价格汇总!D114 -> 6.6 | D9: =价格汇总!E114 -> 5.6 | E9: =价格汇总!F114 -> 5.6 | F9: =价格汇总!H114 -> 6.6 | G9: =价格汇总!I114 -> 5.6 | H9: =价格汇总!J114 -> 5.6 | I9: 23-27天
A10: 组合三区 | B10: ABQ2/QXY8/MCC1 | C10: =价格汇总!D115 -> 7.4 | D10: =价格汇总!E115 -> 6.4 | E10: =价格汇总!F115 -> 6.4 | F10: =价格汇总!H115 -> 7.4 | G10: =价格汇总!I115 -> 6.4 | H10: =价格汇总!J115 -> 6.4 | I10: 25-28天
A11: 组合四区 | B11: FTW1/IUSF/DFW6/IAH3/SAT1 FTW5/STL3/PSC2/PDX7 (标红仓点按12KG起收) 单价按100KG段+1/KG 51KG-100KG按100KG+同价 | C11: =价格汇总!D116 -> 100KG起收 | D11: =价格汇总!E116 -> 100KG起收 | E11: =价格汇总!F116 -> 6.9 | F11: =价格汇总!H116 -> 100KG起收 | G11: =价格汇总!I116 -> 100KG起收 | H11: =价格汇总!J116 -> 6.9 | I11: 28-32天
A12: 组合五区 | B12: IND9/MDW2/FWA4/MEM1 MQJ1/DEN8/RFD2/ORD2/LFT1 (标红仓点按12KG起收) 单价按100KG段+1/KG 51KG-100KG按100KG+同价 | C12: =价格汇总!D117 -> 100KG起收 | D12: =价格汇总!E117 -> 100KG起收 | E12: =价格汇总!F117 -> 7.1 | F12: =价格汇总!H117 -> 100KG起收 | G12: =价格汇总!I117 -> 100KG起收 | H12: =价格汇总!J117 -> 7.1 | I12: 28-32天
A13: 组合六区 | B13: CLT2/RDU2/CLT3/RDU4 (标红仓点按12KG起收) 单价按100KG段+1/KG 51KG-100KG按100KG+同价 | C13: =价格汇总!D118 -> 100KG起收 | D13: =价格汇总!E118 -> 100KG起收 | E13: =价格汇总!F118 -> 8 | F13: =价格汇总!H118 -> 100KG起收 | G13: =价格汇总!I118 -> 100KG起收 | H13: =价格汇总!J118 -> 8 | I13: 30-35天
